2018-04-01 19:57:17,392 INFO org.apache.hadoop.yarn.server.resourcemanager.ResourceManager: STARTUP_MSG: 
/************************************************************
STARTUP_MSG: Starting ResourceManager
STARTUP_MSG:   host = bd18951cf78e/172.20.0.2
STARTUP_MSG:   args = []
STARTUP_MSG:   version = 2.7.1
STARTUP_MSG:   build = https://git-wip-us.apache.org/repos/asf/hadoop.git -r 15ecc87ccf4a0228f35af08fc56de536e6ce657a; compiled by 'jenkins' on 2015-06-29T06:04Z
STARTUP_MSG:   java = 1.7.0_71
************************************************************/
2018-04-01 19:57:17,401 INFO org.apache.hadoop.yarn.server.resourcemanager.ResourceManager: registered UNIX signal handlers for [TERM, HUP, INT]
2018-04-01 19:57:17,708 INFO org.apache.hadoop.conf.Configuration: found resource core-site.xml at file:/usr/local/hadoop-2.7.1/etc/hadoop/core-site.xml
2018-04-01 19:57:17,805 WARN org.apache.hadoop.util.NativeCodeLoader: Unable to load native-hadoop library for your platform... using builtin-java classes where applicable
2018-04-01 19:57:17,836 INFO org.apache.hadoop.security.Groups: clearing userToGroupsMap cache
2018-04-01 19:57:17,916 INFO org.apache.hadoop.conf.Configuration: found resource yarn-site.xml at file:/usr/local/hadoop-2.7.1/etc/hadoop/yarn-site.xml
2018-04-01 19:57:18,100 INFO org.apache.hadoop.yarn.event.AsyncDispatcher: Registering class org.apache.hadoop.yarn.server.resourcemanager.RMFatalEventType for class org.apache.hadoop.yarn.server.resourcemanager.ResourceManager$RMFatalEventDispatcher
2018-04-01 19:57:18,257 INFO org.apache.hadoop.yarn.server.resourcemanager.security.NMTokenSecretManagerInRM: NMTokenKeyRollingInterval: 86400000ms and NMTokenKeyActivationDelay: 900000ms
2018-04-01 19:57:18,262 INFO org.apache.hadoop.yarn.server.resourcemanager.security.RMContainerTokenSecretManager: ContainerTokenKeyRollingInterval: 86400000ms and ContainerTokenKeyActivationDelay: 900000ms
2018-04-01 19:57:18,266 INFO org.apache.hadoop.yarn.server.resourcemanager.security.AMRMTokenSecretManager: AMRMTokenKeyRollingInterval: 86400000ms and AMRMTokenKeyActivationDelay: 900000 ms
2018-04-01 19:57:18,293 INFO org.apache.hadoop.yarn.event.AsyncDispatcher: Registering class org.apache.hadoop.yarn.server.resourcemanager.recovery.RMStateStoreEventType for class org.apache.hadoop.yarn.server.resourcemanager.recovery.RMStateStore$ForwardingEventHandler
2018-04-01 19:57:18,297 INFO org.apache.hadoop.yarn.event.AsyncDispatcher: Registering class org.apache.hadoop.yarn.server.resourcemanager.NodesListManagerEventType for class org.apache.hadoop.yarn.server.resourcemanager.NodesListManager
2018-04-01 19:57:18,297 INFO org.apache.hadoop.yarn.server.resourcemanager.ResourceManager: Using Scheduler: org.apache.hadoop.yarn.server.resourcemanager.scheduler.capacity.CapacityScheduler
2018-04-01 19:57:18,312 INFO org.apache.hadoop.yarn.event.AsyncDispatcher: Registering class org.apache.hadoop.yarn.server.resourcemanager.scheduler.event.SchedulerEventType for class org.apache.hadoop.yarn.server.resourcemanager.ResourceManager$SchedulerEventDispatcher
2018-04-01 19:57:18,313 INFO org.apache.hadoop.yarn.event.AsyncDispatcher: Registering class org.apache.hadoop.yarn.server.resourcemanager.rmapp.RMAppEventType for class org.apache.hadoop.yarn.server.resourcemanager.ResourceManager$ApplicationEventDispatcher
2018-04-01 19:57:18,314 INFO org.apache.hadoop.yarn.event.AsyncDispatcher: Registering class org.apache.hadoop.yarn.server.resourcemanager.rmapp.attempt.RMAppAttemptEventType for class org.apache.hadoop.yarn.server.resourcemanager.ResourceManager$ApplicationAttemptEventDispatcher
2018-04-01 19:57:18,314 INFO org.apache.hadoop.yarn.event.AsyncDispatcher: Registering class org.apache.hadoop.yarn.server.resourcemanager.rmnode.RMNodeEventType for class org.apache.hadoop.yarn.server.resourcemanager.ResourceManager$NodeEventDispatcher
2018-04-01 19:57:18,371 INFO org.apache.hadoop.metrics2.impl.MetricsConfig: loaded properties from hadoop-metrics2.properties
2018-04-01 19:57:18,419 INFO org.apache.hadoop.metrics2.impl.MetricsSystemImpl: Scheduled snapshot period at 10 second(s).
2018-04-01 19:57:18,419 INFO org.apache.hadoop.metrics2.impl.MetricsSystemImpl: ResourceManager metrics system started
2018-04-01 19:57:18,432 INFO org.apache.hadoop.yarn.event.AsyncDispatcher: Registering class org.apache.hadoop.yarn.server.resourcemanager.RMAppManagerEventType for class org.apache.hadoop.yarn.server.resourcemanager.RMAppManager
2018-04-01 19:57:18,438 INFO org.apache.hadoop.yarn.event.AsyncDispatcher: Registering class org.apache.hadoop.yarn.server.resourcemanager.amlauncher.AMLauncherEventType for class org.apache.hadoop.yarn.server.resourcemanager.amlauncher.ApplicationMasterLauncher
2018-04-01 19:57:18,440 INFO org.apache.hadoop.yarn.server.resourcemanager.RMNMInfo: Registered RMNMInfo MBean
2018-04-01 19:57:18,442 INFO org.apache.hadoop.yarn.security.YarnAuthorizationProvider: org.apache.hadoop.yarn.security.ConfiguredYarnAuthorizer is instiantiated.
2018-04-01 19:57:18,442 INFO org.apache.hadoop.yarn.server.resourcemanager.metrics.SystemMetricsPublisher: YARN system metrics publishing service is not enabled
2018-04-01 19:57:18,442 INFO org.apache.hadoop.util.HostsFileReader: Refreshing hosts (include/exclude) list
2018-04-01 19:57:18,446 INFO org.apache.hadoop.conf.Configuration: found resource capacity-scheduler.xml at file:/usr/local/hadoop-2.7.1/etc/hadoop/capacity-scheduler.xml
2018-04-01 19:57:18,502 INFO org.apache.hadoop.yarn.server.resourcemanager.scheduler.capacity.CapacitySchedulerConfiguration: max alloc mb per queue for root is undefined
2018-04-01 19:57:18,503 INFO org.apache.hadoop.yarn.server.resourcemanager.scheduler.capacity.CapacitySchedulerConfiguration: max alloc vcore per queue for root is undefined
2018-04-01 19:57:18,507 INFO org.apache.hadoop.yarn.server.resourcemanager.scheduler.capacity.ParentQueue: root, capacity=1.0, asboluteCapacity=1.0, maxCapacity=1.0, asboluteMaxCapacity=1.0, state=RUNNING, acls=SUBMIT_APP:*ADMINISTER_QUEUE:*, labels=*,
, reservationsContinueLooking=true
2018-04-01 19:57:18,507 INFO org.apache.hadoop.yarn.server.resourcemanager.scheduler.capacity.ParentQueue: Initialized parent-queue root name=root, fullname=root
2018-04-01 19:57:18,517 INFO org.apache.hadoop.yarn.server.resourcemanager.scheduler.capacity.CapacitySchedulerConfiguration: max alloc mb per queue for root.default is undefined
2018-04-01 19:57:18,518 INFO org.apache.hadoop.yarn.server.resourcemanager.scheduler.capacity.CapacitySchedulerConfiguration: max alloc vcore per queue for root.default is undefined
2018-04-01 19:57:18,519 INFO org.apache.hadoop.yarn.server.resourcemanager.scheduler.capacity.LeafQueue: Initializing default
capacity = 1.0 [= (float) configuredCapacity / 100 ]
asboluteCapacity = 1.0 [= parentAbsoluteCapacity * capacity ]
maxCapacity = 1.0 [= configuredMaxCapacity ]
absoluteMaxCapacity = 1.0 [= 1.0 maximumCapacity undefined, (parentAbsoluteMaxCapacity * maximumCapacity) / 100 otherwise ]
userLimit = 100 [= configuredUserLimit ]
userLimitFactor = 1.0 [= configuredUserLimitFactor ]
maxApplications = 10000 [= configuredMaximumSystemApplicationsPerQueue or (int)(configuredMaximumSystemApplications * absoluteCapacity)]
maxApplicationsPerUser = 10000 [= (int)(maxApplications * (userLimit / 100.0f) * userLimitFactor) ]
usedCapacity = 0.0 [= usedResourcesMemory / (clusterResourceMemory * absoluteCapacity)]
absoluteUsedCapacity = 0.0 [= usedResourcesMemory / clusterResourceMemory]
maxAMResourcePerQueuePercent = 0.1 [= configuredMaximumAMResourcePercent ]
minimumAllocationFactor = 0.875 [= (float)(maximumAllocationMemory - minimumAllocationMemory) / maximumAllocationMemory ]
maximumAllocation = <memory:8192, vCores:32> [= configuredMaxAllocation ]
numContainers = 0 [= currentNumContainers ]
state = RUNNING [= configuredState ]
acls = SUBMIT_APP:*ADMINISTER_QUEUE:* [= configuredAcls ]
nodeLocalityDelay = 40
labels=*,
nodeLocalityDelay = 40
reservationsContinueLooking = true
preemptionDisabled = true

2018-04-01 19:57:18,519 INFO org.apache.hadoop.yarn.server.resourcemanager.scheduler.capacity.CapacityScheduler: Initialized queue: default: capacity=1.0, absoluteCapacity=1.0, usedResources=<memory:0, vCores:0>, usedCapacity=0.0, absoluteUsedCapacity=0.0, numApps=0, numContainers=0
2018-04-01 19:57:18,519 INFO org.apache.hadoop.yarn.server.resourcemanager.scheduler.capacity.CapacityScheduler: Initialized queue: root: numChildQueue= 1, capacity=1.0, absoluteCapacity=1.0, usedResources=<memory:0, vCores:0>usedCapacity=0.0, numApps=0, numContainers=0
2018-04-01 19:57:18,520 INFO org.apache.hadoop.yarn.server.resourcemanager.scheduler.capacity.CapacityScheduler: Initialized root queue root: numChildQueue= 1, capacity=1.0, absoluteCapacity=1.0, usedResources=<memory:0, vCores:0>usedCapacity=0.0, numApps=0, numContainers=0
2018-04-01 19:57:18,520 INFO org.apache.hadoop.yarn.server.resourcemanager.scheduler.capacity.CapacityScheduler: Initialized queue mappings, override: false
2018-04-01 19:57:18,520 INFO org.apache.hadoop.yarn.server.resourcemanager.scheduler.capacity.CapacityScheduler: Initialized CapacityScheduler with calculator=class org.apache.hadoop.yarn.util.resource.DefaultResourceCalculator, minimumAllocation=<<memory:1024, vCores:1>>, maximumAllocation=<<memory:8192, vCores:32>>, asynchronousScheduling=false, asyncScheduleInterval=5ms
2018-04-01 19:57:18,527 INFO org.apache.hadoop.yarn.server.resourcemanager.ResourceManager: Transitioning to active state
2018-04-01 19:57:18,543 INFO org.apache.hadoop.yarn.server.resourcemanager.recovery.RMStateStore: Updating AMRMToken
2018-04-01 19:57:18,543 INFO org.apache.hadoop.yarn.server.resourcemanager.security.RMContainerTokenSecretManager: Rolling master-key for container-tokens
2018-04-01 19:57:18,544 INFO org.apache.hadoop.yarn.server.resourcemanager.security.NMTokenSecretManagerInRM: Rolling master-key for nm-tokens
2018-04-01 19:57:18,544 INFO org.apache.hadoop.security.token.delegation.AbstractDelegationTokenSecretManager: Updating the current master key for generating delegation tokens
2018-04-01 19:57:18,545 INFO org.apache.hadoop.yarn.server.resourcemanager.security.RMDelegationTokenSecretManager: storing master key with keyID 1
2018-04-01 19:57:18,545 INFO org.apache.hadoop.yarn.server.resourcemanager.recovery.RMStateStore: Storing RMDTMasterKey.
2018-04-01 19:57:18,546 INFO org.apache.hadoop.security.token.delegation.AbstractDelegationTokenSecretManager: Starting expired delegation token remover thread, tokenRemoverScanInterval=60 min(s)
2018-04-01 19:57:18,546 INFO org.apache.hadoop.security.token.delegation.AbstractDelegationTokenSecretManager: Updating the current master key for generating delegation tokens
2018-04-01 19:57:18,546 INFO org.apache.hadoop.yarn.server.resourcemanager.security.RMDelegationTokenSecretManager: storing master key with keyID 2
2018-04-01 19:57:18,546 INFO org.apache.hadoop.yarn.server.resourcemanager.recovery.RMStateStore: Storing RMDTMasterKey.
2018-04-01 19:57:18,548 INFO org.apache.hadoop.yarn.event.AsyncDispatcher: Registering class org.apache.hadoop.yarn.nodelabels.event.NodeLabelsStoreEventType for class org.apache.hadoop.yarn.nodelabels.CommonNodeLabelsManager$ForwardingEventHandler
2018-04-01 19:57:18,589 INFO org.apache.hadoop.ipc.CallQueueManager: Using callQueue class java.util.concurrent.LinkedBlockingQueue
2018-04-01 19:57:18,599 INFO org.apache.hadoop.ipc.Server: Starting Socket Reader #1 for port 8031
2018-04-01 19:57:18,615 INFO org.apache.hadoop.yarn.factories.impl.pb.RpcServerFactoryPBImpl: Adding protocol org.apache.hadoop.yarn.server.api.ResourceTrackerPB to the server
2018-04-01 19:57:18,616 INFO org.apache.hadoop.ipc.Server: IPC Server Responder: starting
2018-04-01 19:57:18,616 INFO org.apache.hadoop.ipc.Server: IPC Server listener on 8031: starting
2018-04-01 19:57:18,648 INFO org.apache.hadoop.ipc.CallQueueManager: Using callQueue class java.util.concurrent.LinkedBlockingQueue
2018-04-01 19:57:18,654 INFO org.apache.hadoop.ipc.Server: Starting Socket Reader #1 for port 8030
2018-04-01 19:57:18,671 INFO org.apache.hadoop.yarn.factories.impl.pb.RpcServerFactoryPBImpl: Adding protocol org.apache.hadoop.yarn.api.ApplicationMasterProtocolPB to the server
2018-04-01 19:57:18,671 INFO org.apache.hadoop.ipc.Server: IPC Server Responder: starting
2018-04-01 19:57:18,671 INFO org.apache.hadoop.ipc.Server: IPC Server listener on 8030: starting
2018-04-01 19:57:18,758 INFO org.apache.hadoop.ipc.CallQueueManager: Using callQueue class java.util.concurrent.LinkedBlockingQueue
2018-04-01 19:57:18,758 INFO org.apache.hadoop.ipc.Server: Starting Socket Reader #1 for port 8032
2018-04-01 19:57:18,761 INFO org.apache.hadoop.yarn.factories.impl.pb.RpcServerFactoryPBImpl: Adding protocol org.apache.hadoop.yarn.api.ApplicationClientProtocolPB to the server
2018-04-01 19:57:18,764 INFO org.apache.hadoop.ipc.Server: IPC Server Responder: starting
2018-04-01 19:57:18,764 INFO org.apache.hadoop.ipc.Server: IPC Server listener on 8032: starting
2018-04-01 19:57:18,793 INFO org.apache.hadoop.yarn.server.resourcemanager.ResourceManager: Transitioned to active state
2018-04-01 19:57:18,868 INFO org.mortbay.log: Logging to org.slf4j.impl.Log4jLoggerAdapter(org.mortbay.log) via org.mortbay.log.Slf4jLog
2018-04-01 19:57:18,875 INFO org.apache.hadoop.security.authentication.server.AuthenticationFilter: Unable to initialize FileSignerSecretProvider, falling back to use random secrets.
2018-04-01 19:57:18,881 INFO org.apache.hadoop.http.HttpRequestLog: Http request log for http.requests.resourcemanager is not defined
2018-04-01 19:57:18,887 INFO org.apache.hadoop.http.HttpServer2: Added global filter 'safety' (class=org.apache.hadoop.http.HttpServer2$QuotingInputFilter)
2018-04-01 19:57:18,891 INFO org.apache.hadoop.http.HttpServer2: Added filter RMAuthenticationFilter (class=org.apache.hadoop.yarn.server.security.http.RMAuthenticationFilter) to context cluster
2018-04-01 19:57:18,892 INFO org.apache.hadoop.http.HttpServer2: Added filter RMAuthenticationFilter (class=org.apache.hadoop.yarn.server.security.http.RMAuthenticationFilter) to context static
2018-04-01 19:57:18,892 INFO org.apache.hadoop.http.HttpServer2: Added filter RMAuthenticationFilter (class=org.apache.hadoop.yarn.server.security.http.RMAuthenticationFilter) to context logs
2018-04-01 19:57:18,892 INFO org.apache.hadoop.http.HttpServer2: Added filter static_user_filter (class=org.apache.hadoop.http.lib.StaticUserWebFilter$StaticUserFilter) to context cluster
2018-04-01 19:57:18,892 INFO org.apache.hadoop.http.HttpServer2: Added filter static_user_filter (class=org.apache.hadoop.http.lib.StaticUserWebFilter$StaticUserFilter) to context static
2018-04-01 19:57:18,892 INFO org.apache.hadoop.http.HttpServer2: Added filter static_user_filter (class=org.apache.hadoop.http.lib.StaticUserWebFilter$StaticUserFilter) to context logs
2018-04-01 19:57:18,895 INFO org.apache.hadoop.http.HttpServer2: adding path spec: /cluster/*
2018-04-01 19:57:18,896 INFO org.apache.hadoop.http.HttpServer2: adding path spec: /ws/*
2018-04-01 19:57:18,907 INFO org.apache.hadoop.http.HttpServer2: Jetty bound to port 8088
2018-04-01 19:57:18,907 INFO org.mortbay.log: jetty-6.1.26
2018-04-01 19:57:18,944 INFO org.mortbay.log: Extract jar:file:/usr/local/hadoop-2.7.1/share/hadoop/yarn/hadoop-yarn-common-2.7.1.jar!/webapps/cluster to /tmp/Jetty_0_0_0_0_8088_cluster____u0rgz3/webapp
2018-04-01 19:57:19,167 INFO org.apache.hadoop.security.token.delegation.AbstractDelegationTokenSecretManager: Updating the current master key for generating delegation tokens
2018-04-01 19:57:19,168 INFO org.apache.hadoop.security.token.delegation.AbstractDelegationTokenSecretManager: Starting expired delegation token remover thread, tokenRemoverScanInterval=60 min(s)
2018-04-01 19:57:19,168 INFO org.apache.hadoop.security.token.delegation.AbstractDelegationTokenSecretManager: Updating the current master key for generating delegation tokens
2018-04-01 19:57:19,176 INFO org.mortbay.log: Started HttpServer2$SelectChannelConnectorWithSafeStartup@0.0.0.0:8088
2018-04-01 19:57:19,176 INFO org.apache.hadoop.yarn.webapp.WebApps: Web app /cluster started at 8088
2018-04-01 19:57:19,551 INFO org.apache.hadoop.yarn.webapp.WebApps: Registered webapp guice modules
2018-04-01 19:57:19,587 INFO org.apache.hadoop.ipc.CallQueueManager: Using callQueue class java.util.concurrent.LinkedBlockingQueue
2018-04-01 19:57:19,587 INFO org.apache.hadoop.ipc.Server: Starting Socket Reader #1 for port 8033
2018-04-01 19:57:19,590 INFO org.apache.hadoop.yarn.factories.impl.pb.RpcServerFactoryPBImpl: Adding protocol org.apache.hadoop.yarn.server.api.ResourceManagerAdministrationProtocolPB to the server
2018-04-01 19:57:19,590 INFO org.apache.hadoop.ipc.Server: IPC Server Responder: starting
2018-04-01 19:57:19,590 INFO org.apache.hadoop.ipc.Server: IPC Server listener on 8033: starting
2018-04-01 19:57:20,653 INFO org.apache.hadoop.yarn.util.RackResolver: Resolved bd18951cf78e to /default-rack
2018-04-01 19:57:20,655 INFO org.apache.hadoop.yarn.server.resourcemanager.ResourceTrackerService: NodeManager from node bd18951cf78e(cmPort: 36999 httpPort: 8042) registered with capability: <memory:8192, vCores:8>, assigned nodeId bd18951cf78e:36999
2018-04-01 19:57:20,656 INFO org.apache.hadoop.yarn.server.resourcemanager.rmnode.RMNodeImpl: bd18951cf78e:36999 Node Transitioned from NEW to RUNNING
2018-04-01 19:57:20,658 INFO org.apache.hadoop.yarn.server.resourcemanager.scheduler.capacity.CapacityScheduler: Added node bd18951cf78e:36999 clusterResource: <memory:8192, vCores:8>
2018-04-01 19:57:59,243 INFO org.apache.hadoop.yarn.server.resourcemanager.ClientRMService: Allocated new applicationId: 1
2018-04-01 19:58:00,112 INFO org.apache.hadoop.yarn.server.resourcemanager.ClientRMService: Application with id 1 submitted by user root
2018-04-01 19:58:00,112 INFO org.apache.hadoop.yarn.server.resourcemanager.rmapp.RMAppImpl: Storing application with id application_1522627038528_0001
2018-04-01 19:58:00,113 INFO org.apache.hadoop.yarn.server.resourcemanager.RMAuditLogger: USER=root	IP=172.20.0.2	OPERATION=Submit Application Request	TARGET=ClientRMService	RESULT=SUCCESS	APPID=application_1522627038528_0001
2018-04-01 19:58:00,119 INFO org.apache.hadoop.yarn.server.resourcemanager.rmapp.RMAppImpl: application_1522627038528_0001 State change from NEW to NEW_SAVING
2018-04-01 19:58:00,119 INFO org.apache.hadoop.yarn.server.resourcemanager.recovery.RMStateStore: Storing info for app: application_1522627038528_0001
2018-04-01 19:58:00,119 INFO org.apache.hadoop.yarn.server.resourcemanager.rmapp.RMAppImpl: application_1522627038528_0001 State change from NEW_SAVING to SUBMITTED
2018-04-01 19:58:00,121 INFO org.apache.hadoop.yarn.server.resourcemanager.scheduler.capacity.ParentQueue: Application added - appId: application_1522627038528_0001 user: root leaf-queue of parent: root #applications: 1
2018-04-01 19:58:00,121 INFO org.apache.hadoop.yarn.server.resourcemanager.scheduler.capacity.CapacityScheduler: Accepted application application_1522627038528_0001 from user: root, in queue: default
2018-04-01 19:58:00,127 INFO org.apache.hadoop.yarn.server.resourcemanager.rmapp.RMAppImpl: application_1522627038528_0001 State change from SUBMITTED to ACCEPTED
2018-04-01 19:58:00,151 INFO org.apache.hadoop.yarn.server.resourcemanager.ApplicationMasterService: Registering app attempt : appattempt_1522627038528_0001_000001
2018-04-01 19:58:00,152 INFO org.apache.hadoop.yarn.server.resourcemanager.rmapp.attempt.RMAppAttemptImpl: appattempt_1522627038528_0001_000001 State change from NEW to SUBMITTED
2018-04-01 19:58:00,162 WARN org.apache.hadoop.yarn.server.resourcemanager.scheduler.capacity.LeafQueue: maximum-am-resource-percent is insufficient to start a single application in queue, it is likely set too low. skipping enforcement to allow at least one application to start
2018-04-01 19:58:00,162 WARN org.apache.hadoop.yarn.server.resourcemanager.scheduler.capacity.LeafQueue: maximum-am-resource-percent is insufficient to start a single application in queue for user, it is likely set too low. skipping enforcement to allow at least one application to start
2018-04-01 19:58:00,162 INFO org.apache.hadoop.yarn.server.resourcemanager.scheduler.capacity.LeafQueue: Application application_1522627038528_0001 from user: root activated in queue: default
2018-04-01 19:58:00,162 INFO org.apache.hadoop.yarn.server.resourcemanager.scheduler.capacity.LeafQueue: Application added - appId: application_1522627038528_0001 user: org.apache.hadoop.yarn.server.resourcemanager.scheduler.capacity.LeafQueue$User@31560ad3, leaf-queue: default #user-pending-applications: 0 #user-active-applications: 1 #queue-pending-applications: 0 #queue-active-applications: 1
2018-04-01 19:58:00,162 INFO org.apache.hadoop.yarn.server.resourcemanager.scheduler.capacity.CapacityScheduler: Added Application Attempt appattempt_1522627038528_0001_000001 to scheduler from user root in queue default
2018-04-01 19:58:00,163 INFO org.apache.hadoop.yarn.server.resourcemanager.rmapp.attempt.RMAppAttemptImpl: appattempt_1522627038528_0001_000001 State change from SUBMITTED to SCHEDULED
2018-04-01 19:58:00,856 INFO org.apache.hadoop.yarn.server.resourcemanager.rmcontainer.RMContainerImpl: container_1522627038528_0001_01_000001 Container Transitioned from NEW to ALLOCATED
2018-04-01 19:58:00,856 INFO org.apache.hadoop.yarn.server.resourcemanager.RMAuditLogger: USER=root	OPERATION=AM Allocated Container	TARGET=SchedulerApp	RESULT=SUCCESS	APPID=application_1522627038528_0001	CONTAINERID=container_1522627038528_0001_01_000001
2018-04-01 19:58:00,856 INFO org.apache.hadoop.yarn.server.resourcemanager.scheduler.SchedulerNode: Assigned container container_1522627038528_0001_01_000001 of capacity <memory:2048, vCores:1> on host bd18951cf78e:36999, which has 1 containers, <memory:2048, vCores:1> used and <memory:6144, vCores:7> available after allocation
2018-04-01 19:58:00,857 INFO org.apache.hadoop.yarn.server.resourcemanager.scheduler.capacity.LeafQueue: assignedContainer application attempt=appattempt_1522627038528_0001_000001 container=Container: [ContainerId: container_1522627038528_0001_01_000001, NodeId: bd18951cf78e:36999, NodeHttpAddress: bd18951cf78e:8042, Resource: <memory:2048, vCores:1>, Priority: 0, Token: null, ] queue=default: capacity=1.0, absoluteCapacity=1.0, usedResources=<memory:0, vCores:0>, usedCapacity=0.0, absoluteUsedCapacity=0.0, numApps=1, numContainers=0 clusterResource=<memory:8192, vCores:8>
2018-04-01 19:58:00,857 INFO org.apache.hadoop.yarn.server.resourcemanager.scheduler.capacity.ParentQueue: Re-sorting assigned queue: root.default stats: default: capacity=1.0, absoluteCapacity=1.0, usedResources=<memory:2048, vCores:1>, usedCapacity=0.25, absoluteUsedCapacity=0.25, numApps=1, numContainers=1
2018-04-01 19:58:00,857 INFO org.apache.hadoop.yarn.server.resourcemanager.scheduler.capacity.ParentQueue: assignedContainer queue=root usedCapacity=0.25 absoluteUsedCapacity=0.25 used=<memory:2048, vCores:1> cluster=<memory:8192, vCores:8>
2018-04-01 19:58:00,873 INFO org.apache.hadoop.yarn.server.resourcemanager.security.NMTokenSecretManagerInRM: Sending NMToken for nodeId : bd18951cf78e:36999 for container : container_1522627038528_0001_01_000001
2018-04-01 19:58:00,881 INFO org.apache.hadoop.yarn.server.resourcemanager.rmcontainer.RMContainerImpl: container_1522627038528_0001_01_000001 Container Transitioned from ALLOCATED to ACQUIRED
2018-04-01 19:58:00,881 INFO org.apache.hadoop.yarn.server.resourcemanager.security.NMTokenSecretManagerInRM: Clear node set for appattempt_1522627038528_0001_000001
2018-04-01 19:58:00,884 INFO org.apache.hadoop.yarn.server.resourcemanager.rmapp.attempt.RMAppAttemptImpl: Storing attempt: AppId: application_1522627038528_0001 AttemptId: appattempt_1522627038528_0001_000001 MasterContainer: Container: [ContainerId: container_1522627038528_0001_01_000001, NodeId: bd18951cf78e:36999, NodeHttpAddress: bd18951cf78e:8042, Resource: <memory:2048, vCores:1>, Priority: 0, Token: Token { kind: ContainerToken, service: 172.20.0.2:36999 }, ]
2018-04-01 19:58:00,894 INFO org.apache.hadoop.yarn.server.resourcemanager.rmapp.attempt.RMAppAttemptImpl: appattempt_1522627038528_0001_000001 State change from SCHEDULED to ALLOCATED_SAVING
2018-04-01 19:58:00,895 INFO org.apache.hadoop.yarn.server.resourcemanager.rmapp.attempt.RMAppAttemptImpl: appattempt_1522627038528_0001_000001 State change from ALLOCATED_SAVING to ALLOCATED
2018-04-01 19:58:00,897 INFO org.apache.hadoop.yarn.server.resourcemanager.amlauncher.AMLauncher: Launching masterappattempt_1522627038528_0001_000001
2018-04-01 19:58:00,919 INFO org.apache.hadoop.yarn.server.resourcemanager.amlauncher.AMLauncher: Setting up container Container: [ContainerId: container_1522627038528_0001_01_000001, NodeId: bd18951cf78e:36999, NodeHttpAddress: bd18951cf78e:8042, Resource: <memory:2048, vCores:1>, Priority: 0, Token: Token { kind: ContainerToken, service: 172.20.0.2:36999 }, ] for AM appattempt_1522627038528_0001_000001
2018-04-01 19:58:00,919 INFO org.apache.hadoop.yarn.server.resourcemanager.amlauncher.AMLauncher: Command to launch container container_1522627038528_0001_01_000001 : $JAVA_HOME/bin/java -Dlog4j.configuration=container-log4j.properties -Dyarn.app.container.log.dir=<LOG_DIR> -Dyarn.app.container.log.filesize=0 -Dhadoop.root.logger=INFO,CLA -Dhadoop.root.logfile=syslog  -Xmx1024m org.apache.hadoop.mapreduce.v2.app.MRAppMaster 1><LOG_DIR>/stdout 2><LOG_DIR>/stderr 
2018-04-01 19:58:00,920 INFO org.apache.hadoop.yarn.server.resourcemanager.security.AMRMTokenSecretManager: Create AMRMToken for ApplicationAttempt: appattempt_1522627038528_0001_000001
2018-04-01 19:58:00,922 INFO org.apache.hadoop.yarn.server.resourcemanager.security.AMRMTokenSecretManager: Creating password for appattempt_1522627038528_0001_000001
2018-04-01 19:58:01,152 INFO org.apache.hadoop.yarn.server.resourcemanager.amlauncher.AMLauncher: Done launching container Container: [ContainerId: container_1522627038528_0001_01_000001, NodeId: bd18951cf78e:36999, NodeHttpAddress: bd18951cf78e:8042, Resource: <memory:2048, vCores:1>, Priority: 0, Token: Token { kind: ContainerToken, service: 172.20.0.2:36999 }, ] for AM appattempt_1522627038528_0001_000001
2018-04-01 19:58:01,153 INFO org.apache.hadoop.yarn.server.resourcemanager.rmapp.attempt.RMAppAttemptImpl: appattempt_1522627038528_0001_000001 State change from ALLOCATED to LAUNCHED
2018-04-01 19:58:01,843 INFO org.apache.hadoop.yarn.server.resourcemanager.rmcontainer.RMContainerImpl: container_1522627038528_0001_01_000001 Container Transitioned from ACQUIRED to RUNNING
2018-04-01 19:58:04,904 INFO SecurityLogger.org.apache.hadoop.ipc.Server: Auth successful for appattempt_1522627038528_0001_000001 (auth:SIMPLE)
2018-04-01 19:58:04,910 INFO org.apache.hadoop.yarn.server.resourcemanager.ApplicationMasterService: AM registration appattempt_1522627038528_0001_000001
2018-04-01 19:58:04,910 INFO org.apache.hadoop.yarn.server.resourcemanager.RMAuditLogger: USER=root	IP=172.20.0.2	OPERATION=Register App Master	TARGET=ApplicationMasterService	RESULT=SUCCESS	APPID=application_1522627038528_0001	APPATTEMPTID=appattempt_1522627038528_0001_000001
2018-04-01 19:58:04,910 INFO org.apache.hadoop.yarn.server.resourcemanager.rmapp.attempt.RMAppAttemptImpl: appattempt_1522627038528_0001_000001 State change from LAUNCHED to RUNNING
2018-04-01 19:58:04,910 INFO org.apache.hadoop.yarn.server.resourcemanager.rmapp.RMAppImpl: application_1522627038528_0001 State change from ACCEPTED to RUNNING
2018-04-01 19:58:06,856 INFO org.apache.hadoop.yarn.server.resourcemanager.rmcontainer.RMContainerImpl: container_1522627038528_0001_01_000002 Container Transitioned from NEW to ALLOCATED
2018-04-01 19:58:06,856 INFO org.apache.hadoop.yarn.server.resourcemanager.RMAuditLogger: USER=root	OPERATION=AM Allocated Container	TARGET=SchedulerApp	RESULT=SUCCESS	APPID=application_1522627038528_0001	CONTAINERID=container_1522627038528_0001_01_000002
2018-04-01 19:58:06,856 INFO org.apache.hadoop.yarn.server.resourcemanager.scheduler.SchedulerNode: Assigned container container_1522627038528_0001_01_000002 of capacity <memory:1024, vCores:1> on host bd18951cf78e:36999, which has 2 containers, <memory:3072, vCores:2> used and <memory:5120, vCores:6> available after allocation
2018-04-01 19:58:06,856 INFO org.apache.hadoop.yarn.server.resourcemanager.scheduler.capacity.LeafQueue: assignedContainer application attempt=appattempt_1522627038528_0001_000001 container=Container: [ContainerId: container_1522627038528_0001_01_000002, NodeId: bd18951cf78e:36999, NodeHttpAddress: bd18951cf78e:8042, Resource: <memory:1024, vCores:1>, Priority: 20, Token: null, ] queue=default: capacity=1.0, absoluteCapacity=1.0, usedResources=<memory:2048, vCores:1>, usedCapacity=0.25, absoluteUsedCapacity=0.25, numApps=1, numContainers=1 clusterResource=<memory:8192, vCores:8>
2018-04-01 19:58:06,857 INFO org.apache.hadoop.yarn.server.resourcemanager.scheduler.capacity.ParentQueue: Re-sorting assigned queue: root.default stats: default: capacity=1.0, absoluteCapacity=1.0, usedResources=<memory:3072, vCores:2>, usedCapacity=0.375, absoluteUsedCapacity=0.375, numApps=1, numContainers=2
2018-04-01 19:58:06,857 INFO org.apache.hadoop.yarn.server.resourcemanager.scheduler.capacity.ParentQueue: assignedContainer queue=root usedCapacity=0.375 absoluteUsedCapacity=0.375 used=<memory:3072, vCores:2> cluster=<memory:8192, vCores:8>
2018-04-01 19:58:06,857 INFO org.apache.hadoop.yarn.server.resourcemanager.rmcontainer.RMContainerImpl: container_1522627038528_0001_01_000003 Container Transitioned from NEW to ALLOCATED
2018-04-01 19:58:06,857 INFO org.apache.hadoop.yarn.server.resourcemanager.RMAuditLogger: USER=root	OPERATION=AM Allocated Container	TARGET=SchedulerApp	RESULT=SUCCESS	APPID=application_1522627038528_0001	CONTAINERID=container_1522627038528_0001_01_000003
2018-04-01 19:58:06,858 INFO org.apache.hadoop.yarn.server.resourcemanager.scheduler.SchedulerNode: Assigned container container_1522627038528_0001_01_000003 of capacity <memory:1024, vCores:1> on host bd18951cf78e:36999, which has 3 containers, <memory:4096, vCores:3> used and <memory:4096, vCores:5> available after allocation
2018-04-01 19:58:06,858 INFO org.apache.hadoop.yarn.server.resourcemanager.scheduler.capacity.LeafQueue: assignedContainer application attempt=appattempt_1522627038528_0001_000001 container=Container: [ContainerId: container_1522627038528_0001_01_000003, NodeId: bd18951cf78e:36999, NodeHttpAddress: bd18951cf78e:8042, Resource: <memory:1024, vCores:1>, Priority: 20, Token: null, ] queue=default: capacity=1.0, absoluteCapacity=1.0, usedResources=<memory:3072, vCores:2>, usedCapacity=0.375, absoluteUsedCapacity=0.375, numApps=1, numContainers=2 clusterResource=<memory:8192, vCores:8>
2018-04-01 19:58:06,858 INFO org.apache.hadoop.yarn.server.resourcemanager.scheduler.capacity.ParentQueue: Re-sorting assigned queue: root.default stats: default: capacity=1.0, absoluteCapacity=1.0, usedResources=<memory:4096, vCores:3>, usedCapacity=0.5, absoluteUsedCapacity=0.5, numApps=1, numContainers=3
2018-04-01 19:58:06,858 INFO org.apache.hadoop.yarn.server.resourcemanager.scheduler.capacity.ParentQueue: assignedContainer queue=root usedCapacity=0.5 absoluteUsedCapacity=0.5 used=<memory:4096, vCores:3> cluster=<memory:8192, vCores:8>
2018-04-01 19:58:06,858 INFO org.apache.hadoop.yarn.server.resourcemanager.rmcontainer.RMContainerImpl: container_1522627038528_0001_01_000004 Container Transitioned from NEW to ALLOCATED
2018-04-01 19:58:06,859 INFO org.apache.hadoop.yarn.server.resourcemanager.RMAuditLogger: USER=root	OPERATION=AM Allocated Container	TARGET=SchedulerApp	RESULT=SUCCESS	APPID=application_1522627038528_0001	CONTAINERID=container_1522627038528_0001_01_000004
2018-04-01 19:58:06,859 INFO org.apache.hadoop.yarn.server.resourcemanager.scheduler.SchedulerNode: Assigned container container_1522627038528_0001_01_000004 of capacity <memory:1024, vCores:1> on host bd18951cf78e:36999, which has 4 containers, <memory:5120, vCores:4> used and <memory:3072, vCores:4> available after allocation
2018-04-01 19:58:06,859 INFO org.apache.hadoop.yarn.server.resourcemanager.scheduler.capacity.LeafQueue: assignedContainer application attempt=appattempt_1522627038528_0001_000001 container=Container: [ContainerId: container_1522627038528_0001_01_000004, NodeId: bd18951cf78e:36999, NodeHttpAddress: bd18951cf78e:8042, Resource: <memory:1024, vCores:1>, Priority: 20, Token: null, ] queue=default: capacity=1.0, absoluteCapacity=1.0, usedResources=<memory:4096, vCores:3>, usedCapacity=0.5, absoluteUsedCapacity=0.5, numApps=1, numContainers=3 clusterResource=<memory:8192, vCores:8>
2018-04-01 19:58:06,859 INFO org.apache.hadoop.yarn.server.resourcemanager.scheduler.capacity.ParentQueue: Re-sorting assigned queue: root.default stats: default: capacity=1.0, absoluteCapacity=1.0, usedResources=<memory:5120, vCores:4>, usedCapacity=0.625, absoluteUsedCapacity=0.625, numApps=1, numContainers=4
2018-04-01 19:58:06,859 INFO org.apache.hadoop.yarn.server.resourcemanager.scheduler.capacity.ParentQueue: assignedContainer queue=root usedCapacity=0.625 absoluteUsedCapacity=0.625 used=<memory:5120, vCores:4> cluster=<memory:8192, vCores:8>
2018-04-01 19:58:06,860 INFO org.apache.hadoop.yarn.server.resourcemanager.rmcontainer.RMContainerImpl: container_1522627038528_0001_01_000005 Container Transitioned from NEW to ALLOCATED
2018-04-01 19:58:06,860 INFO org.apache.hadoop.yarn.server.resourcemanager.RMAuditLogger: USER=root	OPERATION=AM Allocated Container	TARGET=SchedulerApp	RESULT=SUCCESS	APPID=application_1522627038528_0001	CONTAINERID=container_1522627038528_0001_01_000005
2018-04-01 19:58:06,860 INFO org.apache.hadoop.yarn.server.resourcemanager.scheduler.SchedulerNode: Assigned container container_1522627038528_0001_01_000005 of capacity <memory:1024, vCores:1> on host bd18951cf78e:36999, which has 5 containers, <memory:6144, vCores:5> used and <memory:2048, vCores:3> available after allocation
2018-04-01 19:58:06,860 INFO org.apache.hadoop.yarn.server.resourcemanager.scheduler.capacity.LeafQueue: assignedContainer application attempt=appattempt_1522627038528_0001_000001 container=Container: [ContainerId: container_1522627038528_0001_01_000005, NodeId: bd18951cf78e:36999, NodeHttpAddress: bd18951cf78e:8042, Resource: <memory:1024, vCores:1>, Priority: 20, Token: null, ] queue=default: capacity=1.0, absoluteCapacity=1.0, usedResources=<memory:5120, vCores:4>, usedCapacity=0.625, absoluteUsedCapacity=0.625, numApps=1, numContainers=4 clusterResource=<memory:8192, vCores:8>
2018-04-01 19:58:06,861 INFO org.apache.hadoop.yarn.server.resourcemanager.scheduler.capacity.ParentQueue: Re-sorting assigned queue: root.default stats: default: capacity=1.0, absoluteCapacity=1.0, usedResources=<memory:6144, vCores:5>, usedCapacity=0.75, absoluteUsedCapacity=0.75, numApps=1, numContainers=5
2018-04-01 19:58:06,861 INFO org.apache.hadoop.yarn.server.resourcemanager.scheduler.capacity.ParentQueue: assignedContainer queue=root usedCapacity=0.75 absoluteUsedCapacity=0.75 used=<memory:6144, vCores:5> cluster=<memory:8192, vCores:8>
2018-04-01 19:58:06,861 INFO org.apache.hadoop.yarn.server.resourcemanager.rmcontainer.RMContainerImpl: container_1522627038528_0001_01_000006 Container Transitioned from NEW to ALLOCATED
2018-04-01 19:58:06,861 INFO org.apache.hadoop.yarn.server.resourcemanager.RMAuditLogger: USER=root	OPERATION=AM Allocated Container	TARGET=SchedulerApp	RESULT=SUCCESS	APPID=application_1522627038528_0001	CONTAINERID=container_1522627038528_0001_01_000006
2018-04-01 19:58:06,862 INFO org.apache.hadoop.yarn.server.resourcemanager.scheduler.SchedulerNode: Assigned container container_1522627038528_0001_01_000006 of capacity <memory:1024, vCores:1> on host bd18951cf78e:36999, which has 6 containers, <memory:7168, vCores:6> used and <memory:1024, vCores:2> available after allocation
2018-04-01 19:58:06,862 INFO org.apache.hadoop.yarn.server.resourcemanager.scheduler.capacity.LeafQueue: assignedContainer application attempt=appattempt_1522627038528_0001_000001 container=Container: [ContainerId: container_1522627038528_0001_01_000006, NodeId: bd18951cf78e:36999, NodeHttpAddress: bd18951cf78e:8042, Resource: <memory:1024, vCores:1>, Priority: 20, Token: null, ] queue=default: capacity=1.0, absoluteCapacity=1.0, usedResources=<memory:6144, vCores:5>, usedCapacity=0.75, absoluteUsedCapacity=0.75, numApps=1, numContainers=5 clusterResource=<memory:8192, vCores:8>
2018-04-01 19:58:06,862 INFO org.apache.hadoop.yarn.server.resourcemanager.scheduler.capacity.ParentQueue: Re-sorting assigned queue: root.default stats: default: capacity=1.0, absoluteCapacity=1.0, usedResources=<memory:7168, vCores:6>, usedCapacity=0.875, absoluteUsedCapacity=0.875, numApps=1, numContainers=6
2018-04-01 19:58:06,862 INFO org.apache.hadoop.yarn.server.resourcemanager.scheduler.capacity.ParentQueue: assignedContainer queue=root usedCapacity=0.875 absoluteUsedCapacity=0.875 used=<memory:7168, vCores:6> cluster=<memory:8192, vCores:8>
2018-04-01 19:58:06,863 INFO org.apache.hadoop.yarn.server.resourcemanager.rmcontainer.RMContainerImpl: container_1522627038528_0001_01_000007 Container Transitioned from NEW to ALLOCATED
2018-04-01 19:58:06,863 INFO org.apache.hadoop.yarn.server.resourcemanager.RMAuditLogger: USER=root	OPERATION=AM Allocated Container	TARGET=SchedulerApp	RESULT=SUCCESS	APPID=application_1522627038528_0001	CONTAINERID=container_1522627038528_0001_01_000007
2018-04-01 19:58:06,863 INFO org.apache.hadoop.yarn.server.resourcemanager.scheduler.SchedulerNode: Assigned container container_1522627038528_0001_01_000007 of capacity <memory:1024, vCores:1> on host bd18951cf78e:36999, which has 7 containers, <memory:8192, vCores:7> used and <memory:0, vCores:1> available after allocation
2018-04-01 19:58:06,863 INFO org.apache.hadoop.yarn.server.resourcemanager.scheduler.capacity.LeafQueue: assignedContainer application attempt=appattempt_1522627038528_0001_000001 container=Container: [ContainerId: container_1522627038528_0001_01_000007, NodeId: bd18951cf78e:36999, NodeHttpAddress: bd18951cf78e:8042, Resource: <memory:1024, vCores:1>, Priority: 20, Token: null, ] queue=default: capacity=1.0, absoluteCapacity=1.0, usedResources=<memory:7168, vCores:6>, usedCapacity=0.875, absoluteUsedCapacity=0.875, numApps=1, numContainers=6 clusterResource=<memory:8192, vCores:8>
2018-04-01 19:58:06,863 INFO org.apache.hadoop.yarn.server.resourcemanager.scheduler.capacity.ParentQueue: Re-sorting assigned queue: root.default stats: default: capacity=1.0, absoluteCapacity=1.0, usedResources=<memory:8192, vCores:7>, usedCapacity=1.0, absoluteUsedCapacity=1.0, numApps=1, numContainers=7
2018-04-01 19:58:06,863 INFO org.apache.hadoop.yarn.server.resourcemanager.scheduler.capacity.ParentQueue: assignedContainer queue=root usedCapacity=1.0 absoluteUsedCapacity=1.0 used=<memory:8192, vCores:7> cluster=<memory:8192, vCores:8>
2018-04-01 19:58:06,978 INFO org.apache.hadoop.yarn.server.resourcemanager.security.NMTokenSecretManagerInRM: Sending NMToken for nodeId : bd18951cf78e:36999 for container : container_1522627038528_0001_01_000002
2018-04-01 19:58:06,979 INFO org.apache.hadoop.yarn.server.resourcemanager.rmcontainer.RMContainerImpl: container_1522627038528_0001_01_000002 Container Transitioned from ALLOCATED to ACQUIRED
2018-04-01 19:58:06,980 INFO org.apache.hadoop.yarn.server.resourcemanager.rmcontainer.RMContainerImpl: container_1522627038528_0001_01_000003 Container Transitioned from ALLOCATED to ACQUIRED
2018-04-01 19:58:06,981 INFO org.apache.hadoop.yarn.server.resourcemanager.rmcontainer.RMContainerImpl: container_1522627038528_0001_01_000004 Container Transitioned from ALLOCATED to ACQUIRED
2018-04-01 19:58:06,983 INFO org.apache.hadoop.yarn.server.resourcemanager.rmcontainer.RMContainerImpl: container_1522627038528_0001_01_000005 Container Transitioned from ALLOCATED to ACQUIRED
2018-04-01 19:58:06,984 INFO org.apache.hadoop.yarn.server.resourcemanager.rmcontainer.RMContainerImpl: container_1522627038528_0001_01_000006 Container Transitioned from ALLOCATED to ACQUIRED
2018-04-01 19:58:06,985 INFO org.apache.hadoop.yarn.server.resourcemanager.rmcontainer.RMContainerImpl: container_1522627038528_0001_01_000007 Container Transitioned from ALLOCATED to ACQUIRED
2018-04-01 19:58:07,858 INFO org.apache.hadoop.yarn.server.resourcemanager.rmcontainer.RMContainerImpl: container_1522627038528_0001_01_000002 Container Transitioned from ACQUIRED to RUNNING
2018-04-01 19:58:07,859 INFO org.apache.hadoop.yarn.server.resourcemanager.rmcontainer.RMContainerImpl: container_1522627038528_0001_01_000003 Container Transitioned from ACQUIRED to RUNNING
2018-04-01 19:58:07,860 INFO org.apache.hadoop.yarn.server.resourcemanager.rmcontainer.RMContainerImpl: container_1522627038528_0001_01_000004 Container Transitioned from ACQUIRED to RUNNING
2018-04-01 19:58:07,860 INFO org.apache.hadoop.yarn.server.resourcemanager.rmcontainer.RMContainerImpl: container_1522627038528_0001_01_000005 Container Transitioned from ACQUIRED to RUNNING
2018-04-01 19:58:07,860 INFO org.apache.hadoop.yarn.server.resourcemanager.rmcontainer.RMContainerImpl: container_1522627038528_0001_01_000006 Container Transitioned from ACQUIRED to RUNNING
2018-04-01 19:58:07,861 INFO org.apache.hadoop.yarn.server.resourcemanager.rmcontainer.RMContainerImpl: container_1522627038528_0001_01_000007 Container Transitioned from ACQUIRED to RUNNING
2018-04-01 19:58:16,069 INFO org.apache.hadoop.yarn.server.resourcemanager.rmcontainer.RMContainerImpl: container_1522627038528_0001_01_000002 Container Transitioned from RUNNING to COMPLETED
2018-04-01 19:58:16,069 INFO org.apache.hadoop.yarn.server.resourcemanager.scheduler.common.fica.FiCaSchedulerApp: Completed container: container_1522627038528_0001_01_000002 in state: COMPLETED event:FINISHED
2018-04-01 19:58:16,069 INFO org.apache.hadoop.yarn.server.resourcemanager.RMAuditLogger: USER=root	OPERATION=AM Released Container	TARGET=SchedulerApp	RESULT=SUCCESS	APPID=application_1522627038528_0001	CONTAINERID=container_1522627038528_0001_01_000002
2018-04-01 19:58:16,069 INFO org.apache.hadoop.yarn.server.resourcemanager.scheduler.SchedulerNode: Released container container_1522627038528_0001_01_000002 of capacity <memory:1024, vCores:1> on host bd18951cf78e:36999, which currently has 6 containers, <memory:7168, vCores:6> used and <memory:1024, vCores:2> available, release resources=true
2018-04-01 19:58:16,070 INFO org.apache.hadoop.yarn.server.resourcemanager.scheduler.capacity.LeafQueue: default used=<memory:7168, vCores:6> numContainers=6 user=root user-resources=<memory:7168, vCores:6>
2018-04-01 19:58:16,070 INFO org.apache.hadoop.yarn.server.resourcemanager.scheduler.capacity.LeafQueue: completedContainer container=Container: [ContainerId: container_1522627038528_0001_01_000002, NodeId: bd18951cf78e:36999, NodeHttpAddress: bd18951cf78e:8042, Resource: <memory:1024, vCores:1>, Priority: 20, Token: Token { kind: ContainerToken, service: 172.20.0.2:36999 }, ] queue=default: capacity=1.0, absoluteCapacity=1.0, usedResources=<memory:7168, vCores:6>, usedCapacity=0.875, absoluteUsedCapacity=0.875, numApps=1, numContainers=6 cluster=<memory:8192, vCores:8>
2018-04-01 19:58:16,070 INFO org.apache.hadoop.yarn.server.resourcemanager.scheduler.capacity.ParentQueue: completedContainer queue=root usedCapacity=0.875 absoluteUsedCapacity=0.875 used=<memory:7168, vCores:6> cluster=<memory:8192, vCores:8>
2018-04-01 19:58:16,070 INFO org.apache.hadoop.yarn.server.resourcemanager.scheduler.capacity.ParentQueue: Re-sorting completed queue: root.default stats: default: capacity=1.0, absoluteCapacity=1.0, usedResources=<memory:7168, vCores:6>, usedCapacity=0.875, absoluteUsedCapacity=0.875, numApps=1, numContainers=6
2018-04-01 19:58:16,070 INFO org.apache.hadoop.yarn.server.resourcemanager.scheduler.capacity.CapacityScheduler: Application attempt appattempt_1522627038528_0001_000001 released container container_1522627038528_0001_01_000002 on node: host: bd18951cf78e:36999 #containers=6 available=<memory:1024, vCores:2> used=<memory:7168, vCores:6> with event: FINISHED
2018-04-01 19:58:16,070 INFO org.apache.hadoop.yarn.server.resourcemanager.rmcontainer.RMContainerImpl: container_1522627038528_0001_01_000005 Container Transitioned from RUNNING to COMPLETED
2018-04-01 19:58:16,071 INFO org.apache.hadoop.yarn.server.resourcemanager.scheduler.common.fica.FiCaSchedulerApp: Completed container: container_1522627038528_0001_01_000005 in state: COMPLETED event:FINISHED
2018-04-01 19:58:16,071 INFO org.apache.hadoop.yarn.server.resourcemanager.RMAuditLogger: USER=root	OPERATION=AM Released Container	TARGET=SchedulerApp	RESULT=SUCCESS	APPID=application_1522627038528_0001	CONTAINERID=container_1522627038528_0001_01_000005
2018-04-01 19:58:16,071 INFO org.apache.hadoop.yarn.server.resourcemanager.scheduler.SchedulerNode: Released container container_1522627038528_0001_01_000005 of capacity <memory:1024, vCores:1> on host bd18951cf78e:36999, which currently has 5 containers, <memory:6144, vCores:5> used and <memory:2048, vCores:3> available, release resources=true
2018-04-01 19:58:16,071 INFO org.apache.hadoop.yarn.server.resourcemanager.scheduler.capacity.LeafQueue: default used=<memory:6144, vCores:5> numContainers=5 user=root user-resources=<memory:6144, vCores:5>
2018-04-01 19:58:16,071 INFO org.apache.hadoop.yarn.server.resourcemanager.scheduler.capacity.LeafQueue: completedContainer container=Container: [ContainerId: container_1522627038528_0001_01_000005, NodeId: bd18951cf78e:36999, NodeHttpAddress: bd18951cf78e:8042, Resource: <memory:1024, vCores:1>, Priority: 20, Token: Token { kind: ContainerToken, service: 172.20.0.2:36999 }, ] queue=default: capacity=1.0, absoluteCapacity=1.0, usedResources=<memory:6144, vCores:5>, usedCapacity=0.75, absoluteUsedCapacity=0.75, numApps=1, numContainers=5 cluster=<memory:8192, vCores:8>
2018-04-01 19:58:16,071 INFO org.apache.hadoop.yarn.server.resourcemanager.scheduler.capacity.ParentQueue: completedContainer queue=root usedCapacity=0.75 absoluteUsedCapacity=0.75 used=<memory:6144, vCores:5> cluster=<memory:8192, vCores:8>
2018-04-01 19:58:16,071 INFO org.apache.hadoop.yarn.server.resourcemanager.scheduler.capacity.ParentQueue: Re-sorting completed queue: root.default stats: default: capacity=1.0, absoluteCapacity=1.0, usedResources=<memory:6144, vCores:5>, usedCapacity=0.75, absoluteUsedCapacity=0.75, numApps=1, numContainers=5
2018-04-01 19:58:16,071 INFO org.apache.hadoop.yarn.server.resourcemanager.scheduler.capacity.CapacityScheduler: Application attempt appattempt_1522627038528_0001_000001 released container container_1522627038528_0001_01_000005 on node: host: bd18951cf78e:36999 #containers=5 available=<memory:2048, vCores:3> used=<memory:6144, vCores:5> with event: FINISHED
2018-04-01 19:58:16,072 INFO org.apache.hadoop.yarn.server.resourcemanager.rmcontainer.RMContainerImpl: container_1522627038528_0001_01_000006 Container Transitioned from RUNNING to COMPLETED
2018-04-01 19:58:16,072 INFO org.apache.hadoop.yarn.server.resourcemanager.scheduler.common.fica.FiCaSchedulerApp: Completed container: container_1522627038528_0001_01_000006 in state: COMPLETED event:FINISHED
2018-04-01 19:58:16,072 INFO org.apache.hadoop.yarn.server.resourcemanager.RMAuditLogger: USER=root	OPERATION=AM Released Container	TARGET=SchedulerApp	RESULT=SUCCESS	APPID=application_1522627038528_0001	CONTAINERID=container_1522627038528_0001_01_000006
2018-04-01 19:58:16,072 INFO org.apache.hadoop.yarn.server.resourcemanager.scheduler.SchedulerNode: Released container container_1522627038528_0001_01_000006 of capacity <memory:1024, vCores:1> on host bd18951cf78e:36999, which currently has 4 containers, <memory:5120, vCores:4> used and <memory:3072, vCores:4> available, release resources=true
2018-04-01 19:58:16,072 INFO org.apache.hadoop.yarn.server.resourcemanager.scheduler.capacity.LeafQueue: default used=<memory:5120, vCores:4> numContainers=4 user=root user-resources=<memory:5120, vCores:4>
2018-04-01 19:58:16,072 INFO org.apache.hadoop.yarn.server.resourcemanager.scheduler.capacity.LeafQueue: completedContainer container=Container: [ContainerId: container_1522627038528_0001_01_000006, NodeId: bd18951cf78e:36999, NodeHttpAddress: bd18951cf78e:8042, Resource: <memory:1024, vCores:1>, Priority: 20, Token: Token { kind: ContainerToken, service: 172.20.0.2:36999 }, ] queue=default: capacity=1.0, absoluteCapacity=1.0, usedResources=<memory:5120, vCores:4>, usedCapacity=0.625, absoluteUsedCapacity=0.625, numApps=1, numContainers=4 cluster=<memory:8192, vCores:8>
2018-04-01 19:58:16,072 INFO org.apache.hadoop.yarn.server.resourcemanager.scheduler.capacity.ParentQueue: completedContainer queue=root usedCapacity=0.625 absoluteUsedCapacity=0.625 used=<memory:5120, vCores:4> cluster=<memory:8192, vCores:8>
2018-04-01 19:58:16,072 INFO org.apache.hadoop.yarn.server.resourcemanager.scheduler.capacity.ParentQueue: Re-sorting completed queue: root.default stats: default: capacity=1.0, absoluteCapacity=1.0, usedResources=<memory:5120, vCores:4>, usedCapacity=0.625, absoluteUsedCapacity=0.625, numApps=1, numContainers=4
2018-04-01 19:58:16,072 INFO org.apache.hadoop.yarn.server.resourcemanager.scheduler.capacity.CapacityScheduler: Application attempt appattempt_1522627038528_0001_000001 released container container_1522627038528_0001_01_000006 on node: host: bd18951cf78e:36999 #containers=4 available=<memory:3072, vCores:4> used=<memory:5120, vCores:4> with event: FINISHED
2018-04-01 19:58:16,073 INFO org.apache.hadoop.yarn.server.resourcemanager.rmcontainer.RMContainerImpl: container_1522627038528_0001_01_000007 Container Transitioned from RUNNING to COMPLETED
2018-04-01 19:58:16,073 INFO org.apache.hadoop.yarn.server.resourcemanager.scheduler.common.fica.FiCaSchedulerApp: Completed container: container_1522627038528_0001_01_000007 in state: COMPLETED event:FINISHED
2018-04-01 19:58:16,073 INFO org.apache.hadoop.yarn.server.resourcemanager.RMAuditLogger: USER=root	OPERATION=AM Released Container	TARGET=SchedulerApp	RESULT=SUCCESS	APPID=application_1522627038528_0001	CONTAINERID=container_1522627038528_0001_01_000007
2018-04-01 19:58:16,073 INFO org.apache.hadoop.yarn.server.resourcemanager.scheduler.SchedulerNode: Released container container_1522627038528_0001_01_000007 of capacity <memory:1024, vCores:1> on host bd18951cf78e:36999, which currently has 3 containers, <memory:4096, vCores:3> used and <memory:4096, vCores:5> available, release resources=true
2018-04-01 19:58:16,073 INFO org.apache.hadoop.yarn.server.resourcemanager.scheduler.capacity.LeafQueue: default used=<memory:4096, vCores:3> numContainers=3 user=root user-resources=<memory:4096, vCores:3>
2018-04-01 19:58:16,073 INFO org.apache.hadoop.yarn.server.resourcemanager.scheduler.capacity.LeafQueue: completedContainer container=Container: [ContainerId: container_1522627038528_0001_01_000007, NodeId: bd18951cf78e:36999, NodeHttpAddress: bd18951cf78e:8042, Resource: <memory:1024, vCores:1>, Priority: 20, Token: Token { kind: ContainerToken, service: 172.20.0.2:36999 }, ] queue=default: capacity=1.0, absoluteCapacity=1.0, usedResources=<memory:4096, vCores:3>, usedCapacity=0.5, absoluteUsedCapacity=0.5, numApps=1, numContainers=3 cluster=<memory:8192, vCores:8>
2018-04-01 19:58:16,073 INFO org.apache.hadoop.yarn.server.resourcemanager.scheduler.capacity.ParentQueue: completedContainer queue=root usedCapacity=0.5 absoluteUsedCapacity=0.5 used=<memory:4096, vCores:3> cluster=<memory:8192, vCores:8>
2018-04-01 19:58:16,073 INFO org.apache.hadoop.yarn.server.resourcemanager.scheduler.capacity.ParentQueue: Re-sorting completed queue: root.default stats: default: capacity=1.0, absoluteCapacity=1.0, usedResources=<memory:4096, vCores:3>, usedCapacity=0.5, absoluteUsedCapacity=0.5, numApps=1, numContainers=3
2018-04-01 19:58:16,073 INFO org.apache.hadoop.yarn.server.resourcemanager.scheduler.capacity.CapacityScheduler: Application attempt appattempt_1522627038528_0001_000001 released container container_1522627038528_0001_01_000007 on node: host: bd18951cf78e:36999 #containers=3 available=<memory:4096, vCores:5> used=<memory:4096, vCores:3> with event: FINISHED
2018-04-01 19:58:16,074 INFO org.apache.hadoop.yarn.server.resourcemanager.rmcontainer.RMContainerImpl: container_1522627038528_0001_01_000004 Container Transitioned from RUNNING to COMPLETED
2018-04-01 19:58:16,074 INFO org.apache.hadoop.yarn.server.resourcemanager.scheduler.common.fica.FiCaSchedulerApp: Completed container: container_1522627038528_0001_01_000004 in state: COMPLETED event:FINISHED
2018-04-01 19:58:16,074 INFO org.apache.hadoop.yarn.server.resourcemanager.RMAuditLogger: USER=root	OPERATION=AM Released Container	TARGET=SchedulerApp	RESULT=SUCCESS	APPID=application_1522627038528_0001	CONTAINERID=container_1522627038528_0001_01_000004
2018-04-01 19:58:16,074 INFO org.apache.hadoop.yarn.server.resourcemanager.scheduler.SchedulerNode: Released container container_1522627038528_0001_01_000004 of capacity <memory:1024, vCores:1> on host bd18951cf78e:36999, which currently has 2 containers, <memory:3072, vCores:2> used and <memory:5120, vCores:6> available, release resources=true
2018-04-01 19:58:16,074 INFO org.apache.hadoop.yarn.server.resourcemanager.scheduler.capacity.LeafQueue: default used=<memory:3072, vCores:2> numContainers=2 user=root user-resources=<memory:3072, vCores:2>
2018-04-01 19:58:16,074 INFO org.apache.hadoop.yarn.server.resourcemanager.scheduler.capacity.LeafQueue: completedContainer container=Container: [ContainerId: container_1522627038528_0001_01_000004, NodeId: bd18951cf78e:36999, NodeHttpAddress: bd18951cf78e:8042, Resource: <memory:1024, vCores:1>, Priority: 20, Token: Token { kind: ContainerToken, service: 172.20.0.2:36999 }, ] queue=default: capacity=1.0, absoluteCapacity=1.0, usedResources=<memory:3072, vCores:2>, usedCapacity=0.375, absoluteUsedCapacity=0.375, numApps=1, numContainers=2 cluster=<memory:8192, vCores:8>
2018-04-01 19:58:16,074 INFO org.apache.hadoop.yarn.server.resourcemanager.scheduler.capacity.ParentQueue: completedContainer queue=root usedCapacity=0.375 absoluteUsedCapacity=0.375 used=<memory:3072, vCores:2> cluster=<memory:8192, vCores:8>
2018-04-01 19:58:16,074 INFO org.apache.hadoop.yarn.server.resourcemanager.scheduler.capacity.ParentQueue: Re-sorting completed queue: root.default stats: default: capacity=1.0, absoluteCapacity=1.0, usedResources=<memory:3072, vCores:2>, usedCapacity=0.375, absoluteUsedCapacity=0.375, numApps=1, numContainers=2
2018-04-01 19:58:16,074 INFO org.apache.hadoop.yarn.server.resourcemanager.scheduler.capacity.CapacityScheduler: Application attempt appattempt_1522627038528_0001_000001 released container container_1522627038528_0001_01_000004 on node: host: bd18951cf78e:36999 #containers=2 available=<memory:5120, vCores:6> used=<memory:3072, vCores:2> with event: FINISHED
2018-04-01 19:58:16,075 INFO org.apache.hadoop.yarn.server.resourcemanager.rmcontainer.RMContainerImpl: container_1522627038528_0001_01_000003 Container Transitioned from RUNNING to COMPLETED
2018-04-01 19:58:16,075 INFO org.apache.hadoop.yarn.server.resourcemanager.scheduler.common.fica.FiCaSchedulerApp: Completed container: container_1522627038528_0001_01_000003 in state: COMPLETED event:FINISHED
2018-04-01 19:58:16,075 INFO org.apache.hadoop.yarn.server.resourcemanager.RMAuditLogger: USER=root	OPERATION=AM Released Container	TARGET=SchedulerApp	RESULT=SUCCESS	APPID=application_1522627038528_0001	CONTAINERID=container_1522627038528_0001_01_000003
2018-04-01 19:58:16,075 INFO org.apache.hadoop.yarn.server.resourcemanager.scheduler.SchedulerNode: Released container container_1522627038528_0001_01_000003 of capacity <memory:1024, vCores:1> on host bd18951cf78e:36999, which currently has 1 containers, <memory:2048, vCores:1> used and <memory:6144, vCores:7> available, release resources=true
2018-04-01 19:58:16,075 INFO org.apache.hadoop.yarn.server.resourcemanager.scheduler.capacity.LeafQueue: default used=<memory:2048, vCores:1> numContainers=1 user=root user-resources=<memory:2048, vCores:1>
2018-04-01 19:58:16,075 INFO org.apache.hadoop.yarn.server.resourcemanager.scheduler.capacity.LeafQueue: completedContainer container=Container: [ContainerId: container_1522627038528_0001_01_000003, NodeId: bd18951cf78e:36999, NodeHttpAddress: bd18951cf78e:8042, Resource: <memory:1024, vCores:1>, Priority: 20, Token: Token { kind: ContainerToken, service: 172.20.0.2:36999 }, ] queue=default: capacity=1.0, absoluteCapacity=1.0, usedResources=<memory:2048, vCores:1>, usedCapacity=0.25, absoluteUsedCapacity=0.25, numApps=1, numContainers=1 cluster=<memory:8192, vCores:8>
2018-04-01 19:58:16,075 INFO org.apache.hadoop.yarn.server.resourcemanager.scheduler.capacity.ParentQueue: completedContainer queue=root usedCapacity=0.25 absoluteUsedCapacity=0.25 used=<memory:2048, vCores:1> cluster=<memory:8192, vCores:8>
2018-04-01 19:58:16,075 INFO org.apache.hadoop.yarn.server.resourcemanager.scheduler.capacity.ParentQueue: Re-sorting completed queue: root.default stats: default: capacity=1.0, absoluteCapacity=1.0, usedResources=<memory:2048, vCores:1>, usedCapacity=0.25, absoluteUsedCapacity=0.25, numApps=1, numContainers=1
2018-04-01 19:58:16,075 INFO org.apache.hadoop.yarn.server.resourcemanager.scheduler.capacity.CapacityScheduler: Application attempt appattempt_1522627038528_0001_000001 released container container_1522627038528_0001_01_000003 on node: host: bd18951cf78e:36999 #containers=1 available=<memory:6144, vCores:7> used=<memory:2048, vCores:1> with event: FINISHED
2018-04-01 19:58:16,076 INFO org.apache.hadoop.yarn.server.resourcemanager.rmcontainer.RMContainerImpl: container_1522627038528_0001_01_000008 Container Transitioned from NEW to ALLOCATED
2018-04-01 19:58:16,076 INFO org.apache.hadoop.yarn.server.resourcemanager.RMAuditLogger: USER=root	OPERATION=AM Allocated Container	TARGET=SchedulerApp	RESULT=SUCCESS	APPID=application_1522627038528_0001	CONTAINERID=container_1522627038528_0001_01_000008
2018-04-01 19:58:16,076 INFO org.apache.hadoop.yarn.server.resourcemanager.scheduler.SchedulerNode: Assigned container container_1522627038528_0001_01_000008 of capacity <memory:1024, vCores:1> on host bd18951cf78e:36999, which has 2 containers, <memory:3072, vCores:2> used and <memory:5120, vCores:6> available after allocation
2018-04-01 19:58:16,076 INFO org.apache.hadoop.yarn.server.resourcemanager.scheduler.capacity.LeafQueue: assignedContainer application attempt=appattempt_1522627038528_0001_000001 container=Container: [ContainerId: container_1522627038528_0001_01_000008, NodeId: bd18951cf78e:36999, NodeHttpAddress: bd18951cf78e:8042, Resource: <memory:1024, vCores:1>, Priority: 20, Token: null, ] queue=default: capacity=1.0, absoluteCapacity=1.0, usedResources=<memory:2048, vCores:1>, usedCapacity=0.25, absoluteUsedCapacity=0.25, numApps=1, numContainers=1 clusterResource=<memory:8192, vCores:8>
2018-04-01 19:58:16,076 INFO org.apache.hadoop.yarn.server.resourcemanager.scheduler.capacity.ParentQueue: Re-sorting assigned queue: root.default stats: default: capacity=1.0, absoluteCapacity=1.0, usedResources=<memory:3072, vCores:2>, usedCapacity=0.375, absoluteUsedCapacity=0.375, numApps=1, numContainers=2
2018-04-01 19:58:16,076 INFO org.apache.hadoop.yarn.server.resourcemanager.scheduler.capacity.ParentQueue: assignedContainer queue=root usedCapacity=0.375 absoluteUsedCapacity=0.375 used=<memory:3072, vCores:2> cluster=<memory:8192, vCores:8>
2018-04-01 19:58:16,077 INFO org.apache.hadoop.yarn.server.resourcemanager.rmcontainer.RMContainerImpl: container_1522627038528_0001_01_000009 Container Transitioned from NEW to ALLOCATED
2018-04-01 19:58:16,077 INFO org.apache.hadoop.yarn.server.resourcemanager.RMAuditLogger: USER=root	OPERATION=AM Allocated Container	TARGET=SchedulerApp	RESULT=SUCCESS	APPID=application_1522627038528_0001	CONTAINERID=container_1522627038528_0001_01_000009
2018-04-01 19:58:16,077 INFO org.apache.hadoop.yarn.server.resourcemanager.scheduler.SchedulerNode: Assigned container container_1522627038528_0001_01_000009 of capacity <memory:1024, vCores:1> on host bd18951cf78e:36999, which has 3 containers, <memory:4096, vCores:3> used and <memory:4096, vCores:5> available after allocation
2018-04-01 19:58:16,077 INFO org.apache.hadoop.yarn.server.resourcemanager.scheduler.capacity.LeafQueue: assignedContainer application attempt=appattempt_1522627038528_0001_000001 container=Container: [ContainerId: container_1522627038528_0001_01_000009, NodeId: bd18951cf78e:36999, NodeHttpAddress: bd18951cf78e:8042, Resource: <memory:1024, vCores:1>, Priority: 20, Token: null, ] queue=default: capacity=1.0, absoluteCapacity=1.0, usedResources=<memory:3072, vCores:2>, usedCapacity=0.375, absoluteUsedCapacity=0.375, numApps=1, numContainers=2 clusterResource=<memory:8192, vCores:8>
2018-04-01 19:58:16,077 INFO org.apache.hadoop.yarn.server.resourcemanager.scheduler.capacity.ParentQueue: Re-sorting assigned queue: root.default stats: default: capacity=1.0, absoluteCapacity=1.0, usedResources=<memory:4096, vCores:3>, usedCapacity=0.5, absoluteUsedCapacity=0.5, numApps=1, numContainers=3
2018-04-01 19:58:16,077 INFO org.apache.hadoop.yarn.server.resourcemanager.scheduler.capacity.ParentQueue: assignedContainer queue=root usedCapacity=0.5 absoluteUsedCapacity=0.5 used=<memory:4096, vCores:3> cluster=<memory:8192, vCores:8>
2018-04-01 19:58:16,078 INFO org.apache.hadoop.yarn.server.resourcemanager.rmcontainer.RMContainerImpl: container_1522627038528_0001_01_000010 Container Transitioned from NEW to ALLOCATED
2018-04-01 19:58:16,078 INFO org.apache.hadoop.yarn.server.resourcemanager.RMAuditLogger: USER=root	OPERATION=AM Allocated Container	TARGET=SchedulerApp	RESULT=SUCCESS	APPID=application_1522627038528_0001	CONTAINERID=container_1522627038528_0001_01_000010
2018-04-01 19:58:16,078 INFO org.apache.hadoop.yarn.server.resourcemanager.scheduler.SchedulerNode: Assigned container container_1522627038528_0001_01_000010 of capacity <memory:1024, vCores:1> on host bd18951cf78e:36999, which has 4 containers, <memory:5120, vCores:4> used and <memory:3072, vCores:4> available after allocation
2018-04-01 19:58:16,078 INFO org.apache.hadoop.yarn.server.resourcemanager.scheduler.capacity.LeafQueue: assignedContainer application attempt=appattempt_1522627038528_0001_000001 container=Container: [ContainerId: container_1522627038528_0001_01_000010, NodeId: bd18951cf78e:36999, NodeHttpAddress: bd18951cf78e:8042, Resource: <memory:1024, vCores:1>, Priority: 20, Token: null, ] queue=default: capacity=1.0, absoluteCapacity=1.0, usedResources=<memory:4096, vCores:3>, usedCapacity=0.5, absoluteUsedCapacity=0.5, numApps=1, numContainers=3 clusterResource=<memory:8192, vCores:8>
2018-04-01 19:58:16,078 INFO org.apache.hadoop.yarn.server.resourcemanager.scheduler.capacity.ParentQueue: Re-sorting assigned queue: root.default stats: default: capacity=1.0, absoluteCapacity=1.0, usedResources=<memory:5120, vCores:4>, usedCapacity=0.625, absoluteUsedCapacity=0.625, numApps=1, numContainers=4
2018-04-01 19:58:16,078 INFO org.apache.hadoop.yarn.server.resourcemanager.scheduler.capacity.ParentQueue: assignedContainer queue=root usedCapacity=0.625 absoluteUsedCapacity=0.625 used=<memory:5120, vCores:4> cluster=<memory:8192, vCores:8>
2018-04-01 19:58:16,079 INFO org.apache.hadoop.yarn.server.resourcemanager.rmcontainer.RMContainerImpl: container_1522627038528_0001_01_000011 Container Transitioned from NEW to ALLOCATED
2018-04-01 19:58:16,079 INFO org.apache.hadoop.yarn.server.resourcemanager.RMAuditLogger: USER=root	OPERATION=AM Allocated Container	TARGET=SchedulerApp	RESULT=SUCCESS	APPID=application_1522627038528_0001	CONTAINERID=container_1522627038528_0001_01_000011
2018-04-01 19:58:16,079 INFO org.apache.hadoop.yarn.server.resourcemanager.scheduler.SchedulerNode: Assigned container container_1522627038528_0001_01_000011 of capacity <memory:1024, vCores:1> on host bd18951cf78e:36999, which has 5 containers, <memory:6144, vCores:5> used and <memory:2048, vCores:3> available after allocation
2018-04-01 19:58:16,079 INFO org.apache.hadoop.yarn.server.resourcemanager.scheduler.capacity.LeafQueue: assignedContainer application attempt=appattempt_1522627038528_0001_000001 container=Container: [ContainerId: container_1522627038528_0001_01_000011, NodeId: bd18951cf78e:36999, NodeHttpAddress: bd18951cf78e:8042, Resource: <memory:1024, vCores:1>, Priority: 20, Token: null, ] queue=default: capacity=1.0, absoluteCapacity=1.0, usedResources=<memory:5120, vCores:4>, usedCapacity=0.625, absoluteUsedCapacity=0.625, numApps=1, numContainers=4 clusterResource=<memory:8192, vCores:8>
2018-04-01 19:58:16,079 INFO org.apache.hadoop.yarn.server.resourcemanager.scheduler.capacity.ParentQueue: Re-sorting assigned queue: root.default stats: default: capacity=1.0, absoluteCapacity=1.0, usedResources=<memory:6144, vCores:5>, usedCapacity=0.75, absoluteUsedCapacity=0.75, numApps=1, numContainers=5
2018-04-01 19:58:16,079 INFO org.apache.hadoop.yarn.server.resourcemanager.scheduler.capacity.ParentQueue: assignedContainer queue=root usedCapacity=0.75 absoluteUsedCapacity=0.75 used=<memory:6144, vCores:5> cluster=<memory:8192, vCores:8>
2018-04-01 19:58:16,080 INFO org.apache.hadoop.yarn.server.resourcemanager.rmcontainer.RMContainerImpl: container_1522627038528_0001_01_000012 Container Transitioned from NEW to ALLOCATED
2018-04-01 19:58:16,080 INFO org.apache.hadoop.yarn.server.resourcemanager.RMAuditLogger: USER=root	OPERATION=AM Allocated Container	TARGET=SchedulerApp	RESULT=SUCCESS	APPID=application_1522627038528_0001	CONTAINERID=container_1522627038528_0001_01_000012
2018-04-01 19:58:16,080 INFO org.apache.hadoop.yarn.server.resourcemanager.scheduler.SchedulerNode: Assigned container container_1522627038528_0001_01_000012 of capacity <memory:1024, vCores:1> on host bd18951cf78e:36999, which has 6 containers, <memory:7168, vCores:6> used and <memory:1024, vCores:2> available after allocation
2018-04-01 19:58:16,080 INFO org.apache.hadoop.yarn.server.resourcemanager.scheduler.capacity.LeafQueue: assignedContainer application attempt=appattempt_1522627038528_0001_000001 container=Container: [ContainerId: container_1522627038528_0001_01_000012, NodeId: bd18951cf78e:36999, NodeHttpAddress: bd18951cf78e:8042, Resource: <memory:1024, vCores:1>, Priority: 20, Token: null, ] queue=default: capacity=1.0, absoluteCapacity=1.0, usedResources=<memory:6144, vCores:5>, usedCapacity=0.75, absoluteUsedCapacity=0.75, numApps=1, numContainers=5 clusterResource=<memory:8192, vCores:8>
2018-04-01 19:58:16,080 INFO org.apache.hadoop.yarn.server.resourcemanager.scheduler.capacity.ParentQueue: Re-sorting assigned queue: root.default stats: default: capacity=1.0, absoluteCapacity=1.0, usedResources=<memory:7168, vCores:6>, usedCapacity=0.875, absoluteUsedCapacity=0.875, numApps=1, numContainers=6
2018-04-01 19:58:16,080 INFO org.apache.hadoop.yarn.server.resourcemanager.scheduler.capacity.ParentQueue: assignedContainer queue=root usedCapacity=0.875 absoluteUsedCapacity=0.875 used=<memory:7168, vCores:6> cluster=<memory:8192, vCores:8>
2018-04-01 19:58:16,081 INFO org.apache.hadoop.yarn.server.resourcemanager.rmcontainer.RMContainerImpl: container_1522627038528_0001_01_000013 Container Transitioned from NEW to ALLOCATED
2018-04-01 19:58:16,081 INFO org.apache.hadoop.yarn.server.resourcemanager.RMAuditLogger: USER=root	OPERATION=AM Allocated Container	TARGET=SchedulerApp	RESULT=SUCCESS	APPID=application_1522627038528_0001	CONTAINERID=container_1522627038528_0001_01_000013
2018-04-01 19:58:16,081 INFO org.apache.hadoop.yarn.server.resourcemanager.scheduler.SchedulerNode: Assigned container container_1522627038528_0001_01_000013 of capacity <memory:1024, vCores:1> on host bd18951cf78e:36999, which has 7 containers, <memory:8192, vCores:7> used and <memory:0, vCores:1> available after allocation
2018-04-01 19:58:16,081 INFO org.apache.hadoop.yarn.server.resourcemanager.scheduler.capacity.LeafQueue: assignedContainer application attempt=appattempt_1522627038528_0001_000001 container=Container: [ContainerId: container_1522627038528_0001_01_000013, NodeId: bd18951cf78e:36999, NodeHttpAddress: bd18951cf78e:8042, Resource: <memory:1024, vCores:1>, Priority: 20, Token: null, ] queue=default: capacity=1.0, absoluteCapacity=1.0, usedResources=<memory:7168, vCores:6>, usedCapacity=0.875, absoluteUsedCapacity=0.875, numApps=1, numContainers=6 clusterResource=<memory:8192, vCores:8>
2018-04-01 19:58:16,081 INFO org.apache.hadoop.yarn.server.resourcemanager.scheduler.capacity.ParentQueue: Re-sorting assigned queue: root.default stats: default: capacity=1.0, absoluteCapacity=1.0, usedResources=<memory:8192, vCores:7>, usedCapacity=1.0, absoluteUsedCapacity=1.0, numApps=1, numContainers=7
2018-04-01 19:58:16,082 INFO org.apache.hadoop.yarn.server.resourcemanager.scheduler.capacity.ParentQueue: assignedContainer queue=root usedCapacity=1.0 absoluteUsedCapacity=1.0 used=<memory:8192, vCores:7> cluster=<memory:8192, vCores:8>
2018-04-01 19:58:16,295 INFO org.apache.hadoop.yarn.server.resourcemanager.rmcontainer.RMContainerImpl: container_1522627038528_0001_01_000008 Container Transitioned from ALLOCATED to ACQUIRED
2018-04-01 19:58:16,297 INFO org.apache.hadoop.yarn.server.resourcemanager.rmcontainer.RMContainerImpl: container_1522627038528_0001_01_000009 Container Transitioned from ALLOCATED to ACQUIRED
2018-04-01 19:58:16,298 INFO org.apache.hadoop.yarn.server.resourcemanager.rmcontainer.RMContainerImpl: container_1522627038528_0001_01_000010 Container Transitioned from ALLOCATED to ACQUIRED
2018-04-01 19:58:16,299 INFO org.apache.hadoop.yarn.server.resourcemanager.rmcontainer.RMContainerImpl: container_1522627038528_0001_01_000011 Container Transitioned from ALLOCATED to ACQUIRED
2018-04-01 19:58:16,300 INFO org.apache.hadoop.yarn.server.resourcemanager.rmcontainer.RMContainerImpl: container_1522627038528_0001_01_000012 Container Transitioned from ALLOCATED to ACQUIRED
2018-04-01 19:58:16,301 INFO org.apache.hadoop.yarn.server.resourcemanager.rmcontainer.RMContainerImpl: container_1522627038528_0001_01_000013 Container Transitioned from ALLOCATED to ACQUIRED
2018-04-01 19:58:17,072 INFO org.apache.hadoop.yarn.server.resourcemanager.rmcontainer.RMContainerImpl: container_1522627038528_0001_01_000008 Container Transitioned from ACQUIRED to RUNNING
2018-04-01 19:58:17,073 INFO org.apache.hadoop.yarn.server.resourcemanager.rmcontainer.RMContainerImpl: container_1522627038528_0001_01_000009 Container Transitioned from ACQUIRED to RUNNING
2018-04-01 19:58:17,073 INFO org.apache.hadoop.yarn.server.resourcemanager.rmcontainer.RMContainerImpl: container_1522627038528_0001_01_000010 Container Transitioned from ACQUIRED to RUNNING
2018-04-01 19:58:17,074 INFO org.apache.hadoop.yarn.server.resourcemanager.rmcontainer.RMContainerImpl: container_1522627038528_0001_01_000011 Container Transitioned from ACQUIRED to RUNNING
2018-04-01 19:58:17,074 INFO org.apache.hadoop.yarn.server.resourcemanager.rmcontainer.RMContainerImpl: container_1522627038528_0001_01_000012 Container Transitioned from ACQUIRED to RUNNING
2018-04-01 19:58:17,074 INFO org.apache.hadoop.yarn.server.resourcemanager.rmcontainer.RMContainerImpl: container_1522627038528_0001_01_000013 Container Transitioned from ACQUIRED to RUNNING
2018-04-01 19:58:22,806 INFO org.apache.hadoop.yarn.server.resourcemanager.rmcontainer.RMContainerImpl: container_1522627038528_0001_01_000010 Container Transitioned from RUNNING to COMPLETED
2018-04-01 19:58:22,806 INFO org.apache.hadoop.yarn.server.resourcemanager.scheduler.common.fica.FiCaSchedulerApp: Completed container: container_1522627038528_0001_01_000010 in state: COMPLETED event:FINISHED
2018-04-01 19:58:22,807 INFO org.apache.hadoop.yarn.server.resourcemanager.RMAuditLogger: USER=root	OPERATION=AM Released Container	TARGET=SchedulerApp	RESULT=SUCCESS	APPID=application_1522627038528_0001	CONTAINERID=container_1522627038528_0001_01_000010
2018-04-01 19:58:22,807 INFO org.apache.hadoop.yarn.server.resourcemanager.scheduler.SchedulerNode: Released container container_1522627038528_0001_01_000010 of capacity <memory:1024, vCores:1> on host bd18951cf78e:36999, which currently has 6 containers, <memory:7168, vCores:6> used and <memory:1024, vCores:2> available, release resources=true
2018-04-01 19:58:22,807 INFO org.apache.hadoop.yarn.server.resourcemanager.scheduler.capacity.LeafQueue: default used=<memory:7168, vCores:6> numContainers=6 user=root user-resources=<memory:7168, vCores:6>
2018-04-01 19:58:22,808 INFO org.apache.hadoop.yarn.server.resourcemanager.scheduler.capacity.LeafQueue: completedContainer container=Container: [ContainerId: container_1522627038528_0001_01_000010, NodeId: bd18951cf78e:36999, NodeHttpAddress: bd18951cf78e:8042, Resource: <memory:1024, vCores:1>, Priority: 20, Token: Token { kind: ContainerToken, service: 172.20.0.2:36999 }, ] queue=default: capacity=1.0, absoluteCapacity=1.0, usedResources=<memory:7168, vCores:6>, usedCapacity=0.875, absoluteUsedCapacity=0.875, numApps=1, numContainers=6 cluster=<memory:8192, vCores:8>
2018-04-01 19:58:22,808 INFO org.apache.hadoop.yarn.server.resourcemanager.scheduler.capacity.ParentQueue: completedContainer queue=root usedCapacity=0.875 absoluteUsedCapacity=0.875 used=<memory:7168, vCores:6> cluster=<memory:8192, vCores:8>
2018-04-01 19:58:22,808 INFO org.apache.hadoop.yarn.server.resourcemanager.scheduler.capacity.ParentQueue: Re-sorting completed queue: root.default stats: default: capacity=1.0, absoluteCapacity=1.0, usedResources=<memory:7168, vCores:6>, usedCapacity=0.875, absoluteUsedCapacity=0.875, numApps=1, numContainers=6
2018-04-01 19:58:22,809 INFO org.apache.hadoop.yarn.server.resourcemanager.scheduler.capacity.CapacityScheduler: Application attempt appattempt_1522627038528_0001_000001 released container container_1522627038528_0001_01_000010 on node: host: bd18951cf78e:36999 #containers=6 available=<memory:1024, vCores:2> used=<memory:7168, vCores:6> with event: FINISHED
2018-04-01 19:58:22,810 INFO org.apache.hadoop.yarn.server.resourcemanager.rmcontainer.RMContainerImpl: container_1522627038528_0001_01_000014 Container Transitioned from NEW to ALLOCATED
2018-04-01 19:58:22,810 INFO org.apache.hadoop.yarn.server.resourcemanager.RMAuditLogger: USER=root	OPERATION=AM Allocated Container	TARGET=SchedulerApp	RESULT=SUCCESS	APPID=application_1522627038528_0001	CONTAINERID=container_1522627038528_0001_01_000014
2018-04-01 19:58:22,811 INFO org.apache.hadoop.yarn.server.resourcemanager.scheduler.SchedulerNode: Assigned container container_1522627038528_0001_01_000014 of capacity <memory:1024, vCores:1> on host bd18951cf78e:36999, which has 7 containers, <memory:8192, vCores:7> used and <memory:0, vCores:1> available after allocation
2018-04-01 19:58:22,811 INFO org.apache.hadoop.yarn.server.resourcemanager.scheduler.capacity.LeafQueue: assignedContainer application attempt=appattempt_1522627038528_0001_000001 container=Container: [ContainerId: container_1522627038528_0001_01_000014, NodeId: bd18951cf78e:36999, NodeHttpAddress: bd18951cf78e:8042, Resource: <memory:1024, vCores:1>, Priority: 10, Token: null, ] queue=default: capacity=1.0, absoluteCapacity=1.0, usedResources=<memory:7168, vCores:6>, usedCapacity=0.875, absoluteUsedCapacity=0.875, numApps=1, numContainers=6 clusterResource=<memory:8192, vCores:8>
2018-04-01 19:58:22,812 INFO org.apache.hadoop.yarn.server.resourcemanager.scheduler.capacity.ParentQueue: Re-sorting assigned queue: root.default stats: default: capacity=1.0, absoluteCapacity=1.0, usedResources=<memory:8192, vCores:7>, usedCapacity=1.0, absoluteUsedCapacity=1.0, numApps=1, numContainers=7
2018-04-01 19:58:22,812 INFO org.apache.hadoop.yarn.server.resourcemanager.scheduler.capacity.ParentQueue: assignedContainer queue=root usedCapacity=1.0 absoluteUsedCapacity=1.0 used=<memory:8192, vCores:7> cluster=<memory:8192, vCores:8>
2018-04-01 19:58:23,345 INFO org.apache.hadoop.yarn.server.resourcemanager.rmcontainer.RMContainerImpl: container_1522627038528_0001_01_000014 Container Transitioned from ALLOCATED to ACQUIRED
2018-04-01 19:58:23,869 INFO org.apache.hadoop.yarn.server.resourcemanager.rmcontainer.RMContainerImpl: container_1522627038528_0001_01_000014 Container Transitioned from ACQUIRED to RUNNING
2018-04-01 19:58:23,869 INFO org.apache.hadoop.yarn.server.resourcemanager.rmcontainer.RMContainerImpl: container_1522627038528_0001_01_000011 Container Transitioned from RUNNING to COMPLETED
2018-04-01 19:58:23,869 INFO org.apache.hadoop.yarn.server.resourcemanager.scheduler.common.fica.FiCaSchedulerApp: Completed container: container_1522627038528_0001_01_000011 in state: COMPLETED event:FINISHED
2018-04-01 19:58:23,869 INFO org.apache.hadoop.yarn.server.resourcemanager.RMAuditLogger: USER=root	OPERATION=AM Released Container	TARGET=SchedulerApp	RESULT=SUCCESS	APPID=application_1522627038528_0001	CONTAINERID=container_1522627038528_0001_01_000011
2018-04-01 19:58:23,869 INFO org.apache.hadoop.yarn.server.resourcemanager.scheduler.SchedulerNode: Released container container_1522627038528_0001_01_000011 of capacity <memory:1024, vCores:1> on host bd18951cf78e:36999, which currently has 6 containers, <memory:7168, vCores:6> used and <memory:1024, vCores:2> available, release resources=true
2018-04-01 19:58:23,869 INFO org.apache.hadoop.yarn.server.resourcemanager.scheduler.capacity.LeafQueue: default used=<memory:7168, vCores:6> numContainers=6 user=root user-resources=<memory:7168, vCores:6>
2018-04-01 19:58:23,870 INFO org.apache.hadoop.yarn.server.resourcemanager.scheduler.capacity.LeafQueue: completedContainer container=Container: [ContainerId: container_1522627038528_0001_01_000011, NodeId: bd18951cf78e:36999, NodeHttpAddress: bd18951cf78e:8042, Resource: <memory:1024, vCores:1>, Priority: 20, Token: Token { kind: ContainerToken, service: 172.20.0.2:36999 }, ] queue=default: capacity=1.0, absoluteCapacity=1.0, usedResources=<memory:7168, vCores:6>, usedCapacity=0.875, absoluteUsedCapacity=0.875, numApps=1, numContainers=6 cluster=<memory:8192, vCores:8>
2018-04-01 19:58:23,870 INFO org.apache.hadoop.yarn.server.resourcemanager.scheduler.capacity.ParentQueue: completedContainer queue=root usedCapacity=0.875 absoluteUsedCapacity=0.875 used=<memory:7168, vCores:6> cluster=<memory:8192, vCores:8>
2018-04-01 19:58:23,870 INFO org.apache.hadoop.yarn.server.resourcemanager.scheduler.capacity.ParentQueue: Re-sorting completed queue: root.default stats: default: capacity=1.0, absoluteCapacity=1.0, usedResources=<memory:7168, vCores:6>, usedCapacity=0.875, absoluteUsedCapacity=0.875, numApps=1, numContainers=6
2018-04-01 19:58:23,870 INFO org.apache.hadoop.yarn.server.resourcemanager.scheduler.capacity.CapacityScheduler: Application attempt appattempt_1522627038528_0001_000001 released container container_1522627038528_0001_01_000011 on node: host: bd18951cf78e:36999 #containers=6 available=<memory:1024, vCores:2> used=<memory:7168, vCores:6> with event: FINISHED
2018-04-01 19:58:23,870 INFO org.apache.hadoop.yarn.server.resourcemanager.rmcontainer.RMContainerImpl: container_1522627038528_0001_01_000012 Container Transitioned from RUNNING to COMPLETED
2018-04-01 19:58:23,870 INFO org.apache.hadoop.yarn.server.resourcemanager.scheduler.common.fica.FiCaSchedulerApp: Completed container: container_1522627038528_0001_01_000012 in state: COMPLETED event:FINISHED
2018-04-01 19:58:23,870 INFO org.apache.hadoop.yarn.server.resourcemanager.RMAuditLogger: USER=root	OPERATION=AM Released Container	TARGET=SchedulerApp	RESULT=SUCCESS	APPID=application_1522627038528_0001	CONTAINERID=container_1522627038528_0001_01_000012
2018-04-01 19:58:23,870 INFO org.apache.hadoop.yarn.server.resourcemanager.scheduler.SchedulerNode: Released container container_1522627038528_0001_01_000012 of capacity <memory:1024, vCores:1> on host bd18951cf78e:36999, which currently has 5 containers, <memory:6144, vCores:5> used and <memory:2048, vCores:3> available, release resources=true
2018-04-01 19:58:23,871 INFO org.apache.hadoop.yarn.server.resourcemanager.scheduler.capacity.LeafQueue: default used=<memory:6144, vCores:5> numContainers=5 user=root user-resources=<memory:6144, vCores:5>
2018-04-01 19:58:23,871 INFO org.apache.hadoop.yarn.server.resourcemanager.scheduler.capacity.LeafQueue: completedContainer container=Container: [ContainerId: container_1522627038528_0001_01_000012, NodeId: bd18951cf78e:36999, NodeHttpAddress: bd18951cf78e:8042, Resource: <memory:1024, vCores:1>, Priority: 20, Token: Token { kind: ContainerToken, service: 172.20.0.2:36999 }, ] queue=default: capacity=1.0, absoluteCapacity=1.0, usedResources=<memory:6144, vCores:5>, usedCapacity=0.75, absoluteUsedCapacity=0.75, numApps=1, numContainers=5 cluster=<memory:8192, vCores:8>
2018-04-01 19:58:23,871 INFO org.apache.hadoop.yarn.server.resourcemanager.scheduler.capacity.ParentQueue: completedContainer queue=root usedCapacity=0.75 absoluteUsedCapacity=0.75 used=<memory:6144, vCores:5> cluster=<memory:8192, vCores:8>
2018-04-01 19:58:23,871 INFO org.apache.hadoop.yarn.server.resourcemanager.scheduler.capacity.ParentQueue: Re-sorting completed queue: root.default stats: default: capacity=1.0, absoluteCapacity=1.0, usedResources=<memory:6144, vCores:5>, usedCapacity=0.75, absoluteUsedCapacity=0.75, numApps=1, numContainers=5
2018-04-01 19:58:23,871 INFO org.apache.hadoop.yarn.server.resourcemanager.scheduler.capacity.CapacityScheduler: Application attempt appattempt_1522627038528_0001_000001 released container container_1522627038528_0001_01_000012 on node: host: bd18951cf78e:36999 #containers=5 available=<memory:2048, vCores:3> used=<memory:6144, vCores:5> with event: FINISHED
2018-04-01 19:58:23,871 INFO org.apache.hadoop.yarn.server.resourcemanager.rmcontainer.RMContainerImpl: container_1522627038528_0001_01_000008 Container Transitioned from RUNNING to COMPLETED
2018-04-01 19:58:23,871 INFO org.apache.hadoop.yarn.server.resourcemanager.scheduler.common.fica.FiCaSchedulerApp: Completed container: container_1522627038528_0001_01_000008 in state: COMPLETED event:FINISHED
2018-04-01 19:58:23,871 INFO org.apache.hadoop.yarn.server.resourcemanager.RMAuditLogger: USER=root	OPERATION=AM Released Container	TARGET=SchedulerApp	RESULT=SUCCESS	APPID=application_1522627038528_0001	CONTAINERID=container_1522627038528_0001_01_000008
2018-04-01 19:58:23,872 INFO org.apache.hadoop.yarn.server.resourcemanager.scheduler.SchedulerNode: Released container container_1522627038528_0001_01_000008 of capacity <memory:1024, vCores:1> on host bd18951cf78e:36999, which currently has 4 containers, <memory:5120, vCores:4> used and <memory:3072, vCores:4> available, release resources=true
2018-04-01 19:58:23,872 INFO org.apache.hadoop.yarn.server.resourcemanager.scheduler.capacity.LeafQueue: default used=<memory:5120, vCores:4> numContainers=4 user=root user-resources=<memory:5120, vCores:4>
2018-04-01 19:58:23,872 INFO org.apache.hadoop.yarn.server.resourcemanager.scheduler.capacity.LeafQueue: completedContainer container=Container: [ContainerId: container_1522627038528_0001_01_000008, NodeId: bd18951cf78e:36999, NodeHttpAddress: bd18951cf78e:8042, Resource: <memory:1024, vCores:1>, Priority: 20, Token: Token { kind: ContainerToken, service: 172.20.0.2:36999 }, ] queue=default: capacity=1.0, absoluteCapacity=1.0, usedResources=<memory:5120, vCores:4>, usedCapacity=0.625, absoluteUsedCapacity=0.625, numApps=1, numContainers=4 cluster=<memory:8192, vCores:8>
2018-04-01 19:58:23,872 INFO org.apache.hadoop.yarn.server.resourcemanager.scheduler.capacity.ParentQueue: completedContainer queue=root usedCapacity=0.625 absoluteUsedCapacity=0.625 used=<memory:5120, vCores:4> cluster=<memory:8192, vCores:8>
2018-04-01 19:58:23,872 INFO org.apache.hadoop.yarn.server.resourcemanager.scheduler.capacity.ParentQueue: Re-sorting completed queue: root.default stats: default: capacity=1.0, absoluteCapacity=1.0, usedResources=<memory:5120, vCores:4>, usedCapacity=0.625, absoluteUsedCapacity=0.625, numApps=1, numContainers=4
2018-04-01 19:58:23,872 INFO org.apache.hadoop.yarn.server.resourcemanager.scheduler.capacity.CapacityScheduler: Application attempt appattempt_1522627038528_0001_000001 released container container_1522627038528_0001_01_000008 on node: host: bd18951cf78e:36999 #containers=4 available=<memory:3072, vCores:4> used=<memory:5120, vCores:4> with event: FINISHED
2018-04-01 19:58:23,873 INFO org.apache.hadoop.yarn.server.resourcemanager.rmcontainer.RMContainerImpl: container_1522627038528_0001_01_000009 Container Transitioned from RUNNING to COMPLETED
2018-04-01 19:58:23,873 INFO org.apache.hadoop.yarn.server.resourcemanager.scheduler.common.fica.FiCaSchedulerApp: Completed container: container_1522627038528_0001_01_000009 in state: COMPLETED event:FINISHED
2018-04-01 19:58:23,873 INFO org.apache.hadoop.yarn.server.resourcemanager.RMAuditLogger: USER=root	OPERATION=AM Released Container	TARGET=SchedulerApp	RESULT=SUCCESS	APPID=application_1522627038528_0001	CONTAINERID=container_1522627038528_0001_01_000009
2018-04-01 19:58:23,873 INFO org.apache.hadoop.yarn.server.resourcemanager.scheduler.SchedulerNode: Released container container_1522627038528_0001_01_000009 of capacity <memory:1024, vCores:1> on host bd18951cf78e:36999, which currently has 3 containers, <memory:4096, vCores:3> used and <memory:4096, vCores:5> available, release resources=true
2018-04-01 19:58:23,873 INFO org.apache.hadoop.yarn.server.resourcemanager.scheduler.capacity.LeafQueue: default used=<memory:4096, vCores:3> numContainers=3 user=root user-resources=<memory:4096, vCores:3>
2018-04-01 19:58:23,873 INFO org.apache.hadoop.yarn.server.resourcemanager.scheduler.capacity.LeafQueue: completedContainer container=Container: [ContainerId: container_1522627038528_0001_01_000009, NodeId: bd18951cf78e:36999, NodeHttpAddress: bd18951cf78e:8042, Resource: <memory:1024, vCores:1>, Priority: 20, Token: Token { kind: ContainerToken, service: 172.20.0.2:36999 }, ] queue=default: capacity=1.0, absoluteCapacity=1.0, usedResources=<memory:4096, vCores:3>, usedCapacity=0.5, absoluteUsedCapacity=0.5, numApps=1, numContainers=3 cluster=<memory:8192, vCores:8>
2018-04-01 19:58:23,873 INFO org.apache.hadoop.yarn.server.resourcemanager.scheduler.capacity.ParentQueue: completedContainer queue=root usedCapacity=0.5 absoluteUsedCapacity=0.5 used=<memory:4096, vCores:3> cluster=<memory:8192, vCores:8>
2018-04-01 19:58:23,873 INFO org.apache.hadoop.yarn.server.resourcemanager.scheduler.capacity.ParentQueue: Re-sorting completed queue: root.default stats: default: capacity=1.0, absoluteCapacity=1.0, usedResources=<memory:4096, vCores:3>, usedCapacity=0.5, absoluteUsedCapacity=0.5, numApps=1, numContainers=3
2018-04-01 19:58:23,874 INFO org.apache.hadoop.yarn.server.resourcemanager.scheduler.capacity.CapacityScheduler: Application attempt appattempt_1522627038528_0001_000001 released container container_1522627038528_0001_01_000009 on node: host: bd18951cf78e:36999 #containers=3 available=<memory:4096, vCores:5> used=<memory:4096, vCores:3> with event: FINISHED
2018-04-01 19:58:23,874 INFO org.apache.hadoop.yarn.server.resourcemanager.rmcontainer.RMContainerImpl: container_1522627038528_0001_01_000013 Container Transitioned from RUNNING to COMPLETED
2018-04-01 19:58:23,874 INFO org.apache.hadoop.yarn.server.resourcemanager.scheduler.common.fica.FiCaSchedulerApp: Completed container: container_1522627038528_0001_01_000013 in state: COMPLETED event:FINISHED
2018-04-01 19:58:23,874 INFO org.apache.hadoop.yarn.server.resourcemanager.RMAuditLogger: USER=root	OPERATION=AM Released Container	TARGET=SchedulerApp	RESULT=SUCCESS	APPID=application_1522627038528_0001	CONTAINERID=container_1522627038528_0001_01_000013
2018-04-01 19:58:23,874 INFO org.apache.hadoop.yarn.server.resourcemanager.scheduler.SchedulerNode: Released container container_1522627038528_0001_01_000013 of capacity <memory:1024, vCores:1> on host bd18951cf78e:36999, which currently has 2 containers, <memory:3072, vCores:2> used and <memory:5120, vCores:6> available, release resources=true
2018-04-01 19:58:23,874 INFO org.apache.hadoop.yarn.server.resourcemanager.scheduler.capacity.LeafQueue: default used=<memory:3072, vCores:2> numContainers=2 user=root user-resources=<memory:3072, vCores:2>
2018-04-01 19:58:23,874 INFO org.apache.hadoop.yarn.server.resourcemanager.scheduler.capacity.LeafQueue: completedContainer container=Container: [ContainerId: container_1522627038528_0001_01_000013, NodeId: bd18951cf78e:36999, NodeHttpAddress: bd18951cf78e:8042, Resource: <memory:1024, vCores:1>, Priority: 20, Token: Token { kind: ContainerToken, service: 172.20.0.2:36999 }, ] queue=default: capacity=1.0, absoluteCapacity=1.0, usedResources=<memory:3072, vCores:2>, usedCapacity=0.375, absoluteUsedCapacity=0.375, numApps=1, numContainers=2 cluster=<memory:8192, vCores:8>
2018-04-01 19:58:23,874 INFO org.apache.hadoop.yarn.server.resourcemanager.scheduler.capacity.ParentQueue: completedContainer queue=root usedCapacity=0.375 absoluteUsedCapacity=0.375 used=<memory:3072, vCores:2> cluster=<memory:8192, vCores:8>
2018-04-01 19:58:23,874 INFO org.apache.hadoop.yarn.server.resourcemanager.scheduler.capacity.ParentQueue: Re-sorting completed queue: root.default stats: default: capacity=1.0, absoluteCapacity=1.0, usedResources=<memory:3072, vCores:2>, usedCapacity=0.375, absoluteUsedCapacity=0.375, numApps=1, numContainers=2
2018-04-01 19:58:23,875 INFO org.apache.hadoop.yarn.server.resourcemanager.scheduler.capacity.CapacityScheduler: Application attempt appattempt_1522627038528_0001_000001 released container container_1522627038528_0001_01_000013 on node: host: bd18951cf78e:36999 #containers=2 available=<memory:5120, vCores:6> used=<memory:3072, vCores:2> with event: FINISHED
2018-04-01 19:58:23,875 INFO org.apache.hadoop.yarn.server.resourcemanager.rmcontainer.RMContainerImpl: container_1522627038528_0001_01_000015 Container Transitioned from NEW to ALLOCATED
2018-04-01 19:58:23,875 INFO org.apache.hadoop.yarn.server.resourcemanager.RMAuditLogger: USER=root	OPERATION=AM Allocated Container	TARGET=SchedulerApp	RESULT=SUCCESS	APPID=application_1522627038528_0001	CONTAINERID=container_1522627038528_0001_01_000015
2018-04-01 19:58:23,875 INFO org.apache.hadoop.yarn.server.resourcemanager.scheduler.SchedulerNode: Assigned container container_1522627038528_0001_01_000015 of capacity <memory:1024, vCores:1> on host bd18951cf78e:36999, which has 3 containers, <memory:4096, vCores:3> used and <memory:4096, vCores:5> available after allocation
2018-04-01 19:58:23,875 INFO org.apache.hadoop.yarn.server.resourcemanager.scheduler.capacity.LeafQueue: assignedContainer application attempt=appattempt_1522627038528_0001_000001 container=Container: [ContainerId: container_1522627038528_0001_01_000015, NodeId: bd18951cf78e:36999, NodeHttpAddress: bd18951cf78e:8042, Resource: <memory:1024, vCores:1>, Priority: 20, Token: null, ] queue=default: capacity=1.0, absoluteCapacity=1.0, usedResources=<memory:3072, vCores:2>, usedCapacity=0.375, absoluteUsedCapacity=0.375, numApps=1, numContainers=2 clusterResource=<memory:8192, vCores:8>
2018-04-01 19:58:23,875 INFO org.apache.hadoop.yarn.server.resourcemanager.scheduler.capacity.ParentQueue: Re-sorting assigned queue: root.default stats: default: capacity=1.0, absoluteCapacity=1.0, usedResources=<memory:4096, vCores:3>, usedCapacity=0.5, absoluteUsedCapacity=0.5, numApps=1, numContainers=3
2018-04-01 19:58:23,876 INFO org.apache.hadoop.yarn.server.resourcemanager.scheduler.capacity.ParentQueue: assignedContainer queue=root usedCapacity=0.5 absoluteUsedCapacity=0.5 used=<memory:4096, vCores:3> cluster=<memory:8192, vCores:8>
2018-04-01 19:58:23,877 INFO org.apache.hadoop.yarn.server.resourcemanager.rmcontainer.RMContainerImpl: container_1522627038528_0001_01_000016 Container Transitioned from NEW to ALLOCATED
2018-04-01 19:58:23,877 INFO org.apache.hadoop.yarn.server.resourcemanager.RMAuditLogger: USER=root	OPERATION=AM Allocated Container	TARGET=SchedulerApp	RESULT=SUCCESS	APPID=application_1522627038528_0001	CONTAINERID=container_1522627038528_0001_01_000016
2018-04-01 19:58:23,877 INFO org.apache.hadoop.yarn.server.resourcemanager.scheduler.SchedulerNode: Assigned container container_1522627038528_0001_01_000016 of capacity <memory:1024, vCores:1> on host bd18951cf78e:36999, which has 4 containers, <memory:5120, vCores:4> used and <memory:3072, vCores:4> available after allocation
2018-04-01 19:58:23,877 INFO org.apache.hadoop.yarn.server.resourcemanager.scheduler.capacity.LeafQueue: assignedContainer application attempt=appattempt_1522627038528_0001_000001 container=Container: [ContainerId: container_1522627038528_0001_01_000016, NodeId: bd18951cf78e:36999, NodeHttpAddress: bd18951cf78e:8042, Resource: <memory:1024, vCores:1>, Priority: 20, Token: null, ] queue=default: capacity=1.0, absoluteCapacity=1.0, usedResources=<memory:4096, vCores:3>, usedCapacity=0.5, absoluteUsedCapacity=0.5, numApps=1, numContainers=3 clusterResource=<memory:8192, vCores:8>
2018-04-01 19:58:23,877 INFO org.apache.hadoop.yarn.server.resourcemanager.scheduler.capacity.ParentQueue: Re-sorting assigned queue: root.default stats: default: capacity=1.0, absoluteCapacity=1.0, usedResources=<memory:5120, vCores:4>, usedCapacity=0.625, absoluteUsedCapacity=0.625, numApps=1, numContainers=4
2018-04-01 19:58:23,877 INFO org.apache.hadoop.yarn.server.resourcemanager.scheduler.capacity.ParentQueue: assignedContainer queue=root usedCapacity=0.625 absoluteUsedCapacity=0.625 used=<memory:5120, vCores:4> cluster=<memory:8192, vCores:8>
2018-04-01 19:58:23,878 INFO org.apache.hadoop.yarn.server.resourcemanager.rmcontainer.RMContainerImpl: container_1522627038528_0001_01_000017 Container Transitioned from NEW to ALLOCATED
2018-04-01 19:58:23,878 INFO org.apache.hadoop.yarn.server.resourcemanager.RMAuditLogger: USER=root	OPERATION=AM Allocated Container	TARGET=SchedulerApp	RESULT=SUCCESS	APPID=application_1522627038528_0001	CONTAINERID=container_1522627038528_0001_01_000017
2018-04-01 19:58:23,878 INFO org.apache.hadoop.yarn.server.resourcemanager.scheduler.SchedulerNode: Assigned container container_1522627038528_0001_01_000017 of capacity <memory:1024, vCores:1> on host bd18951cf78e:36999, which has 5 containers, <memory:6144, vCores:5> used and <memory:2048, vCores:3> available after allocation
2018-04-01 19:58:23,878 INFO org.apache.hadoop.yarn.server.resourcemanager.scheduler.capacity.LeafQueue: assignedContainer application attempt=appattempt_1522627038528_0001_000001 container=Container: [ContainerId: container_1522627038528_0001_01_000017, NodeId: bd18951cf78e:36999, NodeHttpAddress: bd18951cf78e:8042, Resource: <memory:1024, vCores:1>, Priority: 20, Token: null, ] queue=default: capacity=1.0, absoluteCapacity=1.0, usedResources=<memory:5120, vCores:4>, usedCapacity=0.625, absoluteUsedCapacity=0.625, numApps=1, numContainers=4 clusterResource=<memory:8192, vCores:8>
2018-04-01 19:58:23,878 INFO org.apache.hadoop.yarn.server.resourcemanager.scheduler.capacity.ParentQueue: Re-sorting assigned queue: root.default stats: default: capacity=1.0, absoluteCapacity=1.0, usedResources=<memory:6144, vCores:5>, usedCapacity=0.75, absoluteUsedCapacity=0.75, numApps=1, numContainers=5
2018-04-01 19:58:23,878 INFO org.apache.hadoop.yarn.server.resourcemanager.scheduler.capacity.ParentQueue: assignedContainer queue=root usedCapacity=0.75 absoluteUsedCapacity=0.75 used=<memory:6144, vCores:5> cluster=<memory:8192, vCores:8>
2018-04-01 19:58:23,879 INFO org.apache.hadoop.yarn.server.resourcemanager.rmcontainer.RMContainerImpl: container_1522627038528_0001_01_000018 Container Transitioned from NEW to ALLOCATED
2018-04-01 19:58:23,879 INFO org.apache.hadoop.yarn.server.resourcemanager.RMAuditLogger: USER=root	OPERATION=AM Allocated Container	TARGET=SchedulerApp	RESULT=SUCCESS	APPID=application_1522627038528_0001	CONTAINERID=container_1522627038528_0001_01_000018
2018-04-01 19:58:23,879 INFO org.apache.hadoop.yarn.server.resourcemanager.scheduler.SchedulerNode: Assigned container container_1522627038528_0001_01_000018 of capacity <memory:1024, vCores:1> on host bd18951cf78e:36999, which has 6 containers, <memory:7168, vCores:6> used and <memory:1024, vCores:2> available after allocation
2018-04-01 19:58:23,879 INFO org.apache.hadoop.yarn.server.resourcemanager.scheduler.capacity.LeafQueue: assignedContainer application attempt=appattempt_1522627038528_0001_000001 container=Container: [ContainerId: container_1522627038528_0001_01_000018, NodeId: bd18951cf78e:36999, NodeHttpAddress: bd18951cf78e:8042, Resource: <memory:1024, vCores:1>, Priority: 20, Token: null, ] queue=default: capacity=1.0, absoluteCapacity=1.0, usedResources=<memory:6144, vCores:5>, usedCapacity=0.75, absoluteUsedCapacity=0.75, numApps=1, numContainers=5 clusterResource=<memory:8192, vCores:8>
2018-04-01 19:58:23,879 INFO org.apache.hadoop.yarn.server.resourcemanager.scheduler.capacity.ParentQueue: Re-sorting assigned queue: root.default stats: default: capacity=1.0, absoluteCapacity=1.0, usedResources=<memory:7168, vCores:6>, usedCapacity=0.875, absoluteUsedCapacity=0.875, numApps=1, numContainers=6
2018-04-01 19:58:23,879 INFO org.apache.hadoop.yarn.server.resourcemanager.scheduler.capacity.ParentQueue: assignedContainer queue=root usedCapacity=0.875 absoluteUsedCapacity=0.875 used=<memory:7168, vCores:6> cluster=<memory:8192, vCores:8>
2018-04-01 19:58:23,880 INFO org.apache.hadoop.yarn.server.resourcemanager.rmcontainer.RMContainerImpl: container_1522627038528_0001_01_000019 Container Transitioned from NEW to ALLOCATED
2018-04-01 19:58:23,880 INFO org.apache.hadoop.yarn.server.resourcemanager.RMAuditLogger: USER=root	OPERATION=AM Allocated Container	TARGET=SchedulerApp	RESULT=SUCCESS	APPID=application_1522627038528_0001	CONTAINERID=container_1522627038528_0001_01_000019
2018-04-01 19:58:23,880 INFO org.apache.hadoop.yarn.server.resourcemanager.scheduler.SchedulerNode: Assigned container container_1522627038528_0001_01_000019 of capacity <memory:1024, vCores:1> on host bd18951cf78e:36999, which has 7 containers, <memory:8192, vCores:7> used and <memory:0, vCores:1> available after allocation
2018-04-01 19:58:23,880 INFO org.apache.hadoop.yarn.server.resourcemanager.scheduler.capacity.LeafQueue: assignedContainer application attempt=appattempt_1522627038528_0001_000001 container=Container: [ContainerId: container_1522627038528_0001_01_000019, NodeId: bd18951cf78e:36999, NodeHttpAddress: bd18951cf78e:8042, Resource: <memory:1024, vCores:1>, Priority: 20, Token: null, ] queue=default: capacity=1.0, absoluteCapacity=1.0, usedResources=<memory:7168, vCores:6>, usedCapacity=0.875, absoluteUsedCapacity=0.875, numApps=1, numContainers=6 clusterResource=<memory:8192, vCores:8>
2018-04-01 19:58:23,880 INFO org.apache.hadoop.yarn.server.resourcemanager.scheduler.capacity.ParentQueue: Re-sorting assigned queue: root.default stats: default: capacity=1.0, absoluteCapacity=1.0, usedResources=<memory:8192, vCores:7>, usedCapacity=1.0, absoluteUsedCapacity=1.0, numApps=1, numContainers=7
2018-04-01 19:58:23,880 INFO org.apache.hadoop.yarn.server.resourcemanager.scheduler.capacity.ParentQueue: assignedContainer queue=root usedCapacity=1.0 absoluteUsedCapacity=1.0 used=<memory:8192, vCores:7> cluster=<memory:8192, vCores:8>
2018-04-01 19:58:24,349 INFO org.apache.hadoop.yarn.server.resourcemanager.scheduler.AppSchedulingInfo: checking for deactivate of application :application_1522627038528_0001
2018-04-01 19:58:24,352 INFO org.apache.hadoop.yarn.server.resourcemanager.rmcontainer.RMContainerImpl: container_1522627038528_0001_01_000015 Container Transitioned from ALLOCATED to ACQUIRED
2018-04-01 19:58:24,354 INFO org.apache.hadoop.yarn.server.resourcemanager.rmcontainer.RMContainerImpl: container_1522627038528_0001_01_000016 Container Transitioned from ALLOCATED to ACQUIRED
2018-04-01 19:58:24,355 INFO org.apache.hadoop.yarn.server.resourcemanager.rmcontainer.RMContainerImpl: container_1522627038528_0001_01_000017 Container Transitioned from ALLOCATED to ACQUIRED
2018-04-01 19:58:24,357 INFO org.apache.hadoop.yarn.server.resourcemanager.rmcontainer.RMContainerImpl: container_1522627038528_0001_01_000018 Container Transitioned from ALLOCATED to ACQUIRED
2018-04-01 19:58:24,359 INFO org.apache.hadoop.yarn.server.resourcemanager.rmcontainer.RMContainerImpl: container_1522627038528_0001_01_000019 Container Transitioned from ALLOCATED to ACQUIRED
2018-04-01 19:58:24,873 INFO org.apache.hadoop.yarn.server.resourcemanager.rmcontainer.RMContainerImpl: container_1522627038528_0001_01_000015 Container Transitioned from ACQUIRED to RUNNING
2018-04-01 19:58:24,873 INFO org.apache.hadoop.yarn.server.resourcemanager.rmcontainer.RMContainerImpl: container_1522627038528_0001_01_000016 Container Transitioned from ACQUIRED to RUNNING
2018-04-01 19:58:24,873 INFO org.apache.hadoop.yarn.server.resourcemanager.rmcontainer.RMContainerImpl: container_1522627038528_0001_01_000017 Container Transitioned from ACQUIRED to RUNNING
2018-04-01 19:58:24,873 INFO org.apache.hadoop.yarn.server.resourcemanager.rmcontainer.RMContainerImpl: container_1522627038528_0001_01_000018 Container Transitioned from ACQUIRED to RUNNING
2018-04-01 19:58:24,874 INFO org.apache.hadoop.yarn.server.resourcemanager.rmcontainer.RMContainerImpl: container_1522627038528_0001_01_000019 Container Transitioned from ACQUIRED to RUNNING
2018-04-01 19:58:29,082 INFO org.apache.hadoop.yarn.server.resourcemanager.rmcontainer.RMContainerImpl: container_1522627038528_0001_01_000015 Container Transitioned from RUNNING to COMPLETED
2018-04-01 19:58:29,082 INFO org.apache.hadoop.yarn.server.resourcemanager.scheduler.common.fica.FiCaSchedulerApp: Completed container: container_1522627038528_0001_01_000015 in state: COMPLETED event:FINISHED
2018-04-01 19:58:29,082 INFO org.apache.hadoop.yarn.server.resourcemanager.RMAuditLogger: USER=root	OPERATION=AM Released Container	TARGET=SchedulerApp	RESULT=SUCCESS	APPID=application_1522627038528_0001	CONTAINERID=container_1522627038528_0001_01_000015
2018-04-01 19:58:29,082 INFO org.apache.hadoop.yarn.server.resourcemanager.scheduler.SchedulerNode: Released container container_1522627038528_0001_01_000015 of capacity <memory:1024, vCores:1> on host bd18951cf78e:36999, which currently has 6 containers, <memory:7168, vCores:6> used and <memory:1024, vCores:2> available, release resources=true
2018-04-01 19:58:29,083 INFO org.apache.hadoop.yarn.server.resourcemanager.scheduler.capacity.LeafQueue: default used=<memory:7168, vCores:6> numContainers=6 user=root user-resources=<memory:7168, vCores:6>
2018-04-01 19:58:29,083 INFO org.apache.hadoop.yarn.server.resourcemanager.scheduler.capacity.LeafQueue: completedContainer container=Container: [ContainerId: container_1522627038528_0001_01_000015, NodeId: bd18951cf78e:36999, NodeHttpAddress: bd18951cf78e:8042, Resource: <memory:1024, vCores:1>, Priority: 20, Token: Token { kind: ContainerToken, service: 172.20.0.2:36999 }, ] queue=default: capacity=1.0, absoluteCapacity=1.0, usedResources=<memory:7168, vCores:6>, usedCapacity=0.875, absoluteUsedCapacity=0.875, numApps=1, numContainers=6 cluster=<memory:8192, vCores:8>
2018-04-01 19:58:29,083 INFO org.apache.hadoop.yarn.server.resourcemanager.scheduler.capacity.ParentQueue: completedContainer queue=root usedCapacity=0.875 absoluteUsedCapacity=0.875 used=<memory:7168, vCores:6> cluster=<memory:8192, vCores:8>
2018-04-01 19:58:29,083 INFO org.apache.hadoop.yarn.server.resourcemanager.scheduler.capacity.ParentQueue: Re-sorting completed queue: root.default stats: default: capacity=1.0, absoluteCapacity=1.0, usedResources=<memory:7168, vCores:6>, usedCapacity=0.875, absoluteUsedCapacity=0.875, numApps=1, numContainers=6
2018-04-01 19:58:29,083 INFO org.apache.hadoop.yarn.server.resourcemanager.scheduler.capacity.CapacityScheduler: Application attempt appattempt_1522627038528_0001_000001 released container container_1522627038528_0001_01_000015 on node: host: bd18951cf78e:36999 #containers=6 available=<memory:1024, vCores:2> used=<memory:7168, vCores:6> with event: FINISHED
2018-04-01 19:58:29,084 INFO org.apache.hadoop.yarn.server.resourcemanager.rmcontainer.RMContainerImpl: container_1522627038528_0001_01_000020 Container Transitioned from NEW to ALLOCATED
2018-04-01 19:58:29,084 INFO org.apache.hadoop.yarn.server.resourcemanager.RMAuditLogger: USER=root	OPERATION=AM Allocated Container	TARGET=SchedulerApp	RESULT=SUCCESS	APPID=application_1522627038528_0001	CONTAINERID=container_1522627038528_0001_01_000020
2018-04-01 19:58:29,084 INFO org.apache.hadoop.yarn.server.resourcemanager.scheduler.SchedulerNode: Assigned container container_1522627038528_0001_01_000020 of capacity <memory:1024, vCores:1> on host bd18951cf78e:36999, which has 7 containers, <memory:8192, vCores:7> used and <memory:0, vCores:1> available after allocation
2018-04-01 19:58:29,085 INFO org.apache.hadoop.yarn.server.resourcemanager.scheduler.capacity.LeafQueue: assignedContainer application attempt=appattempt_1522627038528_0001_000001 container=Container: [ContainerId: container_1522627038528_0001_01_000020, NodeId: bd18951cf78e:36999, NodeHttpAddress: bd18951cf78e:8042, Resource: <memory:1024, vCores:1>, Priority: 20, Token: null, ] queue=default: capacity=1.0, absoluteCapacity=1.0, usedResources=<memory:7168, vCores:6>, usedCapacity=0.875, absoluteUsedCapacity=0.875, numApps=1, numContainers=6 clusterResource=<memory:8192, vCores:8>
2018-04-01 19:58:29,085 INFO org.apache.hadoop.yarn.server.resourcemanager.scheduler.capacity.ParentQueue: Re-sorting assigned queue: root.default stats: default: capacity=1.0, absoluteCapacity=1.0, usedResources=<memory:8192, vCores:7>, usedCapacity=1.0, absoluteUsedCapacity=1.0, numApps=1, numContainers=7
2018-04-01 19:58:29,085 INFO org.apache.hadoop.yarn.server.resourcemanager.scheduler.capacity.ParentQueue: assignedContainer queue=root usedCapacity=1.0 absoluteUsedCapacity=1.0 used=<memory:8192, vCores:7> cluster=<memory:8192, vCores:8>
2018-04-01 19:58:29,323 INFO org.apache.hadoop.yarn.server.resourcemanager.rmcontainer.RMContainerImpl: container_1522627038528_0001_01_000019 Container Transitioned from RUNNING to COMPLETED
2018-04-01 19:58:29,323 INFO org.apache.hadoop.yarn.server.resourcemanager.scheduler.common.fica.FiCaSchedulerApp: Completed container: container_1522627038528_0001_01_000019 in state: COMPLETED event:FINISHED
2018-04-01 19:58:29,323 INFO org.apache.hadoop.yarn.server.resourcemanager.RMAuditLogger: USER=root	OPERATION=AM Released Container	TARGET=SchedulerApp	RESULT=SUCCESS	APPID=application_1522627038528_0001	CONTAINERID=container_1522627038528_0001_01_000019
2018-04-01 19:58:29,324 INFO org.apache.hadoop.yarn.server.resourcemanager.scheduler.SchedulerNode: Released container container_1522627038528_0001_01_000019 of capacity <memory:1024, vCores:1> on host bd18951cf78e:36999, which currently has 6 containers, <memory:7168, vCores:6> used and <memory:1024, vCores:2> available, release resources=true
2018-04-01 19:58:29,324 INFO org.apache.hadoop.yarn.server.resourcemanager.scheduler.capacity.LeafQueue: default used=<memory:7168, vCores:6> numContainers=6 user=root user-resources=<memory:7168, vCores:6>
2018-04-01 19:58:29,324 INFO org.apache.hadoop.yarn.server.resourcemanager.scheduler.capacity.LeafQueue: completedContainer container=Container: [ContainerId: container_1522627038528_0001_01_000019, NodeId: bd18951cf78e:36999, NodeHttpAddress: bd18951cf78e:8042, Resource: <memory:1024, vCores:1>, Priority: 20, Token: Token { kind: ContainerToken, service: 172.20.0.2:36999 }, ] queue=default: capacity=1.0, absoluteCapacity=1.0, usedResources=<memory:7168, vCores:6>, usedCapacity=0.875, absoluteUsedCapacity=0.875, numApps=1, numContainers=6 cluster=<memory:8192, vCores:8>
2018-04-01 19:58:29,324 INFO org.apache.hadoop.yarn.server.resourcemanager.scheduler.capacity.ParentQueue: completedContainer queue=root usedCapacity=0.875 absoluteUsedCapacity=0.875 used=<memory:7168, vCores:6> cluster=<memory:8192, vCores:8>
2018-04-01 19:58:29,325 INFO org.apache.hadoop.yarn.server.resourcemanager.scheduler.capacity.ParentQueue: Re-sorting completed queue: root.default stats: default: capacity=1.0, absoluteCapacity=1.0, usedResources=<memory:7168, vCores:6>, usedCapacity=0.875, absoluteUsedCapacity=0.875, numApps=1, numContainers=6
2018-04-01 19:58:29,325 INFO org.apache.hadoop.yarn.server.resourcemanager.scheduler.capacity.CapacityScheduler: Application attempt appattempt_1522627038528_0001_000001 released container container_1522627038528_0001_01_000019 on node: host: bd18951cf78e:36999 #containers=6 available=<memory:1024, vCores:2> used=<memory:7168, vCores:6> with event: FINISHED
2018-04-01 19:58:29,325 INFO org.apache.hadoop.yarn.server.resourcemanager.rmcontainer.RMContainerImpl: container_1522627038528_0001_01_000018 Container Transitioned from RUNNING to COMPLETED
2018-04-01 19:58:29,325 INFO org.apache.hadoop.yarn.server.resourcemanager.scheduler.common.fica.FiCaSchedulerApp: Completed container: container_1522627038528_0001_01_000018 in state: COMPLETED event:FINISHED
2018-04-01 19:58:29,325 INFO org.apache.hadoop.yarn.server.resourcemanager.RMAuditLogger: USER=root	OPERATION=AM Released Container	TARGET=SchedulerApp	RESULT=SUCCESS	APPID=application_1522627038528_0001	CONTAINERID=container_1522627038528_0001_01_000018
2018-04-01 19:58:29,325 INFO org.apache.hadoop.yarn.server.resourcemanager.scheduler.SchedulerNode: Released container container_1522627038528_0001_01_000018 of capacity <memory:1024, vCores:1> on host bd18951cf78e:36999, which currently has 5 containers, <memory:6144, vCores:5> used and <memory:2048, vCores:3> available, release resources=true
2018-04-01 19:58:29,326 INFO org.apache.hadoop.yarn.server.resourcemanager.scheduler.capacity.LeafQueue: default used=<memory:6144, vCores:5> numContainers=5 user=root user-resources=<memory:6144, vCores:5>
2018-04-01 19:58:29,326 INFO org.apache.hadoop.yarn.server.resourcemanager.scheduler.capacity.LeafQueue: completedContainer container=Container: [ContainerId: container_1522627038528_0001_01_000018, NodeId: bd18951cf78e:36999, NodeHttpAddress: bd18951cf78e:8042, Resource: <memory:1024, vCores:1>, Priority: 20, Token: Token { kind: ContainerToken, service: 172.20.0.2:36999 }, ] queue=default: capacity=1.0, absoluteCapacity=1.0, usedResources=<memory:6144, vCores:5>, usedCapacity=0.75, absoluteUsedCapacity=0.75, numApps=1, numContainers=5 cluster=<memory:8192, vCores:8>
2018-04-01 19:58:29,326 INFO org.apache.hadoop.yarn.server.resourcemanager.scheduler.capacity.ParentQueue: completedContainer queue=root usedCapacity=0.75 absoluteUsedCapacity=0.75 used=<memory:6144, vCores:5> cluster=<memory:8192, vCores:8>
2018-04-01 19:58:29,326 INFO org.apache.hadoop.yarn.server.resourcemanager.scheduler.capacity.ParentQueue: Re-sorting completed queue: root.default stats: default: capacity=1.0, absoluteCapacity=1.0, usedResources=<memory:6144, vCores:5>, usedCapacity=0.75, absoluteUsedCapacity=0.75, numApps=1, numContainers=5
2018-04-01 19:58:29,326 INFO org.apache.hadoop.yarn.server.resourcemanager.scheduler.capacity.CapacityScheduler: Application attempt appattempt_1522627038528_0001_000001 released container container_1522627038528_0001_01_000018 on node: host: bd18951cf78e:36999 #containers=5 available=<memory:2048, vCores:3> used=<memory:6144, vCores:5> with event: FINISHED
2018-04-01 19:58:29,327 INFO org.apache.hadoop.yarn.server.resourcemanager.rmcontainer.RMContainerImpl: container_1522627038528_0001_01_000021 Container Transitioned from NEW to ALLOCATED
2018-04-01 19:58:29,327 INFO org.apache.hadoop.yarn.server.resourcemanager.RMAuditLogger: USER=root	OPERATION=AM Allocated Container	TARGET=SchedulerApp	RESULT=SUCCESS	APPID=application_1522627038528_0001	CONTAINERID=container_1522627038528_0001_01_000021
2018-04-01 19:58:29,327 INFO org.apache.hadoop.yarn.server.resourcemanager.scheduler.SchedulerNode: Assigned container container_1522627038528_0001_01_000021 of capacity <memory:1024, vCores:1> on host bd18951cf78e:36999, which has 6 containers, <memory:7168, vCores:6> used and <memory:1024, vCores:2> available after allocation
2018-04-01 19:58:29,327 INFO org.apache.hadoop.yarn.server.resourcemanager.scheduler.capacity.LeafQueue: assignedContainer application attempt=appattempt_1522627038528_0001_000001 container=Container: [ContainerId: container_1522627038528_0001_01_000021, NodeId: bd18951cf78e:36999, NodeHttpAddress: bd18951cf78e:8042, Resource: <memory:1024, vCores:1>, Priority: 20, Token: null, ] queue=default: capacity=1.0, absoluteCapacity=1.0, usedResources=<memory:6144, vCores:5>, usedCapacity=0.75, absoluteUsedCapacity=0.75, numApps=1, numContainers=5 clusterResource=<memory:8192, vCores:8>
2018-04-01 19:58:29,328 INFO org.apache.hadoop.yarn.server.resourcemanager.scheduler.capacity.ParentQueue: Re-sorting assigned queue: root.default stats: default: capacity=1.0, absoluteCapacity=1.0, usedResources=<memory:7168, vCores:6>, usedCapacity=0.875, absoluteUsedCapacity=0.875, numApps=1, numContainers=6
2018-04-01 19:58:29,328 INFO org.apache.hadoop.yarn.server.resourcemanager.scheduler.capacity.ParentQueue: assignedContainer queue=root usedCapacity=0.875 absoluteUsedCapacity=0.875 used=<memory:7168, vCores:6> cluster=<memory:8192, vCores:8>
2018-04-01 19:58:29,328 INFO org.apache.hadoop.yarn.server.resourcemanager.rmcontainer.RMContainerImpl: container_1522627038528_0001_01_000022 Container Transitioned from NEW to ALLOCATED
2018-04-01 19:58:29,329 INFO org.apache.hadoop.yarn.server.resourcemanager.RMAuditLogger: USER=root	OPERATION=AM Allocated Container	TARGET=SchedulerApp	RESULT=SUCCESS	APPID=application_1522627038528_0001	CONTAINERID=container_1522627038528_0001_01_000022
2018-04-01 19:58:29,329 INFO org.apache.hadoop.yarn.server.resourcemanager.scheduler.SchedulerNode: Assigned container container_1522627038528_0001_01_000022 of capacity <memory:1024, vCores:1> on host bd18951cf78e:36999, which has 7 containers, <memory:8192, vCores:7> used and <memory:0, vCores:1> available after allocation
2018-04-01 19:58:29,329 INFO org.apache.hadoop.yarn.server.resourcemanager.scheduler.capacity.LeafQueue: assignedContainer application attempt=appattempt_1522627038528_0001_000001 container=Container: [ContainerId: container_1522627038528_0001_01_000022, NodeId: bd18951cf78e:36999, NodeHttpAddress: bd18951cf78e:8042, Resource: <memory:1024, vCores:1>, Priority: 20, Token: null, ] queue=default: capacity=1.0, absoluteCapacity=1.0, usedResources=<memory:7168, vCores:6>, usedCapacity=0.875, absoluteUsedCapacity=0.875, numApps=1, numContainers=6 clusterResource=<memory:8192, vCores:8>
2018-04-01 19:58:29,329 INFO org.apache.hadoop.yarn.server.resourcemanager.scheduler.capacity.ParentQueue: Re-sorting assigned queue: root.default stats: default: capacity=1.0, absoluteCapacity=1.0, usedResources=<memory:8192, vCores:7>, usedCapacity=1.0, absoluteUsedCapacity=1.0, numApps=1, numContainers=7
2018-04-01 19:58:29,329 INFO org.apache.hadoop.yarn.server.resourcemanager.scheduler.capacity.ParentQueue: assignedContainer queue=root usedCapacity=1.0 absoluteUsedCapacity=1.0 used=<memory:8192, vCores:7> cluster=<memory:8192, vCores:8>
2018-04-01 19:58:29,382 INFO org.apache.hadoop.yarn.server.resourcemanager.rmcontainer.RMContainerImpl: container_1522627038528_0001_01_000020 Container Transitioned from ALLOCATED to ACQUIRED
2018-04-01 19:58:29,383 INFO org.apache.hadoop.yarn.server.resourcemanager.rmcontainer.RMContainerImpl: container_1522627038528_0001_01_000021 Container Transitioned from ALLOCATED to ACQUIRED
2018-04-01 19:58:29,384 INFO org.apache.hadoop.yarn.server.resourcemanager.rmcontainer.RMContainerImpl: container_1522627038528_0001_01_000022 Container Transitioned from ALLOCATED to ACQUIRED
2018-04-01 19:58:30,349 INFO org.apache.hadoop.yarn.server.resourcemanager.rmcontainer.RMContainerImpl: container_1522627038528_0001_01_000020 Container Transitioned from ACQUIRED to RUNNING
2018-04-01 19:58:30,350 INFO org.apache.hadoop.yarn.server.resourcemanager.rmcontainer.RMContainerImpl: container_1522627038528_0001_01_000021 Container Transitioned from ACQUIRED to RUNNING
2018-04-01 19:58:30,350 INFO org.apache.hadoop.yarn.server.resourcemanager.rmcontainer.RMContainerImpl: container_1522627038528_0001_01_000022 Container Transitioned from ACQUIRED to RUNNING
2018-04-01 19:58:30,351 INFO org.apache.hadoop.yarn.server.resourcemanager.rmcontainer.RMContainerImpl: container_1522627038528_0001_01_000017 Container Transitioned from RUNNING to COMPLETED
2018-04-01 19:58:30,351 INFO org.apache.hadoop.yarn.server.resourcemanager.scheduler.common.fica.FiCaSchedulerApp: Completed container: container_1522627038528_0001_01_000017 in state: COMPLETED event:FINISHED
2018-04-01 19:58:30,351 INFO org.apache.hadoop.yarn.server.resourcemanager.RMAuditLogger: USER=root	OPERATION=AM Released Container	TARGET=SchedulerApp	RESULT=SUCCESS	APPID=application_1522627038528_0001	CONTAINERID=container_1522627038528_0001_01_000017
2018-04-01 19:58:30,351 INFO org.apache.hadoop.yarn.server.resourcemanager.scheduler.SchedulerNode: Released container container_1522627038528_0001_01_000017 of capacity <memory:1024, vCores:1> on host bd18951cf78e:36999, which currently has 6 containers, <memory:7168, vCores:6> used and <memory:1024, vCores:2> available, release resources=true
2018-04-01 19:58:30,351 INFO org.apache.hadoop.yarn.server.resourcemanager.scheduler.capacity.LeafQueue: default used=<memory:7168, vCores:6> numContainers=6 user=root user-resources=<memory:7168, vCores:6>
2018-04-01 19:58:30,352 INFO org.apache.hadoop.yarn.server.resourcemanager.scheduler.capacity.LeafQueue: completedContainer container=Container: [ContainerId: container_1522627038528_0001_01_000017, NodeId: bd18951cf78e:36999, NodeHttpAddress: bd18951cf78e:8042, Resource: <memory:1024, vCores:1>, Priority: 20, Token: Token { kind: ContainerToken, service: 172.20.0.2:36999 }, ] queue=default: capacity=1.0, absoluteCapacity=1.0, usedResources=<memory:7168, vCores:6>, usedCapacity=0.875, absoluteUsedCapacity=0.875, numApps=1, numContainers=6 cluster=<memory:8192, vCores:8>
2018-04-01 19:58:30,352 INFO org.apache.hadoop.yarn.server.resourcemanager.scheduler.capacity.ParentQueue: completedContainer queue=root usedCapacity=0.875 absoluteUsedCapacity=0.875 used=<memory:7168, vCores:6> cluster=<memory:8192, vCores:8>
2018-04-01 19:58:30,352 INFO org.apache.hadoop.yarn.server.resourcemanager.scheduler.capacity.ParentQueue: Re-sorting completed queue: root.default stats: default: capacity=1.0, absoluteCapacity=1.0, usedResources=<memory:7168, vCores:6>, usedCapacity=0.875, absoluteUsedCapacity=0.875, numApps=1, numContainers=6
2018-04-01 19:58:30,352 INFO org.apache.hadoop.yarn.server.resourcemanager.scheduler.capacity.CapacityScheduler: Application attempt appattempt_1522627038528_0001_000001 released container container_1522627038528_0001_01_000017 on node: host: bd18951cf78e:36999 #containers=6 available=<memory:1024, vCores:2> used=<memory:7168, vCores:6> with event: FINISHED
2018-04-01 19:58:30,354 INFO org.apache.hadoop.yarn.server.resourcemanager.rmcontainer.RMContainerImpl: container_1522627038528_0001_01_000016 Container Transitioned from RUNNING to COMPLETED
2018-04-01 19:58:30,354 INFO org.apache.hadoop.yarn.server.resourcemanager.scheduler.common.fica.FiCaSchedulerApp: Completed container: container_1522627038528_0001_01_000016 in state: COMPLETED event:FINISHED
2018-04-01 19:58:30,354 INFO org.apache.hadoop.yarn.server.resourcemanager.RMAuditLogger: USER=root	OPERATION=AM Released Container	TARGET=SchedulerApp	RESULT=SUCCESS	APPID=application_1522627038528_0001	CONTAINERID=container_1522627038528_0001_01_000016
2018-04-01 19:58:30,354 INFO org.apache.hadoop.yarn.server.resourcemanager.scheduler.SchedulerNode: Released container container_1522627038528_0001_01_000016 of capacity <memory:1024, vCores:1> on host bd18951cf78e:36999, which currently has 5 containers, <memory:6144, vCores:5> used and <memory:2048, vCores:3> available, release resources=true
2018-04-01 19:58:30,354 INFO org.apache.hadoop.yarn.server.resourcemanager.scheduler.capacity.LeafQueue: default used=<memory:6144, vCores:5> numContainers=5 user=root user-resources=<memory:6144, vCores:5>
2018-04-01 19:58:30,355 INFO org.apache.hadoop.yarn.server.resourcemanager.scheduler.capacity.LeafQueue: completedContainer container=Container: [ContainerId: container_1522627038528_0001_01_000016, NodeId: bd18951cf78e:36999, NodeHttpAddress: bd18951cf78e:8042, Resource: <memory:1024, vCores:1>, Priority: 20, Token: Token { kind: ContainerToken, service: 172.20.0.2:36999 }, ] queue=default: capacity=1.0, absoluteCapacity=1.0, usedResources=<memory:6144, vCores:5>, usedCapacity=0.75, absoluteUsedCapacity=0.75, numApps=1, numContainers=5 cluster=<memory:8192, vCores:8>
2018-04-01 19:58:30,355 INFO org.apache.hadoop.yarn.server.resourcemanager.scheduler.capacity.ParentQueue: completedContainer queue=root usedCapacity=0.75 absoluteUsedCapacity=0.75 used=<memory:6144, vCores:5> cluster=<memory:8192, vCores:8>
2018-04-01 19:58:30,355 INFO org.apache.hadoop.yarn.server.resourcemanager.scheduler.capacity.ParentQueue: Re-sorting completed queue: root.default stats: default: capacity=1.0, absoluteCapacity=1.0, usedResources=<memory:6144, vCores:5>, usedCapacity=0.75, absoluteUsedCapacity=0.75, numApps=1, numContainers=5
2018-04-01 19:58:30,355 INFO org.apache.hadoop.yarn.server.resourcemanager.scheduler.capacity.CapacityScheduler: Application attempt appattempt_1522627038528_0001_000001 released container container_1522627038528_0001_01_000016 on node: host: bd18951cf78e:36999 #containers=5 available=<memory:2048, vCores:3> used=<memory:6144, vCores:5> with event: FINISHED
2018-04-01 19:58:30,356 INFO org.apache.hadoop.yarn.server.resourcemanager.rmcontainer.RMContainerImpl: container_1522627038528_0001_01_000023 Container Transitioned from NEW to ALLOCATED
2018-04-01 19:58:30,356 INFO org.apache.hadoop.yarn.server.resourcemanager.RMAuditLogger: USER=root	OPERATION=AM Allocated Container	TARGET=SchedulerApp	RESULT=SUCCESS	APPID=application_1522627038528_0001	CONTAINERID=container_1522627038528_0001_01_000023
2018-04-01 19:58:30,357 INFO org.apache.hadoop.yarn.server.resourcemanager.scheduler.SchedulerNode: Assigned container container_1522627038528_0001_01_000023 of capacity <memory:1024, vCores:1> on host bd18951cf78e:36999, which has 6 containers, <memory:7168, vCores:6> used and <memory:1024, vCores:2> available after allocation
2018-04-01 19:58:30,357 INFO org.apache.hadoop.yarn.server.resourcemanager.scheduler.capacity.LeafQueue: assignedContainer application attempt=appattempt_1522627038528_0001_000001 container=Container: [ContainerId: container_1522627038528_0001_01_000023, NodeId: bd18951cf78e:36999, NodeHttpAddress: bd18951cf78e:8042, Resource: <memory:1024, vCores:1>, Priority: 20, Token: null, ] queue=default: capacity=1.0, absoluteCapacity=1.0, usedResources=<memory:6144, vCores:5>, usedCapacity=0.75, absoluteUsedCapacity=0.75, numApps=1, numContainers=5 clusterResource=<memory:8192, vCores:8>
2018-04-01 19:58:30,357 INFO org.apache.hadoop.yarn.server.resourcemanager.scheduler.capacity.ParentQueue: Re-sorting assigned queue: root.default stats: default: capacity=1.0, absoluteCapacity=1.0, usedResources=<memory:7168, vCores:6>, usedCapacity=0.875, absoluteUsedCapacity=0.875, numApps=1, numContainers=6
2018-04-01 19:58:30,357 INFO org.apache.hadoop.yarn.server.resourcemanager.scheduler.capacity.ParentQueue: assignedContainer queue=root usedCapacity=0.875 absoluteUsedCapacity=0.875 used=<memory:7168, vCores:6> cluster=<memory:8192, vCores:8>
2018-04-01 19:58:30,358 INFO org.apache.hadoop.yarn.server.resourcemanager.rmcontainer.RMContainerImpl: container_1522627038528_0001_01_000024 Container Transitioned from NEW to ALLOCATED
2018-04-01 19:58:30,358 INFO org.apache.hadoop.yarn.server.resourcemanager.RMAuditLogger: USER=root	OPERATION=AM Allocated Container	TARGET=SchedulerApp	RESULT=SUCCESS	APPID=application_1522627038528_0001	CONTAINERID=container_1522627038528_0001_01_000024
2018-04-01 19:58:30,358 INFO org.apache.hadoop.yarn.server.resourcemanager.scheduler.SchedulerNode: Assigned container container_1522627038528_0001_01_000024 of capacity <memory:1024, vCores:1> on host bd18951cf78e:36999, which has 7 containers, <memory:8192, vCores:7> used and <memory:0, vCores:1> available after allocation
2018-04-01 19:58:30,359 INFO org.apache.hadoop.yarn.server.resourcemanager.scheduler.capacity.LeafQueue: assignedContainer application attempt=appattempt_1522627038528_0001_000001 container=Container: [ContainerId: container_1522627038528_0001_01_000024, NodeId: bd18951cf78e:36999, NodeHttpAddress: bd18951cf78e:8042, Resource: <memory:1024, vCores:1>, Priority: 20, Token: null, ] queue=default: capacity=1.0, absoluteCapacity=1.0, usedResources=<memory:7168, vCores:6>, usedCapacity=0.875, absoluteUsedCapacity=0.875, numApps=1, numContainers=6 clusterResource=<memory:8192, vCores:8>
2018-04-01 19:58:30,359 INFO org.apache.hadoop.yarn.server.resourcemanager.scheduler.capacity.ParentQueue: Re-sorting assigned queue: root.default stats: default: capacity=1.0, absoluteCapacity=1.0, usedResources=<memory:8192, vCores:7>, usedCapacity=1.0, absoluteUsedCapacity=1.0, numApps=1, numContainers=7
2018-04-01 19:58:30,360 INFO org.apache.hadoop.yarn.server.resourcemanager.scheduler.capacity.ParentQueue: assignedContainer queue=root usedCapacity=1.0 absoluteUsedCapacity=1.0 used=<memory:8192, vCores:7> cluster=<memory:8192, vCores:8>
2018-04-01 19:58:30,391 INFO org.apache.hadoop.yarn.server.resourcemanager.rmcontainer.RMContainerImpl: container_1522627038528_0001_01_000023 Container Transitioned from ALLOCATED to ACQUIRED
2018-04-01 19:58:30,393 INFO org.apache.hadoop.yarn.server.resourcemanager.rmcontainer.RMContainerImpl: container_1522627038528_0001_01_000024 Container Transitioned from ALLOCATED to ACQUIRED
2018-04-01 19:58:31,353 INFO org.apache.hadoop.yarn.server.resourcemanager.rmcontainer.RMContainerImpl: container_1522627038528_0001_01_000023 Container Transitioned from ACQUIRED to RUNNING
2018-04-01 19:58:31,353 INFO org.apache.hadoop.yarn.server.resourcemanager.rmcontainer.RMContainerImpl: container_1522627038528_0001_01_000024 Container Transitioned from ACQUIRED to RUNNING
2018-04-01 19:58:34,338 INFO org.apache.hadoop.yarn.server.resourcemanager.rmcontainer.RMContainerImpl: container_1522627038528_0001_01_000020 Container Transitioned from RUNNING to COMPLETED
2018-04-01 19:58:34,338 INFO org.apache.hadoop.yarn.server.resourcemanager.scheduler.common.fica.FiCaSchedulerApp: Completed container: container_1522627038528_0001_01_000020 in state: COMPLETED event:FINISHED
2018-04-01 19:58:34,338 INFO org.apache.hadoop.yarn.server.resourcemanager.RMAuditLogger: USER=root	OPERATION=AM Released Container	TARGET=SchedulerApp	RESULT=SUCCESS	APPID=application_1522627038528_0001	CONTAINERID=container_1522627038528_0001_01_000020
2018-04-01 19:58:34,338 INFO org.apache.hadoop.yarn.server.resourcemanager.scheduler.SchedulerNode: Released container container_1522627038528_0001_01_000020 of capacity <memory:1024, vCores:1> on host bd18951cf78e:36999, which currently has 6 containers, <memory:7168, vCores:6> used and <memory:1024, vCores:2> available, release resources=true
2018-04-01 19:58:34,338 INFO org.apache.hadoop.yarn.server.resourcemanager.scheduler.capacity.LeafQueue: default used=<memory:7168, vCores:6> numContainers=6 user=root user-resources=<memory:7168, vCores:6>
2018-04-01 19:58:34,339 INFO org.apache.hadoop.yarn.server.resourcemanager.scheduler.capacity.LeafQueue: completedContainer container=Container: [ContainerId: container_1522627038528_0001_01_000020, NodeId: bd18951cf78e:36999, NodeHttpAddress: bd18951cf78e:8042, Resource: <memory:1024, vCores:1>, Priority: 20, Token: Token { kind: ContainerToken, service: 172.20.0.2:36999 }, ] queue=default: capacity=1.0, absoluteCapacity=1.0, usedResources=<memory:7168, vCores:6>, usedCapacity=0.875, absoluteUsedCapacity=0.875, numApps=1, numContainers=6 cluster=<memory:8192, vCores:8>
2018-04-01 19:58:34,339 INFO org.apache.hadoop.yarn.server.resourcemanager.scheduler.capacity.ParentQueue: completedContainer queue=root usedCapacity=0.875 absoluteUsedCapacity=0.875 used=<memory:7168, vCores:6> cluster=<memory:8192, vCores:8>
2018-04-01 19:58:34,339 INFO org.apache.hadoop.yarn.server.resourcemanager.scheduler.capacity.ParentQueue: Re-sorting completed queue: root.default stats: default: capacity=1.0, absoluteCapacity=1.0, usedResources=<memory:7168, vCores:6>, usedCapacity=0.875, absoluteUsedCapacity=0.875, numApps=1, numContainers=6
2018-04-01 19:58:34,339 INFO org.apache.hadoop.yarn.server.resourcemanager.scheduler.capacity.CapacityScheduler: Application attempt appattempt_1522627038528_0001_000001 released container container_1522627038528_0001_01_000020 on node: host: bd18951cf78e:36999 #containers=6 available=<memory:1024, vCores:2> used=<memory:7168, vCores:6> with event: FINISHED
2018-04-01 19:58:34,339 INFO org.apache.hadoop.yarn.server.resourcemanager.rmcontainer.RMContainerImpl: container_1522627038528_0001_01_000021 Container Transitioned from RUNNING to COMPLETED
2018-04-01 19:58:34,339 INFO org.apache.hadoop.yarn.server.resourcemanager.scheduler.common.fica.FiCaSchedulerApp: Completed container: container_1522627038528_0001_01_000021 in state: COMPLETED event:FINISHED
2018-04-01 19:58:34,340 INFO org.apache.hadoop.yarn.server.resourcemanager.RMAuditLogger: USER=root	OPERATION=AM Released Container	TARGET=SchedulerApp	RESULT=SUCCESS	APPID=application_1522627038528_0001	CONTAINERID=container_1522627038528_0001_01_000021
2018-04-01 19:58:34,340 INFO org.apache.hadoop.yarn.server.resourcemanager.scheduler.SchedulerNode: Released container container_1522627038528_0001_01_000021 of capacity <memory:1024, vCores:1> on host bd18951cf78e:36999, which currently has 5 containers, <memory:6144, vCores:5> used and <memory:2048, vCores:3> available, release resources=true
2018-04-01 19:58:34,340 INFO org.apache.hadoop.yarn.server.resourcemanager.scheduler.capacity.LeafQueue: default used=<memory:6144, vCores:5> numContainers=5 user=root user-resources=<memory:6144, vCores:5>
2018-04-01 19:58:34,341 INFO org.apache.hadoop.yarn.server.resourcemanager.scheduler.capacity.LeafQueue: completedContainer container=Container: [ContainerId: container_1522627038528_0001_01_000021, NodeId: bd18951cf78e:36999, NodeHttpAddress: bd18951cf78e:8042, Resource: <memory:1024, vCores:1>, Priority: 20, Token: Token { kind: ContainerToken, service: 172.20.0.2:36999 }, ] queue=default: capacity=1.0, absoluteCapacity=1.0, usedResources=<memory:6144, vCores:5>, usedCapacity=0.75, absoluteUsedCapacity=0.75, numApps=1, numContainers=5 cluster=<memory:8192, vCores:8>
2018-04-01 19:58:34,342 INFO org.apache.hadoop.yarn.server.resourcemanager.scheduler.capacity.ParentQueue: completedContainer queue=root usedCapacity=0.75 absoluteUsedCapacity=0.75 used=<memory:6144, vCores:5> cluster=<memory:8192, vCores:8>
2018-04-01 19:58:34,342 INFO org.apache.hadoop.yarn.server.resourcemanager.scheduler.capacity.ParentQueue: Re-sorting completed queue: root.default stats: default: capacity=1.0, absoluteCapacity=1.0, usedResources=<memory:6144, vCores:5>, usedCapacity=0.75, absoluteUsedCapacity=0.75, numApps=1, numContainers=5
2018-04-01 19:58:34,342 INFO org.apache.hadoop.yarn.server.resourcemanager.scheduler.capacity.CapacityScheduler: Application attempt appattempt_1522627038528_0001_000001 released container container_1522627038528_0001_01_000021 on node: host: bd18951cf78e:36999 #containers=5 available=<memory:2048, vCores:3> used=<memory:6144, vCores:5> with event: FINISHED
2018-04-01 19:58:34,342 INFO org.apache.hadoop.yarn.server.resourcemanager.rmcontainer.RMContainerImpl: container_1522627038528_0001_01_000022 Container Transitioned from RUNNING to COMPLETED
2018-04-01 19:58:34,342 INFO org.apache.hadoop.yarn.server.resourcemanager.scheduler.common.fica.FiCaSchedulerApp: Completed container: container_1522627038528_0001_01_000022 in state: COMPLETED event:FINISHED
2018-04-01 19:58:34,342 INFO org.apache.hadoop.yarn.server.resourcemanager.RMAuditLogger: USER=root	OPERATION=AM Released Container	TARGET=SchedulerApp	RESULT=SUCCESS	APPID=application_1522627038528_0001	CONTAINERID=container_1522627038528_0001_01_000022
2018-04-01 19:58:34,342 INFO org.apache.hadoop.yarn.server.resourcemanager.scheduler.SchedulerNode: Released container container_1522627038528_0001_01_000022 of capacity <memory:1024, vCores:1> on host bd18951cf78e:36999, which currently has 4 containers, <memory:5120, vCores:4> used and <memory:3072, vCores:4> available, release resources=true
2018-04-01 19:58:34,343 INFO org.apache.hadoop.yarn.server.resourcemanager.scheduler.capacity.LeafQueue: default used=<memory:5120, vCores:4> numContainers=4 user=root user-resources=<memory:5120, vCores:4>
2018-04-01 19:58:34,343 INFO org.apache.hadoop.yarn.server.resourcemanager.scheduler.capacity.LeafQueue: completedContainer container=Container: [ContainerId: container_1522627038528_0001_01_000022, NodeId: bd18951cf78e:36999, NodeHttpAddress: bd18951cf78e:8042, Resource: <memory:1024, vCores:1>, Priority: 20, Token: Token { kind: ContainerToken, service: 172.20.0.2:36999 }, ] queue=default: capacity=1.0, absoluteCapacity=1.0, usedResources=<memory:5120, vCores:4>, usedCapacity=0.625, absoluteUsedCapacity=0.625, numApps=1, numContainers=4 cluster=<memory:8192, vCores:8>
2018-04-01 19:58:34,343 INFO org.apache.hadoop.yarn.server.resourcemanager.scheduler.capacity.ParentQueue: completedContainer queue=root usedCapacity=0.625 absoluteUsedCapacity=0.625 used=<memory:5120, vCores:4> cluster=<memory:8192, vCores:8>
2018-04-01 19:58:34,343 INFO org.apache.hadoop.yarn.server.resourcemanager.scheduler.capacity.ParentQueue: Re-sorting completed queue: root.default stats: default: capacity=1.0, absoluteCapacity=1.0, usedResources=<memory:5120, vCores:4>, usedCapacity=0.625, absoluteUsedCapacity=0.625, numApps=1, numContainers=4
2018-04-01 19:58:34,343 INFO org.apache.hadoop.yarn.server.resourcemanager.scheduler.capacity.CapacityScheduler: Application attempt appattempt_1522627038528_0001_000001 released container container_1522627038528_0001_01_000022 on node: host: bd18951cf78e:36999 #containers=4 available=<memory:3072, vCores:4> used=<memory:5120, vCores:4> with event: FINISHED
2018-04-01 19:58:34,344 INFO org.apache.hadoop.yarn.server.resourcemanager.rmcontainer.RMContainerImpl: container_1522627038528_0001_01_000025 Container Transitioned from NEW to ALLOCATED
2018-04-01 19:58:34,344 INFO org.apache.hadoop.yarn.server.resourcemanager.RMAuditLogger: USER=root	OPERATION=AM Allocated Container	TARGET=SchedulerApp	RESULT=SUCCESS	APPID=application_1522627038528_0001	CONTAINERID=container_1522627038528_0001_01_000025
2018-04-01 19:58:34,344 INFO org.apache.hadoop.yarn.server.resourcemanager.scheduler.SchedulerNode: Assigned container container_1522627038528_0001_01_000025 of capacity <memory:1024, vCores:1> on host bd18951cf78e:36999, which has 5 containers, <memory:6144, vCores:5> used and <memory:2048, vCores:3> available after allocation
2018-04-01 19:58:34,344 INFO org.apache.hadoop.yarn.server.resourcemanager.scheduler.capacity.LeafQueue: assignedContainer application attempt=appattempt_1522627038528_0001_000001 container=Container: [ContainerId: container_1522627038528_0001_01_000025, NodeId: bd18951cf78e:36999, NodeHttpAddress: bd18951cf78e:8042, Resource: <memory:1024, vCores:1>, Priority: 20, Token: null, ] queue=default: capacity=1.0, absoluteCapacity=1.0, usedResources=<memory:5120, vCores:4>, usedCapacity=0.625, absoluteUsedCapacity=0.625, numApps=1, numContainers=4 clusterResource=<memory:8192, vCores:8>
2018-04-01 19:58:34,344 INFO org.apache.hadoop.yarn.server.resourcemanager.scheduler.capacity.ParentQueue: Re-sorting assigned queue: root.default stats: default: capacity=1.0, absoluteCapacity=1.0, usedResources=<memory:6144, vCores:5>, usedCapacity=0.75, absoluteUsedCapacity=0.75, numApps=1, numContainers=5
2018-04-01 19:58:34,344 INFO org.apache.hadoop.yarn.server.resourcemanager.scheduler.capacity.ParentQueue: assignedContainer queue=root usedCapacity=0.75 absoluteUsedCapacity=0.75 used=<memory:6144, vCores:5> cluster=<memory:8192, vCores:8>
2018-04-01 19:58:34,345 INFO org.apache.hadoop.yarn.server.resourcemanager.rmcontainer.RMContainerImpl: container_1522627038528_0001_01_000026 Container Transitioned from NEW to ALLOCATED
2018-04-01 19:58:34,345 INFO org.apache.hadoop.yarn.server.resourcemanager.RMAuditLogger: USER=root	OPERATION=AM Allocated Container	TARGET=SchedulerApp	RESULT=SUCCESS	APPID=application_1522627038528_0001	CONTAINERID=container_1522627038528_0001_01_000026
2018-04-01 19:58:34,345 INFO org.apache.hadoop.yarn.server.resourcemanager.scheduler.SchedulerNode: Assigned container container_1522627038528_0001_01_000026 of capacity <memory:1024, vCores:1> on host bd18951cf78e:36999, which has 6 containers, <memory:7168, vCores:6> used and <memory:1024, vCores:2> available after allocation
2018-04-01 19:58:34,346 INFO org.apache.hadoop.yarn.server.resourcemanager.scheduler.capacity.LeafQueue: assignedContainer application attempt=appattempt_1522627038528_0001_000001 container=Container: [ContainerId: container_1522627038528_0001_01_000026, NodeId: bd18951cf78e:36999, NodeHttpAddress: bd18951cf78e:8042, Resource: <memory:1024, vCores:1>, Priority: 20, Token: null, ] queue=default: capacity=1.0, absoluteCapacity=1.0, usedResources=<memory:6144, vCores:5>, usedCapacity=0.75, absoluteUsedCapacity=0.75, numApps=1, numContainers=5 clusterResource=<memory:8192, vCores:8>
2018-04-01 19:58:34,346 INFO org.apache.hadoop.yarn.server.resourcemanager.scheduler.capacity.ParentQueue: Re-sorting assigned queue: root.default stats: default: capacity=1.0, absoluteCapacity=1.0, usedResources=<memory:7168, vCores:6>, usedCapacity=0.875, absoluteUsedCapacity=0.875, numApps=1, numContainers=6
2018-04-01 19:58:34,346 INFO org.apache.hadoop.yarn.server.resourcemanager.scheduler.capacity.ParentQueue: assignedContainer queue=root usedCapacity=0.875 absoluteUsedCapacity=0.875 used=<memory:7168, vCores:6> cluster=<memory:8192, vCores:8>
2018-04-01 19:58:34,347 INFO org.apache.hadoop.yarn.server.resourcemanager.rmcontainer.RMContainerImpl: container_1522627038528_0001_01_000027 Container Transitioned from NEW to ALLOCATED
2018-04-01 19:58:34,347 INFO org.apache.hadoop.yarn.server.resourcemanager.RMAuditLogger: USER=root	OPERATION=AM Allocated Container	TARGET=SchedulerApp	RESULT=SUCCESS	APPID=application_1522627038528_0001	CONTAINERID=container_1522627038528_0001_01_000027
2018-04-01 19:58:34,347 INFO org.apache.hadoop.yarn.server.resourcemanager.scheduler.SchedulerNode: Assigned container container_1522627038528_0001_01_000027 of capacity <memory:1024, vCores:1> on host bd18951cf78e:36999, which has 7 containers, <memory:8192, vCores:7> used and <memory:0, vCores:1> available after allocation
2018-04-01 19:58:34,347 INFO org.apache.hadoop.yarn.server.resourcemanager.scheduler.capacity.LeafQueue: assignedContainer application attempt=appattempt_1522627038528_0001_000001 container=Container: [ContainerId: container_1522627038528_0001_01_000027, NodeId: bd18951cf78e:36999, NodeHttpAddress: bd18951cf78e:8042, Resource: <memory:1024, vCores:1>, Priority: 20, Token: null, ] queue=default: capacity=1.0, absoluteCapacity=1.0, usedResources=<memory:7168, vCores:6>, usedCapacity=0.875, absoluteUsedCapacity=0.875, numApps=1, numContainers=6 clusterResource=<memory:8192, vCores:8>
2018-04-01 19:58:34,348 INFO org.apache.hadoop.yarn.server.resourcemanager.scheduler.capacity.ParentQueue: Re-sorting assigned queue: root.default stats: default: capacity=1.0, absoluteCapacity=1.0, usedResources=<memory:8192, vCores:7>, usedCapacity=1.0, absoluteUsedCapacity=1.0, numApps=1, numContainers=7
2018-04-01 19:58:34,348 INFO org.apache.hadoop.yarn.server.resourcemanager.scheduler.capacity.ParentQueue: assignedContainer queue=root usedCapacity=1.0 absoluteUsedCapacity=1.0 used=<memory:8192, vCores:7> cluster=<memory:8192, vCores:8>
2018-04-01 19:58:34,411 INFO org.apache.hadoop.yarn.server.resourcemanager.rmcontainer.RMContainerImpl: container_1522627038528_0001_01_000025 Container Transitioned from ALLOCATED to ACQUIRED
2018-04-01 19:58:34,413 INFO org.apache.hadoop.yarn.server.resourcemanager.rmcontainer.RMContainerImpl: container_1522627038528_0001_01_000026 Container Transitioned from ALLOCATED to ACQUIRED
2018-04-01 19:58:34,414 INFO org.apache.hadoop.yarn.server.resourcemanager.rmcontainer.RMContainerImpl: container_1522627038528_0001_01_000027 Container Transitioned from ALLOCATED to ACQUIRED
2018-04-01 19:58:35,341 INFO org.apache.hadoop.yarn.server.resourcemanager.rmcontainer.RMContainerImpl: container_1522627038528_0001_01_000025 Container Transitioned from ACQUIRED to RUNNING
2018-04-01 19:58:35,341 INFO org.apache.hadoop.yarn.server.resourcemanager.rmcontainer.RMContainerImpl: container_1522627038528_0001_01_000026 Container Transitioned from ACQUIRED to RUNNING
2018-04-01 19:58:35,342 INFO org.apache.hadoop.yarn.server.resourcemanager.rmcontainer.RMContainerImpl: container_1522627038528_0001_01_000027 Container Transitioned from ACQUIRED to RUNNING
2018-04-01 19:58:35,342 INFO org.apache.hadoop.yarn.server.resourcemanager.rmcontainer.RMContainerImpl: container_1522627038528_0001_01_000024 Container Transitioned from RUNNING to COMPLETED
2018-04-01 19:58:35,342 INFO org.apache.hadoop.yarn.server.resourcemanager.scheduler.common.fica.FiCaSchedulerApp: Completed container: container_1522627038528_0001_01_000024 in state: COMPLETED event:FINISHED
2018-04-01 19:58:35,342 INFO org.apache.hadoop.yarn.server.resourcemanager.RMAuditLogger: USER=root	OPERATION=AM Released Container	TARGET=SchedulerApp	RESULT=SUCCESS	APPID=application_1522627038528_0001	CONTAINERID=container_1522627038528_0001_01_000024
2018-04-01 19:58:35,342 INFO org.apache.hadoop.yarn.server.resourcemanager.scheduler.SchedulerNode: Released container container_1522627038528_0001_01_000024 of capacity <memory:1024, vCores:1> on host bd18951cf78e:36999, which currently has 6 containers, <memory:7168, vCores:6> used and <memory:1024, vCores:2> available, release resources=true
2018-04-01 19:58:35,342 INFO org.apache.hadoop.yarn.server.resourcemanager.scheduler.capacity.LeafQueue: default used=<memory:7168, vCores:6> numContainers=6 user=root user-resources=<memory:7168, vCores:6>
2018-04-01 19:58:35,342 INFO org.apache.hadoop.yarn.server.resourcemanager.scheduler.capacity.LeafQueue: completedContainer container=Container: [ContainerId: container_1522627038528_0001_01_000024, NodeId: bd18951cf78e:36999, NodeHttpAddress: bd18951cf78e:8042, Resource: <memory:1024, vCores:1>, Priority: 20, Token: Token { kind: ContainerToken, service: 172.20.0.2:36999 }, ] queue=default: capacity=1.0, absoluteCapacity=1.0, usedResources=<memory:7168, vCores:6>, usedCapacity=0.875, absoluteUsedCapacity=0.875, numApps=1, numContainers=6 cluster=<memory:8192, vCores:8>
2018-04-01 19:58:35,343 INFO org.apache.hadoop.yarn.server.resourcemanager.scheduler.capacity.ParentQueue: completedContainer queue=root usedCapacity=0.875 absoluteUsedCapacity=0.875 used=<memory:7168, vCores:6> cluster=<memory:8192, vCores:8>
2018-04-01 19:58:35,343 INFO org.apache.hadoop.yarn.server.resourcemanager.scheduler.capacity.ParentQueue: Re-sorting completed queue: root.default stats: default: capacity=1.0, absoluteCapacity=1.0, usedResources=<memory:7168, vCores:6>, usedCapacity=0.875, absoluteUsedCapacity=0.875, numApps=1, numContainers=6
2018-04-01 19:58:35,343 INFO org.apache.hadoop.yarn.server.resourcemanager.scheduler.capacity.CapacityScheduler: Application attempt appattempt_1522627038528_0001_000001 released container container_1522627038528_0001_01_000024 on node: host: bd18951cf78e:36999 #containers=6 available=<memory:1024, vCores:2> used=<memory:7168, vCores:6> with event: FINISHED
2018-04-01 19:58:35,343 INFO org.apache.hadoop.yarn.server.resourcemanager.rmcontainer.RMContainerImpl: container_1522627038528_0001_01_000023 Container Transitioned from RUNNING to COMPLETED
2018-04-01 19:58:35,343 INFO org.apache.hadoop.yarn.server.resourcemanager.scheduler.common.fica.FiCaSchedulerApp: Completed container: container_1522627038528_0001_01_000023 in state: COMPLETED event:FINISHED
2018-04-01 19:58:35,343 INFO org.apache.hadoop.yarn.server.resourcemanager.RMAuditLogger: USER=root	OPERATION=AM Released Container	TARGET=SchedulerApp	RESULT=SUCCESS	APPID=application_1522627038528_0001	CONTAINERID=container_1522627038528_0001_01_000023
2018-04-01 19:58:35,343 INFO org.apache.hadoop.yarn.server.resourcemanager.scheduler.SchedulerNode: Released container container_1522627038528_0001_01_000023 of capacity <memory:1024, vCores:1> on host bd18951cf78e:36999, which currently has 5 containers, <memory:6144, vCores:5> used and <memory:2048, vCores:3> available, release resources=true
2018-04-01 19:58:35,343 INFO org.apache.hadoop.yarn.server.resourcemanager.scheduler.capacity.LeafQueue: default used=<memory:6144, vCores:5> numContainers=5 user=root user-resources=<memory:6144, vCores:5>
2018-04-01 19:58:35,344 INFO org.apache.hadoop.yarn.server.resourcemanager.scheduler.capacity.LeafQueue: completedContainer container=Container: [ContainerId: container_1522627038528_0001_01_000023, NodeId: bd18951cf78e:36999, NodeHttpAddress: bd18951cf78e:8042, Resource: <memory:1024, vCores:1>, Priority: 20, Token: Token { kind: ContainerToken, service: 172.20.0.2:36999 }, ] queue=default: capacity=1.0, absoluteCapacity=1.0, usedResources=<memory:6144, vCores:5>, usedCapacity=0.75, absoluteUsedCapacity=0.75, numApps=1, numContainers=5 cluster=<memory:8192, vCores:8>
2018-04-01 19:58:35,344 INFO org.apache.hadoop.yarn.server.resourcemanager.scheduler.capacity.ParentQueue: completedContainer queue=root usedCapacity=0.75 absoluteUsedCapacity=0.75 used=<memory:6144, vCores:5> cluster=<memory:8192, vCores:8>
2018-04-01 19:58:35,344 INFO org.apache.hadoop.yarn.server.resourcemanager.scheduler.capacity.ParentQueue: Re-sorting completed queue: root.default stats: default: capacity=1.0, absoluteCapacity=1.0, usedResources=<memory:6144, vCores:5>, usedCapacity=0.75, absoluteUsedCapacity=0.75, numApps=1, numContainers=5
2018-04-01 19:58:35,344 INFO org.apache.hadoop.yarn.server.resourcemanager.scheduler.capacity.CapacityScheduler: Application attempt appattempt_1522627038528_0001_000001 released container container_1522627038528_0001_01_000023 on node: host: bd18951cf78e:36999 #containers=5 available=<memory:2048, vCores:3> used=<memory:6144, vCores:5> with event: FINISHED
2018-04-01 19:58:35,345 INFO org.apache.hadoop.yarn.server.resourcemanager.rmcontainer.RMContainerImpl: container_1522627038528_0001_01_000028 Container Transitioned from NEW to ALLOCATED
2018-04-01 19:58:35,345 INFO org.apache.hadoop.yarn.server.resourcemanager.RMAuditLogger: USER=root	OPERATION=AM Allocated Container	TARGET=SchedulerApp	RESULT=SUCCESS	APPID=application_1522627038528_0001	CONTAINERID=container_1522627038528_0001_01_000028
2018-04-01 19:58:35,345 INFO org.apache.hadoop.yarn.server.resourcemanager.scheduler.SchedulerNode: Assigned container container_1522627038528_0001_01_000028 of capacity <memory:1024, vCores:1> on host bd18951cf78e:36999, which has 6 containers, <memory:7168, vCores:6> used and <memory:1024, vCores:2> available after allocation
2018-04-01 19:58:35,345 INFO org.apache.hadoop.yarn.server.resourcemanager.scheduler.capacity.LeafQueue: assignedContainer application attempt=appattempt_1522627038528_0001_000001 container=Container: [ContainerId: container_1522627038528_0001_01_000028, NodeId: bd18951cf78e:36999, NodeHttpAddress: bd18951cf78e:8042, Resource: <memory:1024, vCores:1>, Priority: 20, Token: null, ] queue=default: capacity=1.0, absoluteCapacity=1.0, usedResources=<memory:6144, vCores:5>, usedCapacity=0.75, absoluteUsedCapacity=0.75, numApps=1, numContainers=5 clusterResource=<memory:8192, vCores:8>
2018-04-01 19:58:35,345 INFO org.apache.hadoop.yarn.server.resourcemanager.scheduler.capacity.ParentQueue: Re-sorting assigned queue: root.default stats: default: capacity=1.0, absoluteCapacity=1.0, usedResources=<memory:7168, vCores:6>, usedCapacity=0.875, absoluteUsedCapacity=0.875, numApps=1, numContainers=6
2018-04-01 19:58:35,346 INFO org.apache.hadoop.yarn.server.resourcemanager.scheduler.capacity.ParentQueue: assignedContainer queue=root usedCapacity=0.875 absoluteUsedCapacity=0.875 used=<memory:7168, vCores:6> cluster=<memory:8192, vCores:8>
2018-04-01 19:58:35,346 INFO org.apache.hadoop.yarn.server.resourcemanager.rmcontainer.RMContainerImpl: container_1522627038528_0001_01_000029 Container Transitioned from NEW to ALLOCATED
2018-04-01 19:58:35,346 INFO org.apache.hadoop.yarn.server.resourcemanager.RMAuditLogger: USER=root	OPERATION=AM Allocated Container	TARGET=SchedulerApp	RESULT=SUCCESS	APPID=application_1522627038528_0001	CONTAINERID=container_1522627038528_0001_01_000029
2018-04-01 19:58:35,346 INFO org.apache.hadoop.yarn.server.resourcemanager.scheduler.SchedulerNode: Assigned container container_1522627038528_0001_01_000029 of capacity <memory:1024, vCores:1> on host bd18951cf78e:36999, which has 7 containers, <memory:8192, vCores:7> used and <memory:0, vCores:1> available after allocation
2018-04-01 19:58:35,347 INFO org.apache.hadoop.yarn.server.resourcemanager.scheduler.capacity.LeafQueue: assignedContainer application attempt=appattempt_1522627038528_0001_000001 container=Container: [ContainerId: container_1522627038528_0001_01_000029, NodeId: bd18951cf78e:36999, NodeHttpAddress: bd18951cf78e:8042, Resource: <memory:1024, vCores:1>, Priority: 20, Token: null, ] queue=default: capacity=1.0, absoluteCapacity=1.0, usedResources=<memory:7168, vCores:6>, usedCapacity=0.875, absoluteUsedCapacity=0.875, numApps=1, numContainers=6 clusterResource=<memory:8192, vCores:8>
2018-04-01 19:58:35,347 INFO org.apache.hadoop.yarn.server.resourcemanager.scheduler.capacity.ParentQueue: Re-sorting assigned queue: root.default stats: default: capacity=1.0, absoluteCapacity=1.0, usedResources=<memory:8192, vCores:7>, usedCapacity=1.0, absoluteUsedCapacity=1.0, numApps=1, numContainers=7
2018-04-01 19:58:35,347 INFO org.apache.hadoop.yarn.server.resourcemanager.scheduler.capacity.ParentQueue: assignedContainer queue=root usedCapacity=1.0 absoluteUsedCapacity=1.0 used=<memory:8192, vCores:7> cluster=<memory:8192, vCores:8>
2018-04-01 19:58:35,423 INFO org.apache.hadoop.yarn.server.resourcemanager.rmcontainer.RMContainerImpl: container_1522627038528_0001_01_000028 Container Transitioned from ALLOCATED to ACQUIRED
2018-04-01 19:58:35,425 INFO org.apache.hadoop.yarn.server.resourcemanager.rmcontainer.RMContainerImpl: container_1522627038528_0001_01_000029 Container Transitioned from ALLOCATED to ACQUIRED
2018-04-01 19:58:36,345 INFO org.apache.hadoop.yarn.server.resourcemanager.rmcontainer.RMContainerImpl: container_1522627038528_0001_01_000028 Container Transitioned from ACQUIRED to RUNNING
2018-04-01 19:58:36,345 INFO org.apache.hadoop.yarn.server.resourcemanager.rmcontainer.RMContainerImpl: container_1522627038528_0001_01_000029 Container Transitioned from ACQUIRED to RUNNING
2018-04-01 19:58:38,302 INFO org.apache.hadoop.yarn.server.resourcemanager.rmcontainer.RMContainerImpl: container_1522627038528_0001_01_000025 Container Transitioned from RUNNING to COMPLETED
2018-04-01 19:58:38,302 INFO org.apache.hadoop.yarn.server.resourcemanager.scheduler.common.fica.FiCaSchedulerApp: Completed container: container_1522627038528_0001_01_000025 in state: COMPLETED event:FINISHED
2018-04-01 19:58:38,303 INFO org.apache.hadoop.yarn.server.resourcemanager.RMAuditLogger: USER=root	OPERATION=AM Released Container	TARGET=SchedulerApp	RESULT=SUCCESS	APPID=application_1522627038528_0001	CONTAINERID=container_1522627038528_0001_01_000025
2018-04-01 19:58:38,303 INFO org.apache.hadoop.yarn.server.resourcemanager.scheduler.SchedulerNode: Released container container_1522627038528_0001_01_000025 of capacity <memory:1024, vCores:1> on host bd18951cf78e:36999, which currently has 6 containers, <memory:7168, vCores:6> used and <memory:1024, vCores:2> available, release resources=true
2018-04-01 19:58:38,303 INFO org.apache.hadoop.yarn.server.resourcemanager.scheduler.capacity.LeafQueue: default used=<memory:7168, vCores:6> numContainers=6 user=root user-resources=<memory:7168, vCores:6>
2018-04-01 19:58:38,303 INFO org.apache.hadoop.yarn.server.resourcemanager.scheduler.capacity.LeafQueue: completedContainer container=Container: [ContainerId: container_1522627038528_0001_01_000025, NodeId: bd18951cf78e:36999, NodeHttpAddress: bd18951cf78e:8042, Resource: <memory:1024, vCores:1>, Priority: 20, Token: Token { kind: ContainerToken, service: 172.20.0.2:36999 }, ] queue=default: capacity=1.0, absoluteCapacity=1.0, usedResources=<memory:7168, vCores:6>, usedCapacity=0.875, absoluteUsedCapacity=0.875, numApps=1, numContainers=6 cluster=<memory:8192, vCores:8>
2018-04-01 19:58:38,304 INFO org.apache.hadoop.yarn.server.resourcemanager.scheduler.capacity.ParentQueue: completedContainer queue=root usedCapacity=0.875 absoluteUsedCapacity=0.875 used=<memory:7168, vCores:6> cluster=<memory:8192, vCores:8>
2018-04-01 19:58:38,304 INFO org.apache.hadoop.yarn.server.resourcemanager.scheduler.capacity.ParentQueue: Re-sorting completed queue: root.default stats: default: capacity=1.0, absoluteCapacity=1.0, usedResources=<memory:7168, vCores:6>, usedCapacity=0.875, absoluteUsedCapacity=0.875, numApps=1, numContainers=6
2018-04-01 19:58:38,304 INFO org.apache.hadoop.yarn.server.resourcemanager.scheduler.capacity.CapacityScheduler: Application attempt appattempt_1522627038528_0001_000001 released container container_1522627038528_0001_01_000025 on node: host: bd18951cf78e:36999 #containers=6 available=<memory:1024, vCores:2> used=<memory:7168, vCores:6> with event: FINISHED
2018-04-01 19:58:38,305 INFO org.apache.hadoop.yarn.server.resourcemanager.rmcontainer.RMContainerImpl: container_1522627038528_0001_01_000030 Container Transitioned from NEW to ALLOCATED
2018-04-01 19:58:38,305 INFO org.apache.hadoop.yarn.server.resourcemanager.RMAuditLogger: USER=root	OPERATION=AM Allocated Container	TARGET=SchedulerApp	RESULT=SUCCESS	APPID=application_1522627038528_0001	CONTAINERID=container_1522627038528_0001_01_000030
2018-04-01 19:58:38,306 INFO org.apache.hadoop.yarn.server.resourcemanager.scheduler.SchedulerNode: Assigned container container_1522627038528_0001_01_000030 of capacity <memory:1024, vCores:1> on host bd18951cf78e:36999, which has 7 containers, <memory:8192, vCores:7> used and <memory:0, vCores:1> available after allocation
2018-04-01 19:58:38,306 INFO org.apache.hadoop.yarn.server.resourcemanager.scheduler.capacity.LeafQueue: assignedContainer application attempt=appattempt_1522627038528_0001_000001 container=Container: [ContainerId: container_1522627038528_0001_01_000030, NodeId: bd18951cf78e:36999, NodeHttpAddress: bd18951cf78e:8042, Resource: <memory:1024, vCores:1>, Priority: 20, Token: null, ] queue=default: capacity=1.0, absoluteCapacity=1.0, usedResources=<memory:7168, vCores:6>, usedCapacity=0.875, absoluteUsedCapacity=0.875, numApps=1, numContainers=6 clusterResource=<memory:8192, vCores:8>
2018-04-01 19:58:38,306 INFO org.apache.hadoop.yarn.server.resourcemanager.scheduler.capacity.ParentQueue: Re-sorting assigned queue: root.default stats: default: capacity=1.0, absoluteCapacity=1.0, usedResources=<memory:8192, vCores:7>, usedCapacity=1.0, absoluteUsedCapacity=1.0, numApps=1, numContainers=7
2018-04-01 19:58:38,306 INFO org.apache.hadoop.yarn.server.resourcemanager.scheduler.capacity.ParentQueue: assignedContainer queue=root usedCapacity=1.0 absoluteUsedCapacity=1.0 used=<memory:8192, vCores:7> cluster=<memory:8192, vCores:8>
2018-04-01 19:58:38,441 INFO org.apache.hadoop.yarn.server.resourcemanager.rmcontainer.RMContainerImpl: container_1522627038528_0001_01_000030 Container Transitioned from ALLOCATED to ACQUIRED
2018-04-01 19:58:39,334 INFO org.apache.hadoop.yarn.server.resourcemanager.rmcontainer.RMContainerImpl: container_1522627038528_0001_01_000030 Container Transitioned from ACQUIRED to RUNNING
2018-04-01 19:58:39,334 INFO org.apache.hadoop.yarn.server.resourcemanager.rmcontainer.RMContainerImpl: container_1522627038528_0001_01_000026 Container Transitioned from RUNNING to COMPLETED
2018-04-01 19:58:39,334 INFO org.apache.hadoop.yarn.server.resourcemanager.scheduler.common.fica.FiCaSchedulerApp: Completed container: container_1522627038528_0001_01_000026 in state: COMPLETED event:FINISHED
2018-04-01 19:58:39,334 INFO org.apache.hadoop.yarn.server.resourcemanager.RMAuditLogger: USER=root	OPERATION=AM Released Container	TARGET=SchedulerApp	RESULT=SUCCESS	APPID=application_1522627038528_0001	CONTAINERID=container_1522627038528_0001_01_000026
2018-04-01 19:58:39,334 INFO org.apache.hadoop.yarn.server.resourcemanager.scheduler.SchedulerNode: Released container container_1522627038528_0001_01_000026 of capacity <memory:1024, vCores:1> on host bd18951cf78e:36999, which currently has 6 containers, <memory:7168, vCores:6> used and <memory:1024, vCores:2> available, release resources=true
2018-04-01 19:58:39,335 INFO org.apache.hadoop.yarn.server.resourcemanager.scheduler.capacity.LeafQueue: default used=<memory:7168, vCores:6> numContainers=6 user=root user-resources=<memory:7168, vCores:6>
2018-04-01 19:58:39,335 INFO org.apache.hadoop.yarn.server.resourcemanager.scheduler.capacity.LeafQueue: completedContainer container=Container: [ContainerId: container_1522627038528_0001_01_000026, NodeId: bd18951cf78e:36999, NodeHttpAddress: bd18951cf78e:8042, Resource: <memory:1024, vCores:1>, Priority: 20, Token: Token { kind: ContainerToken, service: 172.20.0.2:36999 }, ] queue=default: capacity=1.0, absoluteCapacity=1.0, usedResources=<memory:7168, vCores:6>, usedCapacity=0.875, absoluteUsedCapacity=0.875, numApps=1, numContainers=6 cluster=<memory:8192, vCores:8>
2018-04-01 19:58:39,335 INFO org.apache.hadoop.yarn.server.resourcemanager.scheduler.capacity.ParentQueue: completedContainer queue=root usedCapacity=0.875 absoluteUsedCapacity=0.875 used=<memory:7168, vCores:6> cluster=<memory:8192, vCores:8>
2018-04-01 19:58:39,335 INFO org.apache.hadoop.yarn.server.resourcemanager.scheduler.capacity.ParentQueue: Re-sorting completed queue: root.default stats: default: capacity=1.0, absoluteCapacity=1.0, usedResources=<memory:7168, vCores:6>, usedCapacity=0.875, absoluteUsedCapacity=0.875, numApps=1, numContainers=6
2018-04-01 19:58:39,335 INFO org.apache.hadoop.yarn.server.resourcemanager.scheduler.capacity.CapacityScheduler: Application attempt appattempt_1522627038528_0001_000001 released container container_1522627038528_0001_01_000026 on node: host: bd18951cf78e:36999 #containers=6 available=<memory:1024, vCores:2> used=<memory:7168, vCores:6> with event: FINISHED
2018-04-01 19:58:39,336 INFO org.apache.hadoop.yarn.server.resourcemanager.rmcontainer.RMContainerImpl: container_1522627038528_0001_01_000027 Container Transitioned from RUNNING to COMPLETED
2018-04-01 19:58:39,336 INFO org.apache.hadoop.yarn.server.resourcemanager.scheduler.common.fica.FiCaSchedulerApp: Completed container: container_1522627038528_0001_01_000027 in state: COMPLETED event:FINISHED
2018-04-01 19:58:39,336 INFO org.apache.hadoop.yarn.server.resourcemanager.RMAuditLogger: USER=root	OPERATION=AM Released Container	TARGET=SchedulerApp	RESULT=SUCCESS	APPID=application_1522627038528_0001	CONTAINERID=container_1522627038528_0001_01_000027
2018-04-01 19:58:39,336 INFO org.apache.hadoop.yarn.server.resourcemanager.scheduler.SchedulerNode: Released container container_1522627038528_0001_01_000027 of capacity <memory:1024, vCores:1> on host bd18951cf78e:36999, which currently has 5 containers, <memory:6144, vCores:5> used and <memory:2048, vCores:3> available, release resources=true
2018-04-01 19:58:39,336 INFO org.apache.hadoop.yarn.server.resourcemanager.scheduler.capacity.LeafQueue: default used=<memory:6144, vCores:5> numContainers=5 user=root user-resources=<memory:6144, vCores:5>
2018-04-01 19:58:39,336 INFO org.apache.hadoop.yarn.server.resourcemanager.scheduler.capacity.LeafQueue: completedContainer container=Container: [ContainerId: container_1522627038528_0001_01_000027, NodeId: bd18951cf78e:36999, NodeHttpAddress: bd18951cf78e:8042, Resource: <memory:1024, vCores:1>, Priority: 20, Token: Token { kind: ContainerToken, service: 172.20.0.2:36999 }, ] queue=default: capacity=1.0, absoluteCapacity=1.0, usedResources=<memory:6144, vCores:5>, usedCapacity=0.75, absoluteUsedCapacity=0.75, numApps=1, numContainers=5 cluster=<memory:8192, vCores:8>
2018-04-01 19:58:39,337 INFO org.apache.hadoop.yarn.server.resourcemanager.scheduler.capacity.ParentQueue: completedContainer queue=root usedCapacity=0.75 absoluteUsedCapacity=0.75 used=<memory:6144, vCores:5> cluster=<memory:8192, vCores:8>
2018-04-01 19:58:39,337 INFO org.apache.hadoop.yarn.server.resourcemanager.scheduler.capacity.ParentQueue: Re-sorting completed queue: root.default stats: default: capacity=1.0, absoluteCapacity=1.0, usedResources=<memory:6144, vCores:5>, usedCapacity=0.75, absoluteUsedCapacity=0.75, numApps=1, numContainers=5
2018-04-01 19:58:39,337 INFO org.apache.hadoop.yarn.server.resourcemanager.scheduler.capacity.CapacityScheduler: Application attempt appattempt_1522627038528_0001_000001 released container container_1522627038528_0001_01_000027 on node: host: bd18951cf78e:36999 #containers=5 available=<memory:2048, vCores:3> used=<memory:6144, vCores:5> with event: FINISHED
2018-04-01 19:58:39,338 INFO org.apache.hadoop.yarn.server.resourcemanager.rmcontainer.RMContainerImpl: container_1522627038528_0001_01_000031 Container Transitioned from NEW to ALLOCATED
2018-04-01 19:58:39,338 INFO org.apache.hadoop.yarn.server.resourcemanager.RMAuditLogger: USER=root	OPERATION=AM Allocated Container	TARGET=SchedulerApp	RESULT=SUCCESS	APPID=application_1522627038528_0001	CONTAINERID=container_1522627038528_0001_01_000031
2018-04-01 19:58:39,338 INFO org.apache.hadoop.yarn.server.resourcemanager.scheduler.SchedulerNode: Assigned container container_1522627038528_0001_01_000031 of capacity <memory:1024, vCores:1> on host bd18951cf78e:36999, which has 6 containers, <memory:7168, vCores:6> used and <memory:1024, vCores:2> available after allocation
2018-04-01 19:58:39,338 INFO org.apache.hadoop.yarn.server.resourcemanager.scheduler.capacity.LeafQueue: assignedContainer application attempt=appattempt_1522627038528_0001_000001 container=Container: [ContainerId: container_1522627038528_0001_01_000031, NodeId: bd18951cf78e:36999, NodeHttpAddress: bd18951cf78e:8042, Resource: <memory:1024, vCores:1>, Priority: 20, Token: null, ] queue=default: capacity=1.0, absoluteCapacity=1.0, usedResources=<memory:6144, vCores:5>, usedCapacity=0.75, absoluteUsedCapacity=0.75, numApps=1, numContainers=5 clusterResource=<memory:8192, vCores:8>
2018-04-01 19:58:39,338 INFO org.apache.hadoop.yarn.server.resourcemanager.scheduler.capacity.ParentQueue: Re-sorting assigned queue: root.default stats: default: capacity=1.0, absoluteCapacity=1.0, usedResources=<memory:7168, vCores:6>, usedCapacity=0.875, absoluteUsedCapacity=0.875, numApps=1, numContainers=6
2018-04-01 19:58:39,339 INFO org.apache.hadoop.yarn.server.resourcemanager.scheduler.capacity.ParentQueue: assignedContainer queue=root usedCapacity=0.875 absoluteUsedCapacity=0.875 used=<memory:7168, vCores:6> cluster=<memory:8192, vCores:8>
2018-04-01 19:58:39,339 INFO org.apache.hadoop.yarn.server.resourcemanager.rmcontainer.RMContainerImpl: container_1522627038528_0001_01_000032 Container Transitioned from NEW to ALLOCATED
2018-04-01 19:58:39,339 INFO org.apache.hadoop.yarn.server.resourcemanager.RMAuditLogger: USER=root	OPERATION=AM Allocated Container	TARGET=SchedulerApp	RESULT=SUCCESS	APPID=application_1522627038528_0001	CONTAINERID=container_1522627038528_0001_01_000032
2018-04-01 19:58:39,339 INFO org.apache.hadoop.yarn.server.resourcemanager.scheduler.SchedulerNode: Assigned container container_1522627038528_0001_01_000032 of capacity <memory:1024, vCores:1> on host bd18951cf78e:36999, which has 7 containers, <memory:8192, vCores:7> used and <memory:0, vCores:1> available after allocation
2018-04-01 19:58:39,340 INFO org.apache.hadoop.yarn.server.resourcemanager.scheduler.capacity.LeafQueue: assignedContainer application attempt=appattempt_1522627038528_0001_000001 container=Container: [ContainerId: container_1522627038528_0001_01_000032, NodeId: bd18951cf78e:36999, NodeHttpAddress: bd18951cf78e:8042, Resource: <memory:1024, vCores:1>, Priority: 20, Token: null, ] queue=default: capacity=1.0, absoluteCapacity=1.0, usedResources=<memory:7168, vCores:6>, usedCapacity=0.875, absoluteUsedCapacity=0.875, numApps=1, numContainers=6 clusterResource=<memory:8192, vCores:8>
2018-04-01 19:58:39,340 INFO org.apache.hadoop.yarn.server.resourcemanager.scheduler.capacity.ParentQueue: Re-sorting assigned queue: root.default stats: default: capacity=1.0, absoluteCapacity=1.0, usedResources=<memory:8192, vCores:7>, usedCapacity=1.0, absoluteUsedCapacity=1.0, numApps=1, numContainers=7
2018-04-01 19:58:39,340 INFO org.apache.hadoop.yarn.server.resourcemanager.scheduler.capacity.ParentQueue: assignedContainer queue=root usedCapacity=1.0 absoluteUsedCapacity=1.0 used=<memory:8192, vCores:7> cluster=<memory:8192, vCores:8>
2018-04-01 19:58:39,447 INFO org.apache.hadoop.yarn.server.resourcemanager.rmcontainer.RMContainerImpl: container_1522627038528_0001_01_000031 Container Transitioned from ALLOCATED to ACQUIRED
2018-04-01 19:58:39,454 INFO org.apache.hadoop.yarn.server.resourcemanager.rmcontainer.RMContainerImpl: container_1522627038528_0001_01_000032 Container Transitioned from ALLOCATED to ACQUIRED
2018-04-01 19:58:39,511 INFO org.apache.hadoop.yarn.server.resourcemanager.rmcontainer.RMContainerImpl: container_1522627038528_0001_01_000031 Container Transitioned from ACQUIRED to RUNNING
2018-04-01 19:58:39,511 INFO org.apache.hadoop.yarn.server.resourcemanager.rmcontainer.RMContainerImpl: container_1522627038528_0001_01_000032 Container Transitioned from ACQUIRED to RUNNING
2018-04-01 19:58:40,528 INFO org.apache.hadoop.yarn.server.resourcemanager.rmcontainer.RMContainerImpl: container_1522627038528_0001_01_000028 Container Transitioned from RUNNING to COMPLETED
2018-04-01 19:58:40,529 INFO org.apache.hadoop.yarn.server.resourcemanager.scheduler.common.fica.FiCaSchedulerApp: Completed container: container_1522627038528_0001_01_000028 in state: COMPLETED event:FINISHED
2018-04-01 19:58:40,529 INFO org.apache.hadoop.yarn.server.resourcemanager.RMAuditLogger: USER=root	OPERATION=AM Released Container	TARGET=SchedulerApp	RESULT=SUCCESS	APPID=application_1522627038528_0001	CONTAINERID=container_1522627038528_0001_01_000028
2018-04-01 19:58:40,529 INFO org.apache.hadoop.yarn.server.resourcemanager.scheduler.SchedulerNode: Released container container_1522627038528_0001_01_000028 of capacity <memory:1024, vCores:1> on host bd18951cf78e:36999, which currently has 6 containers, <memory:7168, vCores:6> used and <memory:1024, vCores:2> available, release resources=true
2018-04-01 19:58:40,529 INFO org.apache.hadoop.yarn.server.resourcemanager.scheduler.capacity.LeafQueue: default used=<memory:7168, vCores:6> numContainers=6 user=root user-resources=<memory:7168, vCores:6>
2018-04-01 19:58:40,530 INFO org.apache.hadoop.yarn.server.resourcemanager.scheduler.capacity.LeafQueue: completedContainer container=Container: [ContainerId: container_1522627038528_0001_01_000028, NodeId: bd18951cf78e:36999, NodeHttpAddress: bd18951cf78e:8042, Resource: <memory:1024, vCores:1>, Priority: 20, Token: Token { kind: ContainerToken, service: 172.20.0.2:36999 }, ] queue=default: capacity=1.0, absoluteCapacity=1.0, usedResources=<memory:7168, vCores:6>, usedCapacity=0.875, absoluteUsedCapacity=0.875, numApps=1, numContainers=6 cluster=<memory:8192, vCores:8>
2018-04-01 19:58:40,530 INFO org.apache.hadoop.yarn.server.resourcemanager.scheduler.capacity.ParentQueue: completedContainer queue=root usedCapacity=0.875 absoluteUsedCapacity=0.875 used=<memory:7168, vCores:6> cluster=<memory:8192, vCores:8>
2018-04-01 19:58:40,530 INFO org.apache.hadoop.yarn.server.resourcemanager.scheduler.capacity.ParentQueue: Re-sorting completed queue: root.default stats: default: capacity=1.0, absoluteCapacity=1.0, usedResources=<memory:7168, vCores:6>, usedCapacity=0.875, absoluteUsedCapacity=0.875, numApps=1, numContainers=6
2018-04-01 19:58:40,530 INFO org.apache.hadoop.yarn.server.resourcemanager.scheduler.capacity.CapacityScheduler: Application attempt appattempt_1522627038528_0001_000001 released container container_1522627038528_0001_01_000028 on node: host: bd18951cf78e:36999 #containers=6 available=<memory:1024, vCores:2> used=<memory:7168, vCores:6> with event: FINISHED
2018-04-01 19:58:40,530 INFO org.apache.hadoop.yarn.server.resourcemanager.rmcontainer.RMContainerImpl: container_1522627038528_0001_01_000029 Container Transitioned from RUNNING to COMPLETED
2018-04-01 19:58:40,530 INFO org.apache.hadoop.yarn.server.resourcemanager.scheduler.common.fica.FiCaSchedulerApp: Completed container: container_1522627038528_0001_01_000029 in state: COMPLETED event:FINISHED
2018-04-01 19:58:40,530 INFO org.apache.hadoop.yarn.server.resourcemanager.RMAuditLogger: USER=root	OPERATION=AM Released Container	TARGET=SchedulerApp	RESULT=SUCCESS	APPID=application_1522627038528_0001	CONTAINERID=container_1522627038528_0001_01_000029
2018-04-01 19:58:40,530 INFO org.apache.hadoop.yarn.server.resourcemanager.scheduler.SchedulerNode: Released container container_1522627038528_0001_01_000029 of capacity <memory:1024, vCores:1> on host bd18951cf78e:36999, which currently has 5 containers, <memory:6144, vCores:5> used and <memory:2048, vCores:3> available, release resources=true
2018-04-01 19:58:40,531 INFO org.apache.hadoop.yarn.server.resourcemanager.scheduler.capacity.LeafQueue: default used=<memory:6144, vCores:5> numContainers=5 user=root user-resources=<memory:6144, vCores:5>
2018-04-01 19:58:40,531 INFO org.apache.hadoop.yarn.server.resourcemanager.scheduler.capacity.LeafQueue: completedContainer container=Container: [ContainerId: container_1522627038528_0001_01_000029, NodeId: bd18951cf78e:36999, NodeHttpAddress: bd18951cf78e:8042, Resource: <memory:1024, vCores:1>, Priority: 20, Token: Token { kind: ContainerToken, service: 172.20.0.2:36999 }, ] queue=default: capacity=1.0, absoluteCapacity=1.0, usedResources=<memory:6144, vCores:5>, usedCapacity=0.75, absoluteUsedCapacity=0.75, numApps=1, numContainers=5 cluster=<memory:8192, vCores:8>
2018-04-01 19:58:40,531 INFO org.apache.hadoop.yarn.server.resourcemanager.scheduler.capacity.ParentQueue: completedContainer queue=root usedCapacity=0.75 absoluteUsedCapacity=0.75 used=<memory:6144, vCores:5> cluster=<memory:8192, vCores:8>
2018-04-01 19:58:40,531 INFO org.apache.hadoop.yarn.server.resourcemanager.scheduler.capacity.ParentQueue: Re-sorting completed queue: root.default stats: default: capacity=1.0, absoluteCapacity=1.0, usedResources=<memory:6144, vCores:5>, usedCapacity=0.75, absoluteUsedCapacity=0.75, numApps=1, numContainers=5
2018-04-01 19:58:40,531 INFO org.apache.hadoop.yarn.server.resourcemanager.scheduler.capacity.CapacityScheduler: Application attempt appattempt_1522627038528_0001_000001 released container container_1522627038528_0001_01_000029 on node: host: bd18951cf78e:36999 #containers=5 available=<memory:2048, vCores:3> used=<memory:6144, vCores:5> with event: FINISHED
2018-04-01 19:58:40,532 INFO org.apache.hadoop.yarn.server.resourcemanager.rmcontainer.RMContainerImpl: container_1522627038528_0001_01_000033 Container Transitioned from NEW to ALLOCATED
2018-04-01 19:58:40,532 INFO org.apache.hadoop.yarn.server.resourcemanager.RMAuditLogger: USER=root	OPERATION=AM Allocated Container	TARGET=SchedulerApp	RESULT=SUCCESS	APPID=application_1522627038528_0001	CONTAINERID=container_1522627038528_0001_01_000033
2018-04-01 19:58:40,532 INFO org.apache.hadoop.yarn.server.resourcemanager.scheduler.SchedulerNode: Assigned container container_1522627038528_0001_01_000033 of capacity <memory:1024, vCores:1> on host bd18951cf78e:36999, which has 6 containers, <memory:7168, vCores:6> used and <memory:1024, vCores:2> available after allocation
2018-04-01 19:58:40,533 INFO org.apache.hadoop.yarn.server.resourcemanager.scheduler.capacity.LeafQueue: assignedContainer application attempt=appattempt_1522627038528_0001_000001 container=Container: [ContainerId: container_1522627038528_0001_01_000033, NodeId: bd18951cf78e:36999, NodeHttpAddress: bd18951cf78e:8042, Resource: <memory:1024, vCores:1>, Priority: 20, Token: null, ] queue=default: capacity=1.0, absoluteCapacity=1.0, usedResources=<memory:6144, vCores:5>, usedCapacity=0.75, absoluteUsedCapacity=0.75, numApps=1, numContainers=5 clusterResource=<memory:8192, vCores:8>
2018-04-01 19:58:40,533 INFO org.apache.hadoop.yarn.server.resourcemanager.scheduler.capacity.ParentQueue: Re-sorting assigned queue: root.default stats: default: capacity=1.0, absoluteCapacity=1.0, usedResources=<memory:7168, vCores:6>, usedCapacity=0.875, absoluteUsedCapacity=0.875, numApps=1, numContainers=6
2018-04-01 19:58:40,533 INFO org.apache.hadoop.yarn.server.resourcemanager.scheduler.capacity.ParentQueue: assignedContainer queue=root usedCapacity=0.875 absoluteUsedCapacity=0.875 used=<memory:7168, vCores:6> cluster=<memory:8192, vCores:8>
2018-04-01 19:58:41,468 INFO org.apache.hadoop.yarn.server.resourcemanager.rmcontainer.RMContainerImpl: container_1522627038528_0001_01_000033 Container Transitioned from ALLOCATED to ACQUIRED
2018-04-01 19:58:41,532 INFO org.apache.hadoop.yarn.server.resourcemanager.rmcontainer.RMContainerImpl: container_1522627038528_0001_01_000033 Container Transitioned from ACQUIRED to RUNNING
2018-04-01 19:58:42,473 INFO org.apache.hadoop.yarn.server.resourcemanager.scheduler.AppSchedulingInfo: checking for deactivate of application :application_1522627038528_0001
2018-04-01 19:58:42,542 INFO org.apache.hadoop.yarn.server.resourcemanager.rmcontainer.RMContainerImpl: container_1522627038528_0001_01_000030 Container Transitioned from RUNNING to COMPLETED
2018-04-01 19:58:42,542 INFO org.apache.hadoop.yarn.server.resourcemanager.scheduler.common.fica.FiCaSchedulerApp: Completed container: container_1522627038528_0001_01_000030 in state: COMPLETED event:FINISHED
2018-04-01 19:58:42,542 INFO org.apache.hadoop.yarn.server.resourcemanager.RMAuditLogger: USER=root	OPERATION=AM Released Container	TARGET=SchedulerApp	RESULT=SUCCESS	APPID=application_1522627038528_0001	CONTAINERID=container_1522627038528_0001_01_000030
2018-04-01 19:58:42,542 INFO org.apache.hadoop.yarn.server.resourcemanager.scheduler.SchedulerNode: Released container container_1522627038528_0001_01_000030 of capacity <memory:1024, vCores:1> on host bd18951cf78e:36999, which currently has 5 containers, <memory:6144, vCores:5> used and <memory:2048, vCores:3> available, release resources=true
2018-04-01 19:58:42,543 INFO org.apache.hadoop.yarn.server.resourcemanager.scheduler.capacity.LeafQueue: default used=<memory:6144, vCores:5> numContainers=5 user=root user-resources=<memory:6144, vCores:5>
2018-04-01 19:58:42,547 INFO org.apache.hadoop.yarn.server.resourcemanager.scheduler.capacity.LeafQueue: completedContainer container=Container: [ContainerId: container_1522627038528_0001_01_000030, NodeId: bd18951cf78e:36999, NodeHttpAddress: bd18951cf78e:8042, Resource: <memory:1024, vCores:1>, Priority: 20, Token: Token { kind: ContainerToken, service: 172.20.0.2:36999 }, ] queue=default: capacity=1.0, absoluteCapacity=1.0, usedResources=<memory:6144, vCores:5>, usedCapacity=0.75, absoluteUsedCapacity=0.75, numApps=1, numContainers=5 cluster=<memory:8192, vCores:8>
2018-04-01 19:58:42,547 INFO org.apache.hadoop.yarn.server.resourcemanager.scheduler.capacity.ParentQueue: completedContainer queue=root usedCapacity=0.75 absoluteUsedCapacity=0.75 used=<memory:6144, vCores:5> cluster=<memory:8192, vCores:8>
2018-04-01 19:58:42,547 INFO org.apache.hadoop.yarn.server.resourcemanager.scheduler.capacity.ParentQueue: Re-sorting completed queue: root.default stats: default: capacity=1.0, absoluteCapacity=1.0, usedResources=<memory:6144, vCores:5>, usedCapacity=0.75, absoluteUsedCapacity=0.75, numApps=1, numContainers=5
2018-04-01 19:58:42,548 INFO org.apache.hadoop.yarn.server.resourcemanager.scheduler.capacity.CapacityScheduler: Application attempt appattempt_1522627038528_0001_000001 released container container_1522627038528_0001_01_000030 on node: host: bd18951cf78e:36999 #containers=5 available=<memory:2048, vCores:3> used=<memory:6144, vCores:5> with event: FINISHED
2018-04-01 19:58:42,570 INFO org.apache.hadoop.yarn.server.resourcemanager.rmcontainer.RMContainerImpl: container_1522627038528_0001_01_000031 Container Transitioned from RUNNING to COMPLETED
2018-04-01 19:58:42,570 INFO org.apache.hadoop.yarn.server.resourcemanager.scheduler.common.fica.FiCaSchedulerApp: Completed container: container_1522627038528_0001_01_000031 in state: COMPLETED event:FINISHED
2018-04-01 19:58:42,570 INFO org.apache.hadoop.yarn.server.resourcemanager.RMAuditLogger: USER=root	OPERATION=AM Released Container	TARGET=SchedulerApp	RESULT=SUCCESS	APPID=application_1522627038528_0001	CONTAINERID=container_1522627038528_0001_01_000031
2018-04-01 19:58:42,570 INFO org.apache.hadoop.yarn.server.resourcemanager.scheduler.SchedulerNode: Released container container_1522627038528_0001_01_000031 of capacity <memory:1024, vCores:1> on host bd18951cf78e:36999, which currently has 4 containers, <memory:5120, vCores:4> used and <memory:3072, vCores:4> available, release resources=true
2018-04-01 19:58:42,570 INFO org.apache.hadoop.yarn.server.resourcemanager.scheduler.capacity.LeafQueue: default used=<memory:5120, vCores:4> numContainers=4 user=root user-resources=<memory:5120, vCores:4>
2018-04-01 19:58:42,571 INFO org.apache.hadoop.yarn.server.resourcemanager.scheduler.capacity.LeafQueue: completedContainer container=Container: [ContainerId: container_1522627038528_0001_01_000031, NodeId: bd18951cf78e:36999, NodeHttpAddress: bd18951cf78e:8042, Resource: <memory:1024, vCores:1>, Priority: 20, Token: Token { kind: ContainerToken, service: 172.20.0.2:36999 }, ] queue=default: capacity=1.0, absoluteCapacity=1.0, usedResources=<memory:5120, vCores:4>, usedCapacity=0.625, absoluteUsedCapacity=0.625, numApps=1, numContainers=4 cluster=<memory:8192, vCores:8>
2018-04-01 19:58:42,571 INFO org.apache.hadoop.yarn.server.resourcemanager.scheduler.capacity.ParentQueue: completedContainer queue=root usedCapacity=0.625 absoluteUsedCapacity=0.625 used=<memory:5120, vCores:4> cluster=<memory:8192, vCores:8>
2018-04-01 19:58:42,571 INFO org.apache.hadoop.yarn.server.resourcemanager.scheduler.capacity.ParentQueue: Re-sorting completed queue: root.default stats: default: capacity=1.0, absoluteCapacity=1.0, usedResources=<memory:5120, vCores:4>, usedCapacity=0.625, absoluteUsedCapacity=0.625, numApps=1, numContainers=4
2018-04-01 19:58:42,571 INFO org.apache.hadoop.yarn.server.resourcemanager.scheduler.capacity.CapacityScheduler: Application attempt appattempt_1522627038528_0001_000001 released container container_1522627038528_0001_01_000031 on node: host: bd18951cf78e:36999 #containers=4 available=<memory:3072, vCores:4> used=<memory:5120, vCores:4> with event: FINISHED
2018-04-01 19:58:43,572 INFO org.apache.hadoop.yarn.server.resourcemanager.rmcontainer.RMContainerImpl: container_1522627038528_0001_01_000032 Container Transitioned from RUNNING to COMPLETED
2018-04-01 19:58:43,572 INFO org.apache.hadoop.yarn.server.resourcemanager.scheduler.common.fica.FiCaSchedulerApp: Completed container: container_1522627038528_0001_01_000032 in state: COMPLETED event:FINISHED
2018-04-01 19:58:43,572 INFO org.apache.hadoop.yarn.server.resourcemanager.RMAuditLogger: USER=root	OPERATION=AM Released Container	TARGET=SchedulerApp	RESULT=SUCCESS	APPID=application_1522627038528_0001	CONTAINERID=container_1522627038528_0001_01_000032
2018-04-01 19:58:43,572 INFO org.apache.hadoop.yarn.server.resourcemanager.scheduler.SchedulerNode: Released container container_1522627038528_0001_01_000032 of capacity <memory:1024, vCores:1> on host bd18951cf78e:36999, which currently has 3 containers, <memory:4096, vCores:3> used and <memory:4096, vCores:5> available, release resources=true
2018-04-01 19:58:43,572 INFO org.apache.hadoop.yarn.server.resourcemanager.scheduler.capacity.LeafQueue: default used=<memory:4096, vCores:3> numContainers=3 user=root user-resources=<memory:4096, vCores:3>
2018-04-01 19:58:43,572 INFO org.apache.hadoop.yarn.server.resourcemanager.scheduler.capacity.LeafQueue: completedContainer container=Container: [ContainerId: container_1522627038528_0001_01_000032, NodeId: bd18951cf78e:36999, NodeHttpAddress: bd18951cf78e:8042, Resource: <memory:1024, vCores:1>, Priority: 20, Token: Token { kind: ContainerToken, service: 172.20.0.2:36999 }, ] queue=default: capacity=1.0, absoluteCapacity=1.0, usedResources=<memory:4096, vCores:3>, usedCapacity=0.5, absoluteUsedCapacity=0.5, numApps=1, numContainers=3 cluster=<memory:8192, vCores:8>
2018-04-01 19:58:43,573 INFO org.apache.hadoop.yarn.server.resourcemanager.scheduler.capacity.ParentQueue: completedContainer queue=root usedCapacity=0.5 absoluteUsedCapacity=0.5 used=<memory:4096, vCores:3> cluster=<memory:8192, vCores:8>
2018-04-01 19:58:43,573 INFO org.apache.hadoop.yarn.server.resourcemanager.scheduler.capacity.ParentQueue: Re-sorting completed queue: root.default stats: default: capacity=1.0, absoluteCapacity=1.0, usedResources=<memory:4096, vCores:3>, usedCapacity=0.5, absoluteUsedCapacity=0.5, numApps=1, numContainers=3
2018-04-01 19:58:43,573 INFO org.apache.hadoop.yarn.server.resourcemanager.scheduler.capacity.CapacityScheduler: Application attempt appattempt_1522627038528_0001_000001 released container container_1522627038528_0001_01_000032 on node: host: bd18951cf78e:36999 #containers=3 available=<memory:4096, vCores:5> used=<memory:4096, vCores:3> with event: FINISHED
2018-04-01 19:58:45,042 INFO org.apache.hadoop.yarn.server.resourcemanager.rmcontainer.RMContainerImpl: container_1522627038528_0001_01_000033 Container Transitioned from RUNNING to COMPLETED
2018-04-01 19:58:45,042 INFO org.apache.hadoop.yarn.server.resourcemanager.scheduler.common.fica.FiCaSchedulerApp: Completed container: container_1522627038528_0001_01_000033 in state: COMPLETED event:FINISHED
2018-04-01 19:58:45,042 INFO org.apache.hadoop.yarn.server.resourcemanager.RMAuditLogger: USER=root	OPERATION=AM Released Container	TARGET=SchedulerApp	RESULT=SUCCESS	APPID=application_1522627038528_0001	CONTAINERID=container_1522627038528_0001_01_000033
2018-04-01 19:58:45,042 INFO org.apache.hadoop.yarn.server.resourcemanager.scheduler.SchedulerNode: Released container container_1522627038528_0001_01_000033 of capacity <memory:1024, vCores:1> on host bd18951cf78e:36999, which currently has 2 containers, <memory:3072, vCores:2> used and <memory:5120, vCores:6> available, release resources=true
2018-04-01 19:58:45,042 INFO org.apache.hadoop.yarn.server.resourcemanager.scheduler.capacity.LeafQueue: default used=<memory:3072, vCores:2> numContainers=2 user=root user-resources=<memory:3072, vCores:2>
2018-04-01 19:58:45,043 INFO org.apache.hadoop.yarn.server.resourcemanager.scheduler.capacity.LeafQueue: completedContainer container=Container: [ContainerId: container_1522627038528_0001_01_000033, NodeId: bd18951cf78e:36999, NodeHttpAddress: bd18951cf78e:8042, Resource: <memory:1024, vCores:1>, Priority: 20, Token: Token { kind: ContainerToken, service: 172.20.0.2:36999 }, ] queue=default: capacity=1.0, absoluteCapacity=1.0, usedResources=<memory:3072, vCores:2>, usedCapacity=0.375, absoluteUsedCapacity=0.375, numApps=1, numContainers=2 cluster=<memory:8192, vCores:8>
2018-04-01 19:58:45,043 INFO org.apache.hadoop.yarn.server.resourcemanager.scheduler.capacity.ParentQueue: completedContainer queue=root usedCapacity=0.375 absoluteUsedCapacity=0.375 used=<memory:3072, vCores:2> cluster=<memory:8192, vCores:8>
2018-04-01 19:58:45,043 INFO org.apache.hadoop.yarn.server.resourcemanager.scheduler.capacity.ParentQueue: Re-sorting completed queue: root.default stats: default: capacity=1.0, absoluteCapacity=1.0, usedResources=<memory:3072, vCores:2>, usedCapacity=0.375, absoluteUsedCapacity=0.375, numApps=1, numContainers=2
2018-04-01 19:58:45,043 INFO org.apache.hadoop.yarn.server.resourcemanager.scheduler.capacity.CapacityScheduler: Application attempt appattempt_1522627038528_0001_000001 released container container_1522627038528_0001_01_000033 on node: host: bd18951cf78e:36999 #containers=2 available=<memory:5120, vCores:6> used=<memory:3072, vCores:2> with event: FINISHED
2018-04-01 19:58:45,450 INFO org.apache.hadoop.yarn.server.resourcemanager.rmapp.attempt.RMAppAttemptImpl: Updating application attempt appattempt_1522627038528_0001_000001 with final state: FINISHING, and exit status: -1000
2018-04-01 19:58:45,451 INFO org.apache.hadoop.yarn.server.resourcemanager.rmapp.attempt.RMAppAttemptImpl: appattempt_1522627038528_0001_000001 State change from RUNNING to FINAL_SAVING
2018-04-01 19:58:45,451 INFO org.apache.hadoop.yarn.server.resourcemanager.rmapp.RMAppImpl: Updating application application_1522627038528_0001 with final state: FINISHING
2018-04-01 19:58:45,452 INFO org.apache.hadoop.yarn.server.resourcemanager.rmapp.RMAppImpl: application_1522627038528_0001 State change from RUNNING to FINAL_SAVING
2018-04-01 19:58:45,452 INFO org.apache.hadoop.yarn.server.resourcemanager.recovery.RMStateStore: Updating info for app: application_1522627038528_0001
2018-04-01 19:58:45,452 INFO org.apache.hadoop.yarn.server.resourcemanager.rmapp.attempt.RMAppAttemptImpl: appattempt_1522627038528_0001_000001 State change from FINAL_SAVING to FINISHING
2018-04-01 19:58:45,452 INFO org.apache.hadoop.yarn.server.resourcemanager.rmapp.RMAppImpl: application_1522627038528_0001 State change from FINAL_SAVING to FINISHING
2018-04-01 19:58:46,209 INFO org.apache.hadoop.yarn.server.resourcemanager.rmcontainer.RMContainerImpl: container_1522627038528_0001_01_000014 Container Transitioned from RUNNING to COMPLETED
2018-04-01 19:58:46,209 INFO org.apache.hadoop.yarn.server.resourcemanager.scheduler.common.fica.FiCaSchedulerApp: Completed container: container_1522627038528_0001_01_000014 in state: COMPLETED event:FINISHED
2018-04-01 19:58:46,209 INFO org.apache.hadoop.yarn.server.resourcemanager.RMAuditLogger: USER=root	OPERATION=AM Released Container	TARGET=SchedulerApp	RESULT=SUCCESS	APPID=application_1522627038528_0001	CONTAINERID=container_1522627038528_0001_01_000014
2018-04-01 19:58:46,210 INFO org.apache.hadoop.yarn.server.resourcemanager.scheduler.SchedulerNode: Released container container_1522627038528_0001_01_000014 of capacity <memory:1024, vCores:1> on host bd18951cf78e:36999, which currently has 1 containers, <memory:2048, vCores:1> used and <memory:6144, vCores:7> available, release resources=true
2018-04-01 19:58:46,210 INFO org.apache.hadoop.yarn.server.resourcemanager.scheduler.capacity.LeafQueue: default used=<memory:2048, vCores:1> numContainers=1 user=root user-resources=<memory:2048, vCores:1>
2018-04-01 19:58:46,210 INFO org.apache.hadoop.yarn.server.resourcemanager.scheduler.capacity.LeafQueue: completedContainer container=Container: [ContainerId: container_1522627038528_0001_01_000014, NodeId: bd18951cf78e:36999, NodeHttpAddress: bd18951cf78e:8042, Resource: <memory:1024, vCores:1>, Priority: 10, Token: Token { kind: ContainerToken, service: 172.20.0.2:36999 }, ] queue=default: capacity=1.0, absoluteCapacity=1.0, usedResources=<memory:2048, vCores:1>, usedCapacity=0.25, absoluteUsedCapacity=0.25, numApps=1, numContainers=1 cluster=<memory:8192, vCores:8>
2018-04-01 19:58:46,210 INFO org.apache.hadoop.yarn.server.resourcemanager.scheduler.capacity.ParentQueue: completedContainer queue=root usedCapacity=0.25 absoluteUsedCapacity=0.25 used=<memory:2048, vCores:1> cluster=<memory:8192, vCores:8>
2018-04-01 19:58:46,210 INFO org.apache.hadoop.yarn.server.resourcemanager.scheduler.capacity.ParentQueue: Re-sorting completed queue: root.default stats: default: capacity=1.0, absoluteCapacity=1.0, usedResources=<memory:2048, vCores:1>, usedCapacity=0.25, absoluteUsedCapacity=0.25, numApps=1, numContainers=1
2018-04-01 19:58:46,211 INFO org.apache.hadoop.yarn.server.resourcemanager.scheduler.capacity.CapacityScheduler: Application attempt appattempt_1522627038528_0001_000001 released container container_1522627038528_0001_01_000014 on node: host: bd18951cf78e:36999 #containers=1 available=<memory:6144, vCores:7> used=<memory:2048, vCores:1> with event: FINISHED
2018-04-01 19:58:46,457 INFO org.apache.hadoop.yarn.server.resourcemanager.ApplicationMasterService: application_1522627038528_0001 unregistered successfully. 
2018-04-01 19:58:46,827 INFO org.apache.hadoop.yarn.server.resourcemanager.ClientRMService: Allocated new applicationId: 2
2018-04-01 19:58:47,426 INFO org.apache.hadoop.yarn.server.resourcemanager.ClientRMService: Application with id 2 submitted by user root
2018-04-01 19:58:47,427 INFO org.apache.hadoop.yarn.server.resourcemanager.rmapp.RMAppImpl: Storing application with id application_1522627038528_0002
2018-04-01 19:58:47,427 INFO org.apache.hadoop.yarn.server.resourcemanager.RMAuditLogger: USER=root	IP=172.20.0.2	OPERATION=Submit Application Request	TARGET=ClientRMService	RESULT=SUCCESS	APPID=application_1522627038528_0002
2018-04-01 19:58:47,427 INFO org.apache.hadoop.yarn.server.resourcemanager.rmapp.RMAppImpl: application_1522627038528_0002 State change from NEW to NEW_SAVING
2018-04-01 19:58:47,427 INFO org.apache.hadoop.yarn.server.resourcemanager.recovery.RMStateStore: Storing info for app: application_1522627038528_0002
2018-04-01 19:58:47,427 INFO org.apache.hadoop.yarn.server.resourcemanager.rmapp.RMAppImpl: application_1522627038528_0002 State change from NEW_SAVING to SUBMITTED
2018-04-01 19:58:47,427 INFO org.apache.hadoop.yarn.server.resourcemanager.scheduler.capacity.ParentQueue: Application added - appId: application_1522627038528_0002 user: root leaf-queue of parent: root #applications: 2
2018-04-01 19:58:47,427 INFO org.apache.hadoop.yarn.server.resourcemanager.scheduler.capacity.CapacityScheduler: Accepted application application_1522627038528_0002 from user: root, in queue: default
2018-04-01 19:58:47,428 INFO org.apache.hadoop.yarn.server.resourcemanager.rmapp.RMAppImpl: application_1522627038528_0002 State change from SUBMITTED to ACCEPTED
2018-04-01 19:58:47,428 INFO org.apache.hadoop.yarn.server.resourcemanager.ApplicationMasterService: Registering app attempt : appattempt_1522627038528_0002_000001
2018-04-01 19:58:47,428 INFO org.apache.hadoop.yarn.server.resourcemanager.rmapp.attempt.RMAppAttemptImpl: appattempt_1522627038528_0002_000001 State change from NEW to SUBMITTED
2018-04-01 19:58:47,428 INFO org.apache.hadoop.yarn.server.resourcemanager.scheduler.capacity.LeafQueue: not starting application as amIfStarted exceeds amLimit
2018-04-01 19:58:47,428 INFO org.apache.hadoop.yarn.server.resourcemanager.scheduler.capacity.LeafQueue: Application added - appId: application_1522627038528_0002 user: org.apache.hadoop.yarn.server.resourcemanager.scheduler.capacity.LeafQueue$User@31560ad3, leaf-queue: default #user-pending-applications: 1 #user-active-applications: 1 #queue-pending-applications: 1 #queue-active-applications: 1
2018-04-01 19:58:47,428 INFO org.apache.hadoop.yarn.server.resourcemanager.scheduler.capacity.CapacityScheduler: Added Application Attempt appattempt_1522627038528_0002_000001 to scheduler from user root in queue default
2018-04-01 19:58:47,429 INFO org.apache.hadoop.yarn.server.resourcemanager.rmapp.attempt.RMAppAttemptImpl: appattempt_1522627038528_0002_000001 State change from SUBMITTED to SCHEDULED
2018-04-01 19:58:52,226 INFO org.apache.hadoop.yarn.server.resourcemanager.rmcontainer.RMContainerImpl: container_1522627038528_0001_01_000001 Container Transitioned from RUNNING to COMPLETED
2018-04-01 19:58:52,226 INFO org.apache.hadoop.yarn.server.resourcemanager.ApplicationMasterService: Unregistering app attempt : appattempt_1522627038528_0001_000001
2018-04-01 19:58:52,226 INFO org.apache.hadoop.yarn.server.resourcemanager.scheduler.common.fica.FiCaSchedulerApp: Completed container: container_1522627038528_0001_01_000001 in state: COMPLETED event:FINISHED
2018-04-01 19:58:52,226 INFO org.apache.hadoop.yarn.server.resourcemanager.RMAuditLogger: USER=root	OPERATION=AM Released Container	TARGET=SchedulerApp	RESULT=SUCCESS	APPID=application_1522627038528_0001	CONTAINERID=container_1522627038528_0001_01_000001
2018-04-01 19:58:52,226 INFO org.apache.hadoop.yarn.server.resourcemanager.scheduler.SchedulerNode: Released container container_1522627038528_0001_01_000001 of capacity <memory:2048, vCores:1> on host bd18951cf78e:36999, which currently has 0 containers, <memory:0, vCores:0> used and <memory:8192, vCores:8> available, release resources=true
2018-04-01 19:58:52,226 INFO org.apache.hadoop.yarn.server.resourcemanager.scheduler.capacity.LeafQueue: default used=<memory:0, vCores:0> numContainers=0 user=root user-resources=<memory:0, vCores:0>
2018-04-01 19:58:52,226 INFO org.apache.hadoop.yarn.server.resourcemanager.scheduler.capacity.LeafQueue: completedContainer container=Container: [ContainerId: container_1522627038528_0001_01_000001, NodeId: bd18951cf78e:36999, NodeHttpAddress: bd18951cf78e:8042, Resource: <memory:2048, vCores:1>, Priority: 0, Token: Token { kind: ContainerToken, service: 172.20.0.2:36999 }, ] queue=default: capacity=1.0, absoluteCapacity=1.0, usedResources=<memory:0, vCores:0>, usedCapacity=0.0, absoluteUsedCapacity=0.0, numApps=2, numContainers=0 cluster=<memory:8192, vCores:8>
2018-04-01 19:58:52,226 INFO org.apache.hadoop.yarn.server.resourcemanager.scheduler.capacity.ParentQueue: completedContainer queue=root usedCapacity=0.0 absoluteUsedCapacity=0.0 used=<memory:0, vCores:0> cluster=<memory:8192, vCores:8>
2018-04-01 19:58:52,226 INFO org.apache.hadoop.yarn.server.resourcemanager.scheduler.capacity.ParentQueue: Re-sorting completed queue: root.default stats: default: capacity=1.0, absoluteCapacity=1.0, usedResources=<memory:0, vCores:0>, usedCapacity=0.0, absoluteUsedCapacity=0.0, numApps=2, numContainers=0
2018-04-01 19:58:52,227 INFO org.apache.hadoop.yarn.server.resourcemanager.scheduler.capacity.CapacityScheduler: Application attempt appattempt_1522627038528_0001_000001 released container container_1522627038528_0001_01_000001 on node: host: bd18951cf78e:36999 #containers=0 available=<memory:8192, vCores:8> used=<memory:0, vCores:0> with event: FINISHED
2018-04-01 19:58:52,227 INFO org.apache.hadoop.yarn.server.resourcemanager.security.AMRMTokenSecretManager: Application finished, removing password for appattempt_1522627038528_0001_000001
2018-04-01 19:58:52,228 INFO org.apache.hadoop.yarn.server.resourcemanager.rmapp.attempt.RMAppAttemptImpl: appattempt_1522627038528_0001_000001 State change from FINISHING to FINISHED
2018-04-01 19:58:52,230 INFO org.apache.hadoop.yarn.server.resourcemanager.rmapp.RMAppImpl: application_1522627038528_0001 State change from FINISHING to FINISHED
2018-04-01 19:58:52,230 INFO org.apache.hadoop.yarn.server.resourcemanager.scheduler.capacity.CapacityScheduler: Application Attempt appattempt_1522627038528_0001_000001 is done. finalState=FINISHED
2018-04-01 19:58:52,230 INFO org.apache.hadoop.yarn.server.resourcemanager.scheduler.AppSchedulingInfo: Application application_1522627038528_0001 requests cleared
2018-04-01 19:58:52,230 WARN org.apache.hadoop.yarn.server.resourcemanager.scheduler.capacity.LeafQueue: maximum-am-resource-percent is insufficient to start a single application in queue, it is likely set too low. skipping enforcement to allow at least one application to start
2018-04-01 19:58:52,230 WARN org.apache.hadoop.yarn.server.resourcemanager.scheduler.capacity.LeafQueue: maximum-am-resource-percent is insufficient to start a single application in queue for user, it is likely set too low. skipping enforcement to allow at least one application to start
2018-04-01 19:58:52,231 INFO org.apache.hadoop.yarn.server.resourcemanager.scheduler.capacity.LeafQueue: Application application_1522627038528_0002 from user: root activated in queue: default
2018-04-01 19:58:52,231 INFO org.apache.hadoop.yarn.server.resourcemanager.scheduler.capacity.LeafQueue: Application removed - appId: application_1522627038528_0001 user: root queue: default #user-pending-applications: 0 #user-active-applications: 1 #queue-pending-applications: 0 #queue-active-applications: 1
2018-04-01 19:58:52,231 INFO org.apache.hadoop.yarn.server.resourcemanager.amlauncher.AMLauncher: Cleaning master appattempt_1522627038528_0001_000001
2018-04-01 19:58:52,231 INFO org.apache.hadoop.yarn.server.resourcemanager.scheduler.capacity.ParentQueue: Application removed - appId: application_1522627038528_0001 user: root leaf-queue of parent: root #applications: 1
2018-04-01 19:58:52,231 INFO org.apache.hadoop.yarn.server.resourcemanager.RMAuditLogger: USER=root	OPERATION=Application Finished - Succeeded	TARGET=RMAppManager	RESULT=SUCCESS	APPID=application_1522627038528_0001
2018-04-01 19:58:52,233 INFO org.apache.hadoop.yarn.server.resourcemanager.RMAppManager$ApplicationSummary: appId=application_1522627038528_0001,name=grep-search,user=root,queue=default,state=FINISHED,trackingUrl=http://bd18951cf78e:8088/proxy/application_1522627038528_0001/,appMasterHost=bd18951cf78e,startTime=1522627080111,finishTime=1522627125451,finalStatus=SUCCEEDED,memorySeconds=329643,vcoreSeconds=255,preemptedAMContainers=0,preemptedNonAMContainers=0,preemptedResources=<memory:0\, vCores:0>,applicationType=MAPREDUCE
2018-04-01 19:58:52,243 INFO org.apache.hadoop.yarn.server.resourcemanager.rmcontainer.RMContainerImpl: container_1522627038528_0002_01_000001 Container Transitioned from NEW to ALLOCATED
2018-04-01 19:58:52,243 INFO org.apache.hadoop.yarn.server.resourcemanager.RMAuditLogger: USER=root	OPERATION=AM Allocated Container	TARGET=SchedulerApp	RESULT=SUCCESS	APPID=application_1522627038528_0002	CONTAINERID=container_1522627038528_0002_01_000001
2018-04-01 19:58:52,243 INFO org.apache.hadoop.yarn.server.resourcemanager.scheduler.SchedulerNode: Assigned container container_1522627038528_0002_01_000001 of capacity <memory:2048, vCores:1> on host bd18951cf78e:36999, which has 1 containers, <memory:2048, vCores:1> used and <memory:6144, vCores:7> available after allocation
2018-04-01 19:58:52,244 INFO org.apache.hadoop.yarn.server.resourcemanager.scheduler.capacity.LeafQueue: assignedContainer application attempt=appattempt_1522627038528_0002_000001 container=Container: [ContainerId: container_1522627038528_0002_01_000001, NodeId: bd18951cf78e:36999, NodeHttpAddress: bd18951cf78e:8042, Resource: <memory:2048, vCores:1>, Priority: 0, Token: null, ] queue=default: capacity=1.0, absoluteCapacity=1.0, usedResources=<memory:0, vCores:0>, usedCapacity=0.0, absoluteUsedCapacity=0.0, numApps=1, numContainers=0 clusterResource=<memory:8192, vCores:8>
2018-04-01 19:58:52,244 INFO org.apache.hadoop.yarn.server.resourcemanager.scheduler.capacity.ParentQueue: Re-sorting assigned queue: root.default stats: default: capacity=1.0, absoluteCapacity=1.0, usedResources=<memory:2048, vCores:1>, usedCapacity=0.25, absoluteUsedCapacity=0.25, numApps=1, numContainers=1
2018-04-01 19:58:52,244 INFO org.apache.hadoop.yarn.server.resourcemanager.scheduler.capacity.ParentQueue: assignedContainer queue=root usedCapacity=0.25 absoluteUsedCapacity=0.25 used=<memory:2048, vCores:1> cluster=<memory:8192, vCores:8>
2018-04-01 19:58:52,245 INFO org.apache.hadoop.yarn.server.resourcemanager.security.NMTokenSecretManagerInRM: Sending NMToken for nodeId : bd18951cf78e:36999 for container : container_1522627038528_0002_01_000001
2018-04-01 19:58:52,246 INFO org.apache.hadoop.yarn.server.resourcemanager.rmcontainer.RMContainerImpl: container_1522627038528_0002_01_000001 Container Transitioned from ALLOCATED to ACQUIRED
2018-04-01 19:58:52,246 INFO org.apache.hadoop.yarn.server.resourcemanager.security.NMTokenSecretManagerInRM: Clear node set for appattempt_1522627038528_0002_000001
2018-04-01 19:58:52,246 INFO org.apache.hadoop.yarn.server.resourcemanager.rmapp.attempt.RMAppAttemptImpl: Storing attempt: AppId: application_1522627038528_0002 AttemptId: appattempt_1522627038528_0002_000001 MasterContainer: Container: [ContainerId: container_1522627038528_0002_01_000001, NodeId: bd18951cf78e:36999, NodeHttpAddress: bd18951cf78e:8042, Resource: <memory:2048, vCores:1>, Priority: 0, Token: Token { kind: ContainerToken, service: 172.20.0.2:36999 }, ]
2018-04-01 19:58:52,246 INFO org.apache.hadoop.yarn.server.resourcemanager.rmapp.attempt.RMAppAttemptImpl: appattempt_1522627038528_0002_000001 State change from SCHEDULED to ALLOCATED_SAVING
2018-04-01 19:58:52,247 INFO org.apache.hadoop.yarn.server.resourcemanager.rmapp.attempt.RMAppAttemptImpl: appattempt_1522627038528_0002_000001 State change from ALLOCATED_SAVING to ALLOCATED
2018-04-01 19:58:52,247 INFO org.apache.hadoop.yarn.server.resourcemanager.amlauncher.AMLauncher: Launching masterappattempt_1522627038528_0002_000001
2018-04-01 19:58:52,249 INFO org.apache.hadoop.yarn.server.resourcemanager.amlauncher.AMLauncher: Setting up container Container: [ContainerId: container_1522627038528_0002_01_000001, NodeId: bd18951cf78e:36999, NodeHttpAddress: bd18951cf78e:8042, Resource: <memory:2048, vCores:1>, Priority: 0, Token: Token { kind: ContainerToken, service: 172.20.0.2:36999 }, ] for AM appattempt_1522627038528_0002_000001
2018-04-01 19:58:52,249 INFO org.apache.hadoop.yarn.server.resourcemanager.amlauncher.AMLauncher: Command to launch container container_1522627038528_0002_01_000001 : $JAVA_HOME/bin/java -Dlog4j.configuration=container-log4j.properties -Dyarn.app.container.log.dir=<LOG_DIR> -Dyarn.app.container.log.filesize=0 -Dhadoop.root.logger=INFO,CLA -Dhadoop.root.logfile=syslog  -Xmx1024m org.apache.hadoop.mapreduce.v2.app.MRAppMaster 1><LOG_DIR>/stdout 2><LOG_DIR>/stderr 
2018-04-01 19:58:52,249 INFO org.apache.hadoop.yarn.server.resourcemanager.security.AMRMTokenSecretManager: Create AMRMToken for ApplicationAttempt: appattempt_1522627038528_0002_000001
2018-04-01 19:58:52,249 INFO org.apache.hadoop.yarn.server.resourcemanager.security.AMRMTokenSecretManager: Creating password for appattempt_1522627038528_0002_000001
2018-04-01 19:58:52,257 INFO org.apache.hadoop.yarn.server.resourcemanager.amlauncher.AMLauncher: Done launching container Container: [ContainerId: container_1522627038528_0002_01_000001, NodeId: bd18951cf78e:36999, NodeHttpAddress: bd18951cf78e:8042, Resource: <memory:2048, vCores:1>, Priority: 0, Token: Token { kind: ContainerToken, service: 172.20.0.2:36999 }, ] for AM appattempt_1522627038528_0002_000001
2018-04-01 19:58:52,257 INFO org.apache.hadoop.yarn.server.resourcemanager.rmapp.attempt.RMAppAttemptImpl: appattempt_1522627038528_0002_000001 State change from ALLOCATED to LAUNCHED
2018-04-01 19:58:53,246 INFO org.apache.hadoop.yarn.server.resourcemanager.rmcontainer.RMContainerImpl: container_1522627038528_0002_01_000001 Container Transitioned from ACQUIRED to RUNNING
2018-04-01 19:58:53,246 INFO org.apache.hadoop.yarn.server.resourcemanager.scheduler.capacity.CapacityScheduler: Null container completed...
2018-04-01 19:58:53,246 INFO org.apache.hadoop.yarn.server.resourcemanager.scheduler.capacity.CapacityScheduler: Null container completed...
2018-04-01 19:58:55,422 INFO SecurityLogger.org.apache.hadoop.ipc.Server: Auth successful for appattempt_1522627038528_0002_000001 (auth:SIMPLE)
2018-04-01 19:58:55,424 INFO org.apache.hadoop.yarn.server.resourcemanager.ApplicationMasterService: AM registration appattempt_1522627038528_0002_000001
2018-04-01 19:58:55,424 INFO org.apache.hadoop.yarn.server.resourcemanager.RMAuditLogger: USER=root	IP=172.20.0.2	OPERATION=Register App Master	TARGET=ApplicationMasterService	RESULT=SUCCESS	APPID=application_1522627038528_0002	APPATTEMPTID=appattempt_1522627038528_0002_000001
2018-04-01 19:58:55,425 INFO org.apache.hadoop.yarn.server.resourcemanager.rmapp.attempt.RMAppAttemptImpl: appattempt_1522627038528_0002_000001 State change from LAUNCHED to RUNNING
2018-04-01 19:58:55,425 INFO org.apache.hadoop.yarn.server.resourcemanager.rmapp.RMAppImpl: application_1522627038528_0002 State change from ACCEPTED to RUNNING
2018-04-01 19:58:57,257 INFO org.apache.hadoop.yarn.server.resourcemanager.rmcontainer.RMContainerImpl: container_1522627038528_0002_01_000002 Container Transitioned from NEW to ALLOCATED
2018-04-01 19:58:57,257 INFO org.apache.hadoop.yarn.server.resourcemanager.RMAuditLogger: USER=root	OPERATION=AM Allocated Container	TARGET=SchedulerApp	RESULT=SUCCESS	APPID=application_1522627038528_0002	CONTAINERID=container_1522627038528_0002_01_000002
2018-04-01 19:58:57,257 INFO org.apache.hadoop.yarn.server.resourcemanager.scheduler.SchedulerNode: Assigned container container_1522627038528_0002_01_000002 of capacity <memory:1024, vCores:1> on host bd18951cf78e:36999, which has 2 containers, <memory:3072, vCores:2> used and <memory:5120, vCores:6> available after allocation
2018-04-01 19:58:57,258 INFO org.apache.hadoop.yarn.server.resourcemanager.scheduler.capacity.LeafQueue: assignedContainer application attempt=appattempt_1522627038528_0002_000001 container=Container: [ContainerId: container_1522627038528_0002_01_000002, NodeId: bd18951cf78e:36999, NodeHttpAddress: bd18951cf78e:8042, Resource: <memory:1024, vCores:1>, Priority: 20, Token: null, ] queue=default: capacity=1.0, absoluteCapacity=1.0, usedResources=<memory:2048, vCores:1>, usedCapacity=0.25, absoluteUsedCapacity=0.25, numApps=1, numContainers=1 clusterResource=<memory:8192, vCores:8>
2018-04-01 19:58:57,259 INFO org.apache.hadoop.yarn.server.resourcemanager.scheduler.capacity.ParentQueue: Re-sorting assigned queue: root.default stats: default: capacity=1.0, absoluteCapacity=1.0, usedResources=<memory:3072, vCores:2>, usedCapacity=0.375, absoluteUsedCapacity=0.375, numApps=1, numContainers=2
2018-04-01 19:58:57,259 INFO org.apache.hadoop.yarn.server.resourcemanager.scheduler.capacity.ParentQueue: assignedContainer queue=root usedCapacity=0.375 absoluteUsedCapacity=0.375 used=<memory:3072, vCores:2> cluster=<memory:8192, vCores:8>
2018-04-01 19:58:57,482 INFO org.apache.hadoop.yarn.server.resourcemanager.security.NMTokenSecretManagerInRM: Sending NMToken for nodeId : bd18951cf78e:36999 for container : container_1522627038528_0002_01_000002
2018-04-01 19:58:57,483 INFO org.apache.hadoop.yarn.server.resourcemanager.rmcontainer.RMContainerImpl: container_1522627038528_0002_01_000002 Container Transitioned from ALLOCATED to ACQUIRED
2018-04-01 19:58:58,257 INFO org.apache.hadoop.yarn.server.resourcemanager.rmcontainer.RMContainerImpl: container_1522627038528_0002_01_000002 Container Transitioned from ACQUIRED to RUNNING
2018-04-01 19:58:58,501 INFO org.apache.hadoop.yarn.server.resourcemanager.scheduler.AppSchedulingInfo: checking for deactivate of application :application_1522627038528_0002
2018-04-01 19:59:00,839 INFO org.apache.hadoop.yarn.server.resourcemanager.rmcontainer.RMContainerImpl: container_1522627038528_0002_01_000002 Container Transitioned from RUNNING to COMPLETED
2018-04-01 19:59:00,839 INFO org.apache.hadoop.yarn.server.resourcemanager.scheduler.common.fica.FiCaSchedulerApp: Completed container: container_1522627038528_0002_01_000002 in state: COMPLETED event:FINISHED
2018-04-01 19:59:00,839 INFO org.apache.hadoop.yarn.server.resourcemanager.RMAuditLogger: USER=root	OPERATION=AM Released Container	TARGET=SchedulerApp	RESULT=SUCCESS	APPID=application_1522627038528_0002	CONTAINERID=container_1522627038528_0002_01_000002
2018-04-01 19:59:00,839 INFO org.apache.hadoop.yarn.server.resourcemanager.scheduler.SchedulerNode: Released container container_1522627038528_0002_01_000002 of capacity <memory:1024, vCores:1> on host bd18951cf78e:36999, which currently has 1 containers, <memory:2048, vCores:1> used and <memory:6144, vCores:7> available, release resources=true
2018-04-01 19:59:00,840 INFO org.apache.hadoop.yarn.server.resourcemanager.scheduler.capacity.LeafQueue: default used=<memory:2048, vCores:1> numContainers=1 user=root user-resources=<memory:2048, vCores:1>
2018-04-01 19:59:00,840 INFO org.apache.hadoop.yarn.server.resourcemanager.scheduler.capacity.LeafQueue: completedContainer container=Container: [ContainerId: container_1522627038528_0002_01_000002, NodeId: bd18951cf78e:36999, NodeHttpAddress: bd18951cf78e:8042, Resource: <memory:1024, vCores:1>, Priority: 20, Token: Token { kind: ContainerToken, service: 172.20.0.2:36999 }, ] queue=default: capacity=1.0, absoluteCapacity=1.0, usedResources=<memory:2048, vCores:1>, usedCapacity=0.25, absoluteUsedCapacity=0.25, numApps=1, numContainers=1 cluster=<memory:8192, vCores:8>
2018-04-01 19:59:00,841 INFO org.apache.hadoop.yarn.server.resourcemanager.scheduler.capacity.ParentQueue: completedContainer queue=root usedCapacity=0.25 absoluteUsedCapacity=0.25 used=<memory:2048, vCores:1> cluster=<memory:8192, vCores:8>
2018-04-01 19:59:00,841 INFO org.apache.hadoop.yarn.server.resourcemanager.scheduler.capacity.ParentQueue: Re-sorting completed queue: root.default stats: default: capacity=1.0, absoluteCapacity=1.0, usedResources=<memory:2048, vCores:1>, usedCapacity=0.25, absoluteUsedCapacity=0.25, numApps=1, numContainers=1
2018-04-01 19:59:00,841 INFO org.apache.hadoop.yarn.server.resourcemanager.scheduler.capacity.CapacityScheduler: Application attempt appattempt_1522627038528_0002_000001 released container container_1522627038528_0002_01_000002 on node: host: bd18951cf78e:36999 #containers=1 available=<memory:6144, vCores:7> used=<memory:2048, vCores:1> with event: FINISHED
2018-04-01 19:59:01,841 INFO org.apache.hadoop.yarn.server.resourcemanager.rmcontainer.RMContainerImpl: container_1522627038528_0002_01_000003 Container Transitioned from NEW to ALLOCATED
2018-04-01 19:59:01,841 INFO org.apache.hadoop.yarn.server.resourcemanager.RMAuditLogger: USER=root	OPERATION=AM Allocated Container	TARGET=SchedulerApp	RESULT=SUCCESS	APPID=application_1522627038528_0002	CONTAINERID=container_1522627038528_0002_01_000003
2018-04-01 19:59:01,841 INFO org.apache.hadoop.yarn.server.resourcemanager.scheduler.SchedulerNode: Assigned container container_1522627038528_0002_01_000003 of capacity <memory:1024, vCores:1> on host bd18951cf78e:36999, which has 2 containers, <memory:3072, vCores:2> used and <memory:5120, vCores:6> available after allocation
2018-04-01 19:59:01,842 INFO org.apache.hadoop.yarn.server.resourcemanager.scheduler.capacity.LeafQueue: assignedContainer application attempt=appattempt_1522627038528_0002_000001 container=Container: [ContainerId: container_1522627038528_0002_01_000003, NodeId: bd18951cf78e:36999, NodeHttpAddress: bd18951cf78e:8042, Resource: <memory:1024, vCores:1>, Priority: 10, Token: null, ] queue=default: capacity=1.0, absoluteCapacity=1.0, usedResources=<memory:2048, vCores:1>, usedCapacity=0.25, absoluteUsedCapacity=0.25, numApps=1, numContainers=1 clusterResource=<memory:8192, vCores:8>
2018-04-01 19:59:01,842 INFO org.apache.hadoop.yarn.server.resourcemanager.scheduler.capacity.ParentQueue: Re-sorting assigned queue: root.default stats: default: capacity=1.0, absoluteCapacity=1.0, usedResources=<memory:3072, vCores:2>, usedCapacity=0.375, absoluteUsedCapacity=0.375, numApps=1, numContainers=2
2018-04-01 19:59:01,842 INFO org.apache.hadoop.yarn.server.resourcemanager.scheduler.capacity.ParentQueue: assignedContainer queue=root usedCapacity=0.375 absoluteUsedCapacity=0.375 used=<memory:3072, vCores:2> cluster=<memory:8192, vCores:8>
2018-04-01 19:59:02,528 INFO org.apache.hadoop.yarn.server.resourcemanager.rmcontainer.RMContainerImpl: container_1522627038528_0002_01_000003 Container Transitioned from ALLOCATED to ACQUIRED
2018-04-01 19:59:02,842 INFO org.apache.hadoop.yarn.server.resourcemanager.rmcontainer.RMContainerImpl: container_1522627038528_0002_01_000003 Container Transitioned from ACQUIRED to RUNNING
2018-04-01 19:59:03,533 INFO org.apache.hadoop.yarn.server.resourcemanager.scheduler.AppSchedulingInfo: checking for deactivate of application :application_1522627038528_0002
2018-04-01 19:59:05,333 INFO org.apache.hadoop.yarn.server.resourcemanager.rmapp.attempt.RMAppAttemptImpl: Updating application attempt appattempt_1522627038528_0002_000001 with final state: FINISHING, and exit status: -1000
2018-04-01 19:59:05,333 INFO org.apache.hadoop.yarn.server.resourcemanager.rmapp.attempt.RMAppAttemptImpl: appattempt_1522627038528_0002_000001 State change from RUNNING to FINAL_SAVING
2018-04-01 19:59:05,334 INFO org.apache.hadoop.yarn.server.resourcemanager.rmapp.RMAppImpl: Updating application application_1522627038528_0002 with final state: FINISHING
2018-04-01 19:59:05,334 INFO org.apache.hadoop.yarn.server.resourcemanager.rmapp.RMAppImpl: application_1522627038528_0002 State change from RUNNING to FINAL_SAVING
2018-04-01 19:59:05,334 INFO org.apache.hadoop.yarn.server.resourcemanager.recovery.RMStateStore: Updating info for app: application_1522627038528_0002
2018-04-01 19:59:05,334 INFO org.apache.hadoop.yarn.server.resourcemanager.rmapp.attempt.RMAppAttemptImpl: appattempt_1522627038528_0002_000001 State change from FINAL_SAVING to FINISHING
2018-04-01 19:59:05,334 INFO org.apache.hadoop.yarn.server.resourcemanager.rmapp.RMAppImpl: application_1522627038528_0002 State change from FINAL_SAVING to FINISHING
2018-04-01 19:59:06,114 INFO org.apache.hadoop.yarn.server.resourcemanager.rmcontainer.RMContainerImpl: container_1522627038528_0002_01_000003 Container Transitioned from RUNNING to COMPLETED
2018-04-01 19:59:06,115 INFO org.apache.hadoop.yarn.server.resourcemanager.scheduler.common.fica.FiCaSchedulerApp: Completed container: container_1522627038528_0002_01_000003 in state: COMPLETED event:FINISHED
2018-04-01 19:59:06,115 INFO org.apache.hadoop.yarn.server.resourcemanager.RMAuditLogger: USER=root	OPERATION=AM Released Container	TARGET=SchedulerApp	RESULT=SUCCESS	APPID=application_1522627038528_0002	CONTAINERID=container_1522627038528_0002_01_000003
2018-04-01 19:59:06,115 INFO org.apache.hadoop.yarn.server.resourcemanager.scheduler.SchedulerNode: Released container container_1522627038528_0002_01_000003 of capacity <memory:1024, vCores:1> on host bd18951cf78e:36999, which currently has 1 containers, <memory:2048, vCores:1> used and <memory:6144, vCores:7> available, release resources=true
2018-04-01 19:59:06,115 INFO org.apache.hadoop.yarn.server.resourcemanager.scheduler.capacity.LeafQueue: default used=<memory:2048, vCores:1> numContainers=1 user=root user-resources=<memory:2048, vCores:1>
2018-04-01 19:59:06,115 INFO org.apache.hadoop.yarn.server.resourcemanager.scheduler.capacity.LeafQueue: completedContainer container=Container: [ContainerId: container_1522627038528_0002_01_000003, NodeId: bd18951cf78e:36999, NodeHttpAddress: bd18951cf78e:8042, Resource: <memory:1024, vCores:1>, Priority: 10, Token: Token { kind: ContainerToken, service: 172.20.0.2:36999 }, ] queue=default: capacity=1.0, absoluteCapacity=1.0, usedResources=<memory:2048, vCores:1>, usedCapacity=0.25, absoluteUsedCapacity=0.25, numApps=1, numContainers=1 cluster=<memory:8192, vCores:8>
2018-04-01 19:59:06,115 INFO org.apache.hadoop.yarn.server.resourcemanager.scheduler.capacity.ParentQueue: completedContainer queue=root usedCapacity=0.25 absoluteUsedCapacity=0.25 used=<memory:2048, vCores:1> cluster=<memory:8192, vCores:8>
2018-04-01 19:59:06,115 INFO org.apache.hadoop.yarn.server.resourcemanager.scheduler.capacity.ParentQueue: Re-sorting completed queue: root.default stats: default: capacity=1.0, absoluteCapacity=1.0, usedResources=<memory:2048, vCores:1>, usedCapacity=0.25, absoluteUsedCapacity=0.25, numApps=1, numContainers=1
2018-04-01 19:59:06,115 INFO org.apache.hadoop.yarn.server.resourcemanager.scheduler.capacity.CapacityScheduler: Application attempt appattempt_1522627038528_0002_000001 released container container_1522627038528_0002_01_000003 on node: host: bd18951cf78e:36999 #containers=1 available=<memory:6144, vCores:7> used=<memory:2048, vCores:1> with event: FINISHED
2018-04-01 19:59:06,336 INFO org.apache.hadoop.yarn.server.resourcemanager.ApplicationMasterService: application_1522627038528_0002 unregistered successfully. 
2018-04-01 19:59:12,136 INFO org.apache.hadoop.yarn.server.resourcemanager.rmcontainer.RMContainerImpl: container_1522627038528_0002_01_000001 Container Transitioned from RUNNING to COMPLETED
2018-04-01 19:59:12,136 INFO org.apache.hadoop.yarn.server.resourcemanager.ApplicationMasterService: Unregistering app attempt : appattempt_1522627038528_0002_000001
2018-04-01 19:59:12,137 INFO org.apache.hadoop.yarn.server.resourcemanager.scheduler.common.fica.FiCaSchedulerApp: Completed container: container_1522627038528_0002_01_000001 in state: COMPLETED event:FINISHED
2018-04-01 19:59:12,137 INFO org.apache.hadoop.yarn.server.resourcemanager.security.AMRMTokenSecretManager: Application finished, removing password for appattempt_1522627038528_0002_000001
2018-04-01 19:59:12,137 INFO org.apache.hadoop.yarn.server.resourcemanager.RMAuditLogger: USER=root	OPERATION=AM Released Container	TARGET=SchedulerApp	RESULT=SUCCESS	APPID=application_1522627038528_0002	CONTAINERID=container_1522627038528_0002_01_000001
2018-04-01 19:59:12,137 INFO org.apache.hadoop.yarn.server.resourcemanager.rmapp.attempt.RMAppAttemptImpl: appattempt_1522627038528_0002_000001 State change from FINISHING to FINISHED
2018-04-01 19:59:12,137 INFO org.apache.hadoop.yarn.server.resourcemanager.scheduler.SchedulerNode: Released container container_1522627038528_0002_01_000001 of capacity <memory:2048, vCores:1> on host bd18951cf78e:36999, which currently has 0 containers, <memory:0, vCores:0> used and <memory:8192, vCores:8> available, release resources=true
2018-04-01 19:59:12,137 INFO org.apache.hadoop.yarn.server.resourcemanager.rmapp.RMAppImpl: application_1522627038528_0002 State change from FINISHING to FINISHED
2018-04-01 19:59:12,138 INFO org.apache.hadoop.yarn.server.resourcemanager.scheduler.capacity.LeafQueue: default used=<memory:0, vCores:0> numContainers=0 user=root user-resources=<memory:0, vCores:0>
2018-04-01 19:59:12,138 INFO org.apache.hadoop.yarn.server.resourcemanager.RMAuditLogger: USER=root	OPERATION=Application Finished - Succeeded	TARGET=RMAppManager	RESULT=SUCCESS	APPID=application_1522627038528_0002
2018-04-01 19:59:12,138 INFO org.apache.hadoop.yarn.server.resourcemanager.scheduler.capacity.LeafQueue: completedContainer container=Container: [ContainerId: container_1522627038528_0002_01_000001, NodeId: bd18951cf78e:36999, NodeHttpAddress: bd18951cf78e:8042, Resource: <memory:2048, vCores:1>, Priority: 0, Token: Token { kind: ContainerToken, service: 172.20.0.2:36999 }, ] queue=default: capacity=1.0, absoluteCapacity=1.0, usedResources=<memory:0, vCores:0>, usedCapacity=0.0, absoluteUsedCapacity=0.0, numApps=1, numContainers=0 cluster=<memory:8192, vCores:8>
2018-04-01 19:59:12,138 INFO org.apache.hadoop.yarn.server.resourcemanager.scheduler.capacity.ParentQueue: completedContainer queue=root usedCapacity=0.0 absoluteUsedCapacity=0.0 used=<memory:0, vCores:0> cluster=<memory:8192, vCores:8>
2018-04-01 19:59:12,139 INFO org.apache.hadoop.yarn.server.resourcemanager.scheduler.capacity.ParentQueue: Re-sorting completed queue: root.default stats: default: capacity=1.0, absoluteCapacity=1.0, usedResources=<memory:0, vCores:0>, usedCapacity=0.0, absoluteUsedCapacity=0.0, numApps=1, numContainers=0
2018-04-01 19:59:12,139 INFO org.apache.hadoop.yarn.server.resourcemanager.amlauncher.AMLauncher: Cleaning master appattempt_1522627038528_0002_000001
2018-04-01 19:59:12,141 INFO org.apache.hadoop.yarn.server.resourcemanager.scheduler.capacity.CapacityScheduler: Application attempt appattempt_1522627038528_0002_000001 released container container_1522627038528_0002_01_000001 on node: host: bd18951cf78e:36999 #containers=0 available=<memory:8192, vCores:8> used=<memory:0, vCores:0> with event: FINISHED
2018-04-01 19:59:12,141 INFO org.apache.hadoop.yarn.server.resourcemanager.RMAppManager$ApplicationSummary: appId=application_1522627038528_0002,name=grep-sort,user=root,queue=default,state=FINISHED,trackingUrl=http://bd18951cf78e:8088/proxy/application_1522627038528_0002/,appMasterHost=bd18951cf78e,startTime=1522627127426,finishTime=1522627145334,finalStatus=SUCCEEDED,memorySeconds=48783,vcoreSeconds=26,preemptedAMContainers=0,preemptedNonAMContainers=0,preemptedResources=<memory:0\, vCores:0>,applicationType=MAPREDUCE
2018-04-01 19:59:12,142 INFO org.apache.hadoop.yarn.server.resourcemanager.scheduler.capacity.CapacityScheduler: Application Attempt appattempt_1522627038528_0002_000001 is done. finalState=FINISHED
2018-04-01 19:59:12,143 INFO org.apache.hadoop.yarn.server.resourcemanager.scheduler.AppSchedulingInfo: Application application_1522627038528_0002 requests cleared
2018-04-01 19:59:12,143 INFO org.apache.hadoop.yarn.server.resourcemanager.scheduler.capacity.LeafQueue: Application removed - appId: application_1522627038528_0002 user: root queue: default #user-pending-applications: 0 #user-active-applications: 0 #queue-pending-applications: 0 #queue-active-applications: 0
2018-04-01 19:59:12,143 INFO org.apache.hadoop.yarn.server.resourcemanager.scheduler.capacity.ParentQueue: Application removed - appId: application_1522627038528_0002 user: root leaf-queue of parent: root #applications: 0
2018-04-01 19:59:13,158 INFO org.apache.hadoop.yarn.server.resourcemanager.scheduler.capacity.CapacityScheduler: Null container completed...
2018-04-01 20:00:18,443 INFO org.apache.hadoop.yarn.server.resourcemanager.ClientRMService: Allocated new applicationId: 3
2018-04-01 20:00:19,129 INFO org.apache.hadoop.yarn.server.resourcemanager.ClientRMService: Application with id 3 submitted by user root
2018-04-01 20:00:19,129 INFO org.apache.hadoop.yarn.server.resourcemanager.rmapp.RMAppImpl: Storing application with id application_1522627038528_0003
2018-04-01 20:00:19,129 INFO org.apache.hadoop.yarn.server.resourcemanager.RMAuditLogger: USER=root	IP=172.20.0.2	OPERATION=Submit Application Request	TARGET=ClientRMService	RESULT=SUCCESS	APPID=application_1522627038528_0003
2018-04-01 20:00:19,129 INFO org.apache.hadoop.yarn.server.resourcemanager.rmapp.RMAppImpl: application_1522627038528_0003 State change from NEW to NEW_SAVING
2018-04-01 20:00:19,129 INFO org.apache.hadoop.yarn.server.resourcemanager.recovery.RMStateStore: Storing info for app: application_1522627038528_0003
2018-04-01 20:00:19,129 INFO org.apache.hadoop.yarn.server.resourcemanager.rmapp.RMAppImpl: application_1522627038528_0003 State change from NEW_SAVING to SUBMITTED
2018-04-01 20:00:19,129 INFO org.apache.hadoop.yarn.server.resourcemanager.scheduler.capacity.ParentQueue: Application added - appId: application_1522627038528_0003 user: root leaf-queue of parent: root #applications: 1
2018-04-01 20:00:19,130 INFO org.apache.hadoop.yarn.server.resourcemanager.scheduler.capacity.CapacityScheduler: Accepted application application_1522627038528_0003 from user: root, in queue: default
2018-04-01 20:00:19,130 INFO org.apache.hadoop.yarn.server.resourcemanager.rmapp.RMAppImpl: application_1522627038528_0003 State change from SUBMITTED to ACCEPTED
2018-04-01 20:00:19,130 INFO org.apache.hadoop.yarn.server.resourcemanager.ApplicationMasterService: Registering app attempt : appattempt_1522627038528_0003_000001
2018-04-01 20:00:19,130 INFO org.apache.hadoop.yarn.server.resourcemanager.rmapp.attempt.RMAppAttemptImpl: appattempt_1522627038528_0003_000001 State change from NEW to SUBMITTED
2018-04-01 20:00:19,131 WARN org.apache.hadoop.yarn.server.resourcemanager.scheduler.capacity.LeafQueue: maximum-am-resource-percent is insufficient to start a single application in queue, it is likely set too low. skipping enforcement to allow at least one application to start
2018-04-01 20:00:19,131 WARN org.apache.hadoop.yarn.server.resourcemanager.scheduler.capacity.LeafQueue: maximum-am-resource-percent is insufficient to start a single application in queue for user, it is likely set too low. skipping enforcement to allow at least one application to start
2018-04-01 20:00:19,131 INFO org.apache.hadoop.yarn.server.resourcemanager.scheduler.capacity.LeafQueue: Application application_1522627038528_0003 from user: root activated in queue: default
2018-04-01 20:00:19,131 INFO org.apache.hadoop.yarn.server.resourcemanager.scheduler.capacity.LeafQueue: Application added - appId: application_1522627038528_0003 user: org.apache.hadoop.yarn.server.resourcemanager.scheduler.capacity.LeafQueue$User@766c7a95, leaf-queue: default #user-pending-applications: 0 #user-active-applications: 1 #queue-pending-applications: 0 #queue-active-applications: 1
2018-04-01 20:00:19,131 INFO org.apache.hadoop.yarn.server.resourcemanager.scheduler.capacity.CapacityScheduler: Added Application Attempt appattempt_1522627038528_0003_000001 to scheduler from user root in queue default
2018-04-01 20:00:19,131 INFO org.apache.hadoop.yarn.server.resourcemanager.rmapp.attempt.RMAppAttemptImpl: appattempt_1522627038528_0003_000001 State change from SUBMITTED to SCHEDULED
2018-04-01 20:00:19,328 INFO org.apache.hadoop.yarn.server.resourcemanager.rmcontainer.RMContainerImpl: container_1522627038528_0003_01_000001 Container Transitioned from NEW to ALLOCATED
2018-04-01 20:00:19,328 INFO org.apache.hadoop.yarn.server.resourcemanager.RMAuditLogger: USER=root	OPERATION=AM Allocated Container	TARGET=SchedulerApp	RESULT=SUCCESS	APPID=application_1522627038528_0003	CONTAINERID=container_1522627038528_0003_01_000001
2018-04-01 20:00:19,328 INFO org.apache.hadoop.yarn.server.resourcemanager.scheduler.SchedulerNode: Assigned container container_1522627038528_0003_01_000001 of capacity <memory:2048, vCores:1> on host bd18951cf78e:36999, which has 1 containers, <memory:2048, vCores:1> used and <memory:6144, vCores:7> available after allocation
2018-04-01 20:00:19,329 INFO org.apache.hadoop.yarn.server.resourcemanager.scheduler.capacity.LeafQueue: assignedContainer application attempt=appattempt_1522627038528_0003_000001 container=Container: [ContainerId: container_1522627038528_0003_01_000001, NodeId: bd18951cf78e:36999, NodeHttpAddress: bd18951cf78e:8042, Resource: <memory:2048, vCores:1>, Priority: 0, Token: null, ] queue=default: capacity=1.0, absoluteCapacity=1.0, usedResources=<memory:0, vCores:0>, usedCapacity=0.0, absoluteUsedCapacity=0.0, numApps=1, numContainers=0 clusterResource=<memory:8192, vCores:8>
2018-04-01 20:00:19,329 INFO org.apache.hadoop.yarn.server.resourcemanager.scheduler.capacity.ParentQueue: Re-sorting assigned queue: root.default stats: default: capacity=1.0, absoluteCapacity=1.0, usedResources=<memory:2048, vCores:1>, usedCapacity=0.25, absoluteUsedCapacity=0.25, numApps=1, numContainers=1
2018-04-01 20:00:19,329 INFO org.apache.hadoop.yarn.server.resourcemanager.scheduler.capacity.ParentQueue: assignedContainer queue=root usedCapacity=0.25 absoluteUsedCapacity=0.25 used=<memory:2048, vCores:1> cluster=<memory:8192, vCores:8>
2018-04-01 20:00:19,330 INFO org.apache.hadoop.yarn.server.resourcemanager.security.NMTokenSecretManagerInRM: Sending NMToken for nodeId : bd18951cf78e:36999 for container : container_1522627038528_0003_01_000001
2018-04-01 20:00:19,333 INFO org.apache.hadoop.yarn.server.resourcemanager.rmcontainer.RMContainerImpl: container_1522627038528_0003_01_000001 Container Transitioned from ALLOCATED to ACQUIRED
2018-04-01 20:00:19,333 INFO org.apache.hadoop.yarn.server.resourcemanager.security.NMTokenSecretManagerInRM: Clear node set for appattempt_1522627038528_0003_000001
2018-04-01 20:00:19,334 INFO org.apache.hadoop.yarn.server.resourcemanager.rmapp.attempt.RMAppAttemptImpl: Storing attempt: AppId: application_1522627038528_0003 AttemptId: appattempt_1522627038528_0003_000001 MasterContainer: Container: [ContainerId: container_1522627038528_0003_01_000001, NodeId: bd18951cf78e:36999, NodeHttpAddress: bd18951cf78e:8042, Resource: <memory:2048, vCores:1>, Priority: 0, Token: Token { kind: ContainerToken, service: 172.20.0.2:36999 }, ]
2018-04-01 20:00:19,334 INFO org.apache.hadoop.yarn.server.resourcemanager.rmapp.attempt.RMAppAttemptImpl: appattempt_1522627038528_0003_000001 State change from SCHEDULED to ALLOCATED_SAVING
2018-04-01 20:00:19,334 INFO org.apache.hadoop.yarn.server.resourcemanager.rmapp.attempt.RMAppAttemptImpl: appattempt_1522627038528_0003_000001 State change from ALLOCATED_SAVING to ALLOCATED
2018-04-01 20:00:19,335 INFO org.apache.hadoop.yarn.server.resourcemanager.amlauncher.AMLauncher: Launching masterappattempt_1522627038528_0003_000001
2018-04-01 20:00:19,337 INFO org.apache.hadoop.yarn.server.resourcemanager.amlauncher.AMLauncher: Setting up container Container: [ContainerId: container_1522627038528_0003_01_000001, NodeId: bd18951cf78e:36999, NodeHttpAddress: bd18951cf78e:8042, Resource: <memory:2048, vCores:1>, Priority: 0, Token: Token { kind: ContainerToken, service: 172.20.0.2:36999 }, ] for AM appattempt_1522627038528_0003_000001
2018-04-01 20:00:19,337 INFO org.apache.hadoop.yarn.server.resourcemanager.amlauncher.AMLauncher: Command to launch container container_1522627038528_0003_01_000001 : $JAVA_HOME/bin/java -Dlog4j.configuration=container-log4j.properties -Dyarn.app.container.log.dir=<LOG_DIR> -Dyarn.app.container.log.filesize=0 -Dhadoop.root.logger=INFO,CLA -Dhadoop.root.logfile=syslog  -Xmx1024m org.apache.hadoop.mapreduce.v2.app.MRAppMaster 1><LOG_DIR>/stdout 2><LOG_DIR>/stderr 
2018-04-01 20:00:19,337 INFO org.apache.hadoop.yarn.server.resourcemanager.security.AMRMTokenSecretManager: Create AMRMToken for ApplicationAttempt: appattempt_1522627038528_0003_000001
2018-04-01 20:00:19,337 INFO org.apache.hadoop.yarn.server.resourcemanager.security.AMRMTokenSecretManager: Creating password for appattempt_1522627038528_0003_000001
2018-04-01 20:00:19,349 INFO org.apache.hadoop.yarn.server.resourcemanager.amlauncher.AMLauncher: Done launching container Container: [ContainerId: container_1522627038528_0003_01_000001, NodeId: bd18951cf78e:36999, NodeHttpAddress: bd18951cf78e:8042, Resource: <memory:2048, vCores:1>, Priority: 0, Token: Token { kind: ContainerToken, service: 172.20.0.2:36999 }, ] for AM appattempt_1522627038528_0003_000001
2018-04-01 20:00:19,349 INFO org.apache.hadoop.yarn.server.resourcemanager.rmapp.attempt.RMAppAttemptImpl: appattempt_1522627038528_0003_000001 State change from ALLOCATED to LAUNCHED
2018-04-01 20:00:20,330 INFO org.apache.hadoop.yarn.server.resourcemanager.rmcontainer.RMContainerImpl: container_1522627038528_0003_01_000001 Container Transitioned from ACQUIRED to RUNNING
2018-04-01 20:00:22,526 INFO SecurityLogger.org.apache.hadoop.ipc.Server: Auth successful for appattempt_1522627038528_0003_000001 (auth:SIMPLE)
2018-04-01 20:00:22,529 INFO org.apache.hadoop.yarn.server.resourcemanager.ApplicationMasterService: AM registration appattempt_1522627038528_0003_000001
2018-04-01 20:00:22,529 INFO org.apache.hadoop.yarn.server.resourcemanager.RMAuditLogger: USER=root	IP=172.20.0.2	OPERATION=Register App Master	TARGET=ApplicationMasterService	RESULT=SUCCESS	APPID=application_1522627038528_0003	APPATTEMPTID=appattempt_1522627038528_0003_000001
2018-04-01 20:00:22,529 INFO org.apache.hadoop.yarn.server.resourcemanager.rmapp.attempt.RMAppAttemptImpl: appattempt_1522627038528_0003_000001 State change from LAUNCHED to RUNNING
2018-04-01 20:00:22,529 INFO org.apache.hadoop.yarn.server.resourcemanager.rmapp.RMAppImpl: application_1522627038528_0003 State change from ACCEPTED to RUNNING
2018-04-01 20:00:24,341 INFO org.apache.hadoop.yarn.server.resourcemanager.rmcontainer.RMContainerImpl: container_1522627038528_0003_01_000002 Container Transitioned from NEW to ALLOCATED
2018-04-01 20:00:24,341 INFO org.apache.hadoop.yarn.server.resourcemanager.RMAuditLogger: USER=root	OPERATION=AM Allocated Container	TARGET=SchedulerApp	RESULT=SUCCESS	APPID=application_1522627038528_0003	CONTAINERID=container_1522627038528_0003_01_000002
2018-04-01 20:00:24,342 INFO org.apache.hadoop.yarn.server.resourcemanager.scheduler.SchedulerNode: Assigned container container_1522627038528_0003_01_000002 of capacity <memory:1024, vCores:1> on host bd18951cf78e:36999, which has 2 containers, <memory:3072, vCores:2> used and <memory:5120, vCores:6> available after allocation
2018-04-01 20:00:24,342 INFO org.apache.hadoop.yarn.server.resourcemanager.scheduler.capacity.LeafQueue: assignedContainer application attempt=appattempt_1522627038528_0003_000001 container=Container: [ContainerId: container_1522627038528_0003_01_000002, NodeId: bd18951cf78e:36999, NodeHttpAddress: bd18951cf78e:8042, Resource: <memory:1024, vCores:1>, Priority: 20, Token: null, ] queue=default: capacity=1.0, absoluteCapacity=1.0, usedResources=<memory:2048, vCores:1>, usedCapacity=0.25, absoluteUsedCapacity=0.25, numApps=1, numContainers=1 clusterResource=<memory:8192, vCores:8>
2018-04-01 20:00:24,342 INFO org.apache.hadoop.yarn.server.resourcemanager.scheduler.capacity.ParentQueue: Re-sorting assigned queue: root.default stats: default: capacity=1.0, absoluteCapacity=1.0, usedResources=<memory:3072, vCores:2>, usedCapacity=0.375, absoluteUsedCapacity=0.375, numApps=1, numContainers=2
2018-04-01 20:00:24,342 INFO org.apache.hadoop.yarn.server.resourcemanager.scheduler.capacity.ParentQueue: assignedContainer queue=root usedCapacity=0.375 absoluteUsedCapacity=0.375 used=<memory:3072, vCores:2> cluster=<memory:8192, vCores:8>
2018-04-01 20:00:24,585 INFO org.apache.hadoop.yarn.server.resourcemanager.security.NMTokenSecretManagerInRM: Sending NMToken for nodeId : bd18951cf78e:36999 for container : container_1522627038528_0003_01_000002
2018-04-01 20:00:24,587 INFO org.apache.hadoop.yarn.server.resourcemanager.rmcontainer.RMContainerImpl: container_1522627038528_0003_01_000002 Container Transitioned from ALLOCATED to ACQUIRED
2018-04-01 20:00:25,341 INFO org.apache.hadoop.yarn.server.resourcemanager.rmcontainer.RMContainerImpl: container_1522627038528_0003_01_000002 Container Transitioned from ACQUIRED to RUNNING
2018-04-01 20:00:25,600 INFO org.apache.hadoop.yarn.server.resourcemanager.scheduler.AppSchedulingInfo: checking for deactivate of application :application_1522627038528_0003
2018-04-01 20:00:49,029 INFO org.apache.hadoop.yarn.server.resourcemanager.rmcontainer.RMContainerImpl: container_1522627038528_0003_01_000002 Container Transitioned from RUNNING to COMPLETED
2018-04-01 20:00:49,029 INFO org.apache.hadoop.yarn.server.resourcemanager.scheduler.common.fica.FiCaSchedulerApp: Completed container: container_1522627038528_0003_01_000002 in state: COMPLETED event:FINISHED
2018-04-01 20:00:49,029 INFO org.apache.hadoop.yarn.server.resourcemanager.RMAuditLogger: USER=root	OPERATION=AM Released Container	TARGET=SchedulerApp	RESULT=SUCCESS	APPID=application_1522627038528_0003	CONTAINERID=container_1522627038528_0003_01_000002
2018-04-01 20:00:49,029 INFO org.apache.hadoop.yarn.server.resourcemanager.scheduler.SchedulerNode: Released container container_1522627038528_0003_01_000002 of capacity <memory:1024, vCores:1> on host bd18951cf78e:36999, which currently has 1 containers, <memory:2048, vCores:1> used and <memory:6144, vCores:7> available, release resources=true
2018-04-01 20:00:49,029 INFO org.apache.hadoop.yarn.server.resourcemanager.scheduler.capacity.LeafQueue: default used=<memory:2048, vCores:1> numContainers=1 user=root user-resources=<memory:2048, vCores:1>
2018-04-01 20:00:49,030 INFO org.apache.hadoop.yarn.server.resourcemanager.scheduler.capacity.LeafQueue: completedContainer container=Container: [ContainerId: container_1522627038528_0003_01_000002, NodeId: bd18951cf78e:36999, NodeHttpAddress: bd18951cf78e:8042, Resource: <memory:1024, vCores:1>, Priority: 20, Token: Token { kind: ContainerToken, service: 172.20.0.2:36999 }, ] queue=default: capacity=1.0, absoluteCapacity=1.0, usedResources=<memory:2048, vCores:1>, usedCapacity=0.25, absoluteUsedCapacity=0.25, numApps=1, numContainers=1 cluster=<memory:8192, vCores:8>
2018-04-01 20:00:49,030 INFO org.apache.hadoop.yarn.server.resourcemanager.scheduler.capacity.ParentQueue: completedContainer queue=root usedCapacity=0.25 absoluteUsedCapacity=0.25 used=<memory:2048, vCores:1> cluster=<memory:8192, vCores:8>
2018-04-01 20:00:49,030 INFO org.apache.hadoop.yarn.server.resourcemanager.scheduler.capacity.ParentQueue: Re-sorting completed queue: root.default stats: default: capacity=1.0, absoluteCapacity=1.0, usedResources=<memory:2048, vCores:1>, usedCapacity=0.25, absoluteUsedCapacity=0.25, numApps=1, numContainers=1
2018-04-01 20:00:49,030 INFO org.apache.hadoop.yarn.server.resourcemanager.scheduler.capacity.CapacityScheduler: Application attempt appattempt_1522627038528_0003_000001 released container container_1522627038528_0003_01_000002 on node: host: bd18951cf78e:36999 #containers=1 available=<memory:6144, vCores:7> used=<memory:2048, vCores:1> with event: FINISHED
2018-04-01 20:00:50,031 INFO org.apache.hadoop.yarn.server.resourcemanager.rmcontainer.RMContainerImpl: container_1522627038528_0003_01_000003 Container Transitioned from NEW to ALLOCATED
2018-04-01 20:00:50,031 INFO org.apache.hadoop.yarn.server.resourcemanager.RMAuditLogger: USER=root	OPERATION=AM Allocated Container	TARGET=SchedulerApp	RESULT=SUCCESS	APPID=application_1522627038528_0003	CONTAINERID=container_1522627038528_0003_01_000003
2018-04-01 20:00:50,031 INFO org.apache.hadoop.yarn.server.resourcemanager.scheduler.SchedulerNode: Assigned container container_1522627038528_0003_01_000003 of capacity <memory:1024, vCores:1> on host bd18951cf78e:36999, which has 2 containers, <memory:3072, vCores:2> used and <memory:5120, vCores:6> available after allocation
2018-04-01 20:00:50,032 INFO org.apache.hadoop.yarn.server.resourcemanager.scheduler.capacity.LeafQueue: assignedContainer application attempt=appattempt_1522627038528_0003_000001 container=Container: [ContainerId: container_1522627038528_0003_01_000003, NodeId: bd18951cf78e:36999, NodeHttpAddress: bd18951cf78e:8042, Resource: <memory:1024, vCores:1>, Priority: 10, Token: null, ] queue=default: capacity=1.0, absoluteCapacity=1.0, usedResources=<memory:2048, vCores:1>, usedCapacity=0.25, absoluteUsedCapacity=0.25, numApps=1, numContainers=1 clusterResource=<memory:8192, vCores:8>
2018-04-01 20:00:50,032 INFO org.apache.hadoop.yarn.server.resourcemanager.scheduler.capacity.ParentQueue: Re-sorting assigned queue: root.default stats: default: capacity=1.0, absoluteCapacity=1.0, usedResources=<memory:3072, vCores:2>, usedCapacity=0.375, absoluteUsedCapacity=0.375, numApps=1, numContainers=2
2018-04-01 20:00:50,032 INFO org.apache.hadoop.yarn.server.resourcemanager.scheduler.capacity.ParentQueue: assignedContainer queue=root usedCapacity=0.375 absoluteUsedCapacity=0.375 used=<memory:3072, vCores:2> cluster=<memory:8192, vCores:8>
2018-04-01 20:00:50,670 INFO org.apache.hadoop.yarn.server.resourcemanager.rmcontainer.RMContainerImpl: container_1522627038528_0003_01_000003 Container Transitioned from ALLOCATED to ACQUIRED
2018-04-01 20:00:51,032 INFO org.apache.hadoop.yarn.server.resourcemanager.rmcontainer.RMContainerImpl: container_1522627038528_0003_01_000003 Container Transitioned from ACQUIRED to RUNNING
2018-04-01 20:00:51,673 INFO org.apache.hadoop.yarn.server.resourcemanager.scheduler.AppSchedulingInfo: checking for deactivate of application :application_1522627038528_0003
2018-04-01 20:01:03,214 INFO org.apache.hadoop.yarn.server.resourcemanager.rmapp.attempt.RMAppAttemptImpl: Updating application attempt appattempt_1522627038528_0003_000001 with final state: FINISHING, and exit status: -1000
2018-04-01 20:01:03,214 INFO org.apache.hadoop.yarn.server.resourcemanager.rmapp.attempt.RMAppAttemptImpl: appattempt_1522627038528_0003_000001 State change from RUNNING to FINAL_SAVING
2018-04-01 20:01:03,214 INFO org.apache.hadoop.yarn.server.resourcemanager.rmapp.RMAppImpl: Updating application application_1522627038528_0003 with final state: FINISHING
2018-04-01 20:01:03,214 INFO org.apache.hadoop.yarn.server.resourcemanager.rmapp.RMAppImpl: application_1522627038528_0003 State change from RUNNING to FINAL_SAVING
2018-04-01 20:01:03,214 INFO org.apache.hadoop.yarn.server.resourcemanager.recovery.RMStateStore: Updating info for app: application_1522627038528_0003
2018-04-01 20:01:03,214 INFO org.apache.hadoop.yarn.server.resourcemanager.rmapp.attempt.RMAppAttemptImpl: appattempt_1522627038528_0003_000001 State change from FINAL_SAVING to FINISHING
2018-04-01 20:01:03,214 INFO org.apache.hadoop.yarn.server.resourcemanager.rmapp.RMAppImpl: application_1522627038528_0003 State change from FINAL_SAVING to FINISHING
2018-04-01 20:01:04,008 INFO org.apache.hadoop.yarn.server.resourcemanager.rmcontainer.RMContainerImpl: container_1522627038528_0003_01_000003 Container Transitioned from RUNNING to COMPLETED
2018-04-01 20:01:04,009 INFO org.apache.hadoop.yarn.server.resourcemanager.scheduler.common.fica.FiCaSchedulerApp: Completed container: container_1522627038528_0003_01_000003 in state: COMPLETED event:FINISHED
2018-04-01 20:01:04,009 INFO org.apache.hadoop.yarn.server.resourcemanager.RMAuditLogger: USER=root	OPERATION=AM Released Container	TARGET=SchedulerApp	RESULT=SUCCESS	APPID=application_1522627038528_0003	CONTAINERID=container_1522627038528_0003_01_000003
2018-04-01 20:01:04,009 INFO org.apache.hadoop.yarn.server.resourcemanager.scheduler.SchedulerNode: Released container container_1522627038528_0003_01_000003 of capacity <memory:1024, vCores:1> on host bd18951cf78e:36999, which currently has 1 containers, <memory:2048, vCores:1> used and <memory:6144, vCores:7> available, release resources=true
2018-04-01 20:01:04,010 INFO org.apache.hadoop.yarn.server.resourcemanager.scheduler.capacity.LeafQueue: default used=<memory:2048, vCores:1> numContainers=1 user=root user-resources=<memory:2048, vCores:1>
2018-04-01 20:01:04,011 INFO org.apache.hadoop.yarn.server.resourcemanager.scheduler.capacity.LeafQueue: completedContainer container=Container: [ContainerId: container_1522627038528_0003_01_000003, NodeId: bd18951cf78e:36999, NodeHttpAddress: bd18951cf78e:8042, Resource: <memory:1024, vCores:1>, Priority: 10, Token: Token { kind: ContainerToken, service: 172.20.0.2:36999 }, ] queue=default: capacity=1.0, absoluteCapacity=1.0, usedResources=<memory:2048, vCores:1>, usedCapacity=0.25, absoluteUsedCapacity=0.25, numApps=1, numContainers=1 cluster=<memory:8192, vCores:8>
2018-04-01 20:01:04,011 INFO org.apache.hadoop.yarn.server.resourcemanager.scheduler.capacity.ParentQueue: completedContainer queue=root usedCapacity=0.25 absoluteUsedCapacity=0.25 used=<memory:2048, vCores:1> cluster=<memory:8192, vCores:8>
2018-04-01 20:01:04,011 INFO org.apache.hadoop.yarn.server.resourcemanager.scheduler.capacity.ParentQueue: Re-sorting completed queue: root.default stats: default: capacity=1.0, absoluteCapacity=1.0, usedResources=<memory:2048, vCores:1>, usedCapacity=0.25, absoluteUsedCapacity=0.25, numApps=1, numContainers=1
2018-04-01 20:01:04,012 INFO org.apache.hadoop.yarn.server.resourcemanager.scheduler.capacity.CapacityScheduler: Application attempt appattempt_1522627038528_0003_000001 released container container_1522627038528_0003_01_000003 on node: host: bd18951cf78e:36999 #containers=1 available=<memory:6144, vCores:7> used=<memory:2048, vCores:1> with event: FINISHED
2018-04-01 20:01:04,217 INFO org.apache.hadoop.yarn.server.resourcemanager.ApplicationMasterService: application_1522627038528_0003 unregistered successfully. 
2018-04-01 20:01:10,027 INFO org.apache.hadoop.yarn.server.resourcemanager.rmcontainer.RMContainerImpl: container_1522627038528_0003_01_000001 Container Transitioned from RUNNING to COMPLETED
2018-04-01 20:01:10,027 INFO org.apache.hadoop.yarn.server.resourcemanager.ApplicationMasterService: Unregistering app attempt : appattempt_1522627038528_0003_000001
2018-04-01 20:01:10,027 INFO org.apache.hadoop.yarn.server.resourcemanager.scheduler.common.fica.FiCaSchedulerApp: Completed container: container_1522627038528_0003_01_000001 in state: COMPLETED event:FINISHED
2018-04-01 20:01:10,027 INFO org.apache.hadoop.yarn.server.resourcemanager.security.AMRMTokenSecretManager: Application finished, removing password for appattempt_1522627038528_0003_000001
2018-04-01 20:01:10,027 INFO org.apache.hadoop.yarn.server.resourcemanager.RMAuditLogger: USER=root	OPERATION=AM Released Container	TARGET=SchedulerApp	RESULT=SUCCESS	APPID=application_1522627038528_0003	CONTAINERID=container_1522627038528_0003_01_000001
2018-04-01 20:01:10,028 INFO org.apache.hadoop.yarn.server.resourcemanager.rmapp.attempt.RMAppAttemptImpl: appattempt_1522627038528_0003_000001 State change from FINISHING to FINISHED
2018-04-01 20:01:10,028 INFO org.apache.hadoop.yarn.server.resourcemanager.scheduler.SchedulerNode: Released container container_1522627038528_0003_01_000001 of capacity <memory:2048, vCores:1> on host bd18951cf78e:36999, which currently has 0 containers, <memory:0, vCores:0> used and <memory:8192, vCores:8> available, release resources=true
2018-04-01 20:01:10,028 INFO org.apache.hadoop.yarn.server.resourcemanager.rmapp.RMAppImpl: application_1522627038528_0003 State change from FINISHING to FINISHED
2018-04-01 20:01:10,028 INFO org.apache.hadoop.yarn.server.resourcemanager.scheduler.capacity.LeafQueue: default used=<memory:0, vCores:0> numContainers=0 user=root user-resources=<memory:0, vCores:0>
2018-04-01 20:01:10,028 INFO org.apache.hadoop.yarn.server.resourcemanager.RMAuditLogger: USER=root	OPERATION=Application Finished - Succeeded	TARGET=RMAppManager	RESULT=SUCCESS	APPID=application_1522627038528_0003
2018-04-01 20:01:10,029 INFO org.apache.hadoop.yarn.server.resourcemanager.scheduler.capacity.LeafQueue: completedContainer container=Container: [ContainerId: container_1522627038528_0003_01_000001, NodeId: bd18951cf78e:36999, NodeHttpAddress: bd18951cf78e:8042, Resource: <memory:2048, vCores:1>, Priority: 0, Token: Token { kind: ContainerToken, service: 172.20.0.2:36999 }, ] queue=default: capacity=1.0, absoluteCapacity=1.0, usedResources=<memory:0, vCores:0>, usedCapacity=0.0, absoluteUsedCapacity=0.0, numApps=1, numContainers=0 cluster=<memory:8192, vCores:8>
2018-04-01 20:01:10,029 INFO org.apache.hadoop.yarn.server.resourcemanager.scheduler.capacity.ParentQueue: completedContainer queue=root usedCapacity=0.0 absoluteUsedCapacity=0.0 used=<memory:0, vCores:0> cluster=<memory:8192, vCores:8>
2018-04-01 20:01:10,029 INFO org.apache.hadoop.yarn.server.resourcemanager.amlauncher.AMLauncher: Cleaning master appattempt_1522627038528_0003_000001
2018-04-01 20:01:10,029 INFO org.apache.hadoop.yarn.server.resourcemanager.scheduler.capacity.ParentQueue: Re-sorting completed queue: root.default stats: default: capacity=1.0, absoluteCapacity=1.0, usedResources=<memory:0, vCores:0>, usedCapacity=0.0, absoluteUsedCapacity=0.0, numApps=1, numContainers=0
2018-04-01 20:01:10,030 INFO org.apache.hadoop.yarn.server.resourcemanager.scheduler.capacity.CapacityScheduler: Application attempt appattempt_1522627038528_0003_000001 released container container_1522627038528_0003_01_000001 on node: host: bd18951cf78e:36999 #containers=0 available=<memory:8192, vCores:8> used=<memory:0, vCores:0> with event: FINISHED
2018-04-01 20:01:10,030 INFO org.apache.hadoop.yarn.server.resourcemanager.scheduler.capacity.CapacityScheduler: Application Attempt appattempt_1522627038528_0003_000001 is done. finalState=FINISHED
2018-04-01 20:01:10,030 INFO org.apache.hadoop.yarn.server.resourcemanager.RMAppManager$ApplicationSummary: appId=application_1522627038528_0003,name=streamjob4837149805089805222.jar,user=root,queue=default,state=FINISHED,trackingUrl=http://bd18951cf78e:8088/proxy/application_1522627038528_0003/,appMasterHost=bd18951cf78e,startTime=1522627219128,finishTime=1522627263214,finalStatus=SUCCEEDED,memorySeconds=143422,vcoreSeconds=87,preemptedAMContainers=0,preemptedNonAMContainers=0,preemptedResources=<memory:0\, vCores:0>,applicationType=MAPREDUCE
2018-04-01 20:01:10,030 INFO org.apache.hadoop.yarn.server.resourcemanager.scheduler.AppSchedulingInfo: Application application_1522627038528_0003 requests cleared
2018-04-01 20:01:10,031 INFO org.apache.hadoop.yarn.server.resourcemanager.scheduler.capacity.LeafQueue: Application removed - appId: application_1522627038528_0003 user: root queue: default #user-pending-applications: 0 #user-active-applications: 0 #queue-pending-applications: 0 #queue-active-applications: 0
2018-04-01 20:01:10,031 INFO org.apache.hadoop.yarn.server.resourcemanager.scheduler.capacity.ParentQueue: Application removed - appId: application_1522627038528_0003 user: root leaf-queue of parent: root #applications: 0
2018-04-01 20:01:11,047 INFO org.apache.hadoop.yarn.server.resourcemanager.scheduler.capacity.CapacityScheduler: Null container completed...
2018-04-01 20:01:35,195 INFO org.apache.hadoop.yarn.server.resourcemanager.ClientRMService: Allocated new applicationId: 4
2018-04-01 20:01:35,894 INFO org.apache.hadoop.yarn.server.resourcemanager.ClientRMService: Application with id 4 submitted by user root
2018-04-01 20:01:35,895 INFO org.apache.hadoop.yarn.server.resourcemanager.rmapp.RMAppImpl: Storing application with id application_1522627038528_0004
2018-04-01 20:01:35,895 INFO org.apache.hadoop.yarn.server.resourcemanager.RMAuditLogger: USER=root	IP=172.20.0.2	OPERATION=Submit Application Request	TARGET=ClientRMService	RESULT=SUCCESS	APPID=application_1522627038528_0004
2018-04-01 20:01:35,895 INFO org.apache.hadoop.yarn.server.resourcemanager.rmapp.RMAppImpl: application_1522627038528_0004 State change from NEW to NEW_SAVING
2018-04-01 20:01:35,895 INFO org.apache.hadoop.yarn.server.resourcemanager.recovery.RMStateStore: Storing info for app: application_1522627038528_0004
2018-04-01 20:01:35,895 INFO org.apache.hadoop.yarn.server.resourcemanager.rmapp.RMAppImpl: application_1522627038528_0004 State change from NEW_SAVING to SUBMITTED
2018-04-01 20:01:35,895 INFO org.apache.hadoop.yarn.server.resourcemanager.scheduler.capacity.ParentQueue: Application added - appId: application_1522627038528_0004 user: root leaf-queue of parent: root #applications: 1
2018-04-01 20:01:35,896 INFO org.apache.hadoop.yarn.server.resourcemanager.scheduler.capacity.CapacityScheduler: Accepted application application_1522627038528_0004 from user: root, in queue: default
2018-04-01 20:01:35,896 INFO org.apache.hadoop.yarn.server.resourcemanager.rmapp.RMAppImpl: application_1522627038528_0004 State change from SUBMITTED to ACCEPTED
2018-04-01 20:01:35,896 INFO org.apache.hadoop.yarn.server.resourcemanager.ApplicationMasterService: Registering app attempt : appattempt_1522627038528_0004_000001
2018-04-01 20:01:35,896 INFO org.apache.hadoop.yarn.server.resourcemanager.rmapp.attempt.RMAppAttemptImpl: appattempt_1522627038528_0004_000001 State change from NEW to SUBMITTED
2018-04-01 20:01:35,897 WARN org.apache.hadoop.yarn.server.resourcemanager.scheduler.capacity.LeafQueue: maximum-am-resource-percent is insufficient to start a single application in queue, it is likely set too low. skipping enforcement to allow at least one application to start
2018-04-01 20:01:35,897 WARN org.apache.hadoop.yarn.server.resourcemanager.scheduler.capacity.LeafQueue: maximum-am-resource-percent is insufficient to start a single application in queue for user, it is likely set too low. skipping enforcement to allow at least one application to start
2018-04-01 20:01:35,897 INFO org.apache.hadoop.yarn.server.resourcemanager.scheduler.capacity.LeafQueue: Application application_1522627038528_0004 from user: root activated in queue: default
2018-04-01 20:01:35,897 INFO org.apache.hadoop.yarn.server.resourcemanager.scheduler.capacity.LeafQueue: Application added - appId: application_1522627038528_0004 user: org.apache.hadoop.yarn.server.resourcemanager.scheduler.capacity.LeafQueue$User@18c06ea2, leaf-queue: default #user-pending-applications: 0 #user-active-applications: 1 #queue-pending-applications: 0 #queue-active-applications: 1
2018-04-01 20:01:35,897 INFO org.apache.hadoop.yarn.server.resourcemanager.scheduler.capacity.CapacityScheduler: Added Application Attempt appattempt_1522627038528_0004_000001 to scheduler from user root in queue default
2018-04-01 20:01:35,897 INFO org.apache.hadoop.yarn.server.resourcemanager.rmapp.attempt.RMAppAttemptImpl: appattempt_1522627038528_0004_000001 State change from SUBMITTED to SCHEDULED
2018-04-01 20:01:36,110 INFO org.apache.hadoop.yarn.server.resourcemanager.rmcontainer.RMContainerImpl: container_1522627038528_0004_01_000001 Container Transitioned from NEW to ALLOCATED
2018-04-01 20:01:36,111 INFO org.apache.hadoop.yarn.server.resourcemanager.RMAuditLogger: USER=root	OPERATION=AM Allocated Container	TARGET=SchedulerApp	RESULT=SUCCESS	APPID=application_1522627038528_0004	CONTAINERID=container_1522627038528_0004_01_000001
2018-04-01 20:01:36,111 INFO org.apache.hadoop.yarn.server.resourcemanager.scheduler.SchedulerNode: Assigned container container_1522627038528_0004_01_000001 of capacity <memory:2048, vCores:1> on host bd18951cf78e:36999, which has 1 containers, <memory:2048, vCores:1> used and <memory:6144, vCores:7> available after allocation
2018-04-01 20:01:36,111 INFO org.apache.hadoop.yarn.server.resourcemanager.scheduler.capacity.LeafQueue: assignedContainer application attempt=appattempt_1522627038528_0004_000001 container=Container: [ContainerId: container_1522627038528_0004_01_000001, NodeId: bd18951cf78e:36999, NodeHttpAddress: bd18951cf78e:8042, Resource: <memory:2048, vCores:1>, Priority: 0, Token: null, ] queue=default: capacity=1.0, absoluteCapacity=1.0, usedResources=<memory:0, vCores:0>, usedCapacity=0.0, absoluteUsedCapacity=0.0, numApps=1, numContainers=0 clusterResource=<memory:8192, vCores:8>
2018-04-01 20:01:36,111 INFO org.apache.hadoop.yarn.server.resourcemanager.scheduler.capacity.ParentQueue: Re-sorting assigned queue: root.default stats: default: capacity=1.0, absoluteCapacity=1.0, usedResources=<memory:2048, vCores:1>, usedCapacity=0.25, absoluteUsedCapacity=0.25, numApps=1, numContainers=1
2018-04-01 20:01:36,111 INFO org.apache.hadoop.yarn.server.resourcemanager.scheduler.capacity.ParentQueue: assignedContainer queue=root usedCapacity=0.25 absoluteUsedCapacity=0.25 used=<memory:2048, vCores:1> cluster=<memory:8192, vCores:8>
2018-04-01 20:01:36,112 INFO org.apache.hadoop.yarn.server.resourcemanager.security.NMTokenSecretManagerInRM: Sending NMToken for nodeId : bd18951cf78e:36999 for container : container_1522627038528_0004_01_000001
2018-04-01 20:01:36,113 INFO org.apache.hadoop.yarn.server.resourcemanager.rmcontainer.RMContainerImpl: container_1522627038528_0004_01_000001 Container Transitioned from ALLOCATED to ACQUIRED
2018-04-01 20:01:36,113 INFO org.apache.hadoop.yarn.server.resourcemanager.security.NMTokenSecretManagerInRM: Clear node set for appattempt_1522627038528_0004_000001
2018-04-01 20:01:36,113 INFO org.apache.hadoop.yarn.server.resourcemanager.rmapp.attempt.RMAppAttemptImpl: Storing attempt: AppId: application_1522627038528_0004 AttemptId: appattempt_1522627038528_0004_000001 MasterContainer: Container: [ContainerId: container_1522627038528_0004_01_000001, NodeId: bd18951cf78e:36999, NodeHttpAddress: bd18951cf78e:8042, Resource: <memory:2048, vCores:1>, Priority: 0, Token: Token { kind: ContainerToken, service: 172.20.0.2:36999 }, ]
2018-04-01 20:01:36,113 INFO org.apache.hadoop.yarn.server.resourcemanager.rmapp.attempt.RMAppAttemptImpl: appattempt_1522627038528_0004_000001 State change from SCHEDULED to ALLOCATED_SAVING
2018-04-01 20:01:36,113 INFO org.apache.hadoop.yarn.server.resourcemanager.rmapp.attempt.RMAppAttemptImpl: appattempt_1522627038528_0004_000001 State change from ALLOCATED_SAVING to ALLOCATED
2018-04-01 20:01:36,114 INFO org.apache.hadoop.yarn.server.resourcemanager.amlauncher.AMLauncher: Launching masterappattempt_1522627038528_0004_000001
2018-04-01 20:01:36,115 INFO org.apache.hadoop.yarn.server.resourcemanager.amlauncher.AMLauncher: Setting up container Container: [ContainerId: container_1522627038528_0004_01_000001, NodeId: bd18951cf78e:36999, NodeHttpAddress: bd18951cf78e:8042, Resource: <memory:2048, vCores:1>, Priority: 0, Token: Token { kind: ContainerToken, service: 172.20.0.2:36999 }, ] for AM appattempt_1522627038528_0004_000001
2018-04-01 20:01:36,115 INFO org.apache.hadoop.yarn.server.resourcemanager.amlauncher.AMLauncher: Command to launch container container_1522627038528_0004_01_000001 : $JAVA_HOME/bin/java -Dlog4j.configuration=container-log4j.properties -Dyarn.app.container.log.dir=<LOG_DIR> -Dyarn.app.container.log.filesize=0 -Dhadoop.root.logger=INFO,CLA -Dhadoop.root.logfile=syslog  -Xmx1024m org.apache.hadoop.mapreduce.v2.app.MRAppMaster 1><LOG_DIR>/stdout 2><LOG_DIR>/stderr 
2018-04-01 20:01:36,116 INFO org.apache.hadoop.yarn.server.resourcemanager.security.AMRMTokenSecretManager: Create AMRMToken for ApplicationAttempt: appattempt_1522627038528_0004_000001
2018-04-01 20:01:36,116 INFO org.apache.hadoop.yarn.server.resourcemanager.security.AMRMTokenSecretManager: Creating password for appattempt_1522627038528_0004_000001
2018-04-01 20:01:36,125 INFO org.apache.hadoop.yarn.server.resourcemanager.amlauncher.AMLauncher: Done launching container Container: [ContainerId: container_1522627038528_0004_01_000001, NodeId: bd18951cf78e:36999, NodeHttpAddress: bd18951cf78e:8042, Resource: <memory:2048, vCores:1>, Priority: 0, Token: Token { kind: ContainerToken, service: 172.20.0.2:36999 }, ] for AM appattempt_1522627038528_0004_000001
2018-04-01 20:01:36,125 INFO org.apache.hadoop.yarn.server.resourcemanager.rmapp.attempt.RMAppAttemptImpl: appattempt_1522627038528_0004_000001 State change from ALLOCATED to LAUNCHED
2018-04-01 20:01:37,112 INFO org.apache.hadoop.yarn.server.resourcemanager.rmcontainer.RMContainerImpl: container_1522627038528_0004_01_000001 Container Transitioned from ACQUIRED to RUNNING
2018-04-01 20:01:39,149 INFO SecurityLogger.org.apache.hadoop.ipc.Server: Auth successful for appattempt_1522627038528_0004_000001 (auth:SIMPLE)
2018-04-01 20:01:39,152 INFO org.apache.hadoop.yarn.server.resourcemanager.ApplicationMasterService: AM registration appattempt_1522627038528_0004_000001
2018-04-01 20:01:39,152 INFO org.apache.hadoop.yarn.server.resourcemanager.RMAuditLogger: USER=root	IP=172.20.0.2	OPERATION=Register App Master	TARGET=ApplicationMasterService	RESULT=SUCCESS	APPID=application_1522627038528_0004	APPATTEMPTID=appattempt_1522627038528_0004_000001
2018-04-01 20:01:39,152 INFO org.apache.hadoop.yarn.server.resourcemanager.rmapp.attempt.RMAppAttemptImpl: appattempt_1522627038528_0004_000001 State change from LAUNCHED to RUNNING
2018-04-01 20:01:39,152 INFO org.apache.hadoop.yarn.server.resourcemanager.rmapp.RMAppImpl: application_1522627038528_0004 State change from ACCEPTED to RUNNING
2018-04-01 20:01:41,124 INFO org.apache.hadoop.yarn.server.resourcemanager.rmcontainer.RMContainerImpl: container_1522627038528_0004_01_000002 Container Transitioned from NEW to ALLOCATED
2018-04-01 20:01:41,124 INFO org.apache.hadoop.yarn.server.resourcemanager.RMAuditLogger: USER=root	OPERATION=AM Allocated Container	TARGET=SchedulerApp	RESULT=SUCCESS	APPID=application_1522627038528_0004	CONTAINERID=container_1522627038528_0004_01_000002
2018-04-01 20:01:41,124 INFO org.apache.hadoop.yarn.server.resourcemanager.scheduler.SchedulerNode: Assigned container container_1522627038528_0004_01_000002 of capacity <memory:1024, vCores:1> on host bd18951cf78e:36999, which has 2 containers, <memory:3072, vCores:2> used and <memory:5120, vCores:6> available after allocation
2018-04-01 20:01:41,125 INFO org.apache.hadoop.yarn.server.resourcemanager.scheduler.capacity.LeafQueue: assignedContainer application attempt=appattempt_1522627038528_0004_000001 container=Container: [ContainerId: container_1522627038528_0004_01_000002, NodeId: bd18951cf78e:36999, NodeHttpAddress: bd18951cf78e:8042, Resource: <memory:1024, vCores:1>, Priority: 20, Token: null, ] queue=default: capacity=1.0, absoluteCapacity=1.0, usedResources=<memory:2048, vCores:1>, usedCapacity=0.25, absoluteUsedCapacity=0.25, numApps=1, numContainers=1 clusterResource=<memory:8192, vCores:8>
2018-04-01 20:01:41,125 INFO org.apache.hadoop.yarn.server.resourcemanager.scheduler.capacity.ParentQueue: Re-sorting assigned queue: root.default stats: default: capacity=1.0, absoluteCapacity=1.0, usedResources=<memory:3072, vCores:2>, usedCapacity=0.375, absoluteUsedCapacity=0.375, numApps=1, numContainers=2
2018-04-01 20:01:41,125 INFO org.apache.hadoop.yarn.server.resourcemanager.scheduler.capacity.ParentQueue: assignedContainer queue=root usedCapacity=0.375 absoluteUsedCapacity=0.375 used=<memory:3072, vCores:2> cluster=<memory:8192, vCores:8>
2018-04-01 20:01:41,201 INFO org.apache.hadoop.yarn.server.resourcemanager.security.NMTokenSecretManagerInRM: Sending NMToken for nodeId : bd18951cf78e:36999 for container : container_1522627038528_0004_01_000002
2018-04-01 20:01:41,203 INFO org.apache.hadoop.yarn.server.resourcemanager.rmcontainer.RMContainerImpl: container_1522627038528_0004_01_000002 Container Transitioned from ALLOCATED to ACQUIRED
2018-04-01 20:01:42,124 INFO org.apache.hadoop.yarn.server.resourcemanager.rmcontainer.RMContainerImpl: container_1522627038528_0004_01_000002 Container Transitioned from ACQUIRED to RUNNING
2018-04-01 20:01:42,218 INFO org.apache.hadoop.yarn.server.resourcemanager.scheduler.AppSchedulingInfo: checking for deactivate of application :application_1522627038528_0004
2018-04-01 20:02:00,175 INFO org.apache.hadoop.yarn.server.resourcemanager.rmcontainer.RMContainerImpl: container_1522627038528_0004_01_000002 Container Transitioned from RUNNING to COMPLETED
2018-04-01 20:02:00,175 INFO org.apache.hadoop.yarn.server.resourcemanager.scheduler.common.fica.FiCaSchedulerApp: Completed container: container_1522627038528_0004_01_000002 in state: COMPLETED event:FINISHED
2018-04-01 20:02:00,175 INFO org.apache.hadoop.yarn.server.resourcemanager.RMAuditLogger: USER=root	OPERATION=AM Released Container	TARGET=SchedulerApp	RESULT=SUCCESS	APPID=application_1522627038528_0004	CONTAINERID=container_1522627038528_0004_01_000002
2018-04-01 20:02:00,175 INFO org.apache.hadoop.yarn.server.resourcemanager.scheduler.SchedulerNode: Released container container_1522627038528_0004_01_000002 of capacity <memory:1024, vCores:1> on host bd18951cf78e:36999, which currently has 1 containers, <memory:2048, vCores:1> used and <memory:6144, vCores:7> available, release resources=true
2018-04-01 20:02:00,175 INFO org.apache.hadoop.yarn.server.resourcemanager.scheduler.capacity.LeafQueue: default used=<memory:2048, vCores:1> numContainers=1 user=root user-resources=<memory:2048, vCores:1>
2018-04-01 20:02:00,176 INFO org.apache.hadoop.yarn.server.resourcemanager.scheduler.capacity.LeafQueue: completedContainer container=Container: [ContainerId: container_1522627038528_0004_01_000002, NodeId: bd18951cf78e:36999, NodeHttpAddress: bd18951cf78e:8042, Resource: <memory:1024, vCores:1>, Priority: 20, Token: Token { kind: ContainerToken, service: 172.20.0.2:36999 }, ] queue=default: capacity=1.0, absoluteCapacity=1.0, usedResources=<memory:2048, vCores:1>, usedCapacity=0.25, absoluteUsedCapacity=0.25, numApps=1, numContainers=1 cluster=<memory:8192, vCores:8>
2018-04-01 20:02:00,176 INFO org.apache.hadoop.yarn.server.resourcemanager.scheduler.capacity.ParentQueue: completedContainer queue=root usedCapacity=0.25 absoluteUsedCapacity=0.25 used=<memory:2048, vCores:1> cluster=<memory:8192, vCores:8>
2018-04-01 20:02:00,176 INFO org.apache.hadoop.yarn.server.resourcemanager.scheduler.capacity.ParentQueue: Re-sorting completed queue: root.default stats: default: capacity=1.0, absoluteCapacity=1.0, usedResources=<memory:2048, vCores:1>, usedCapacity=0.25, absoluteUsedCapacity=0.25, numApps=1, numContainers=1
2018-04-01 20:02:00,176 INFO org.apache.hadoop.yarn.server.resourcemanager.scheduler.capacity.CapacityScheduler: Application attempt appattempt_1522627038528_0004_000001 released container container_1522627038528_0004_01_000002 on node: host: bd18951cf78e:36999 #containers=1 available=<memory:6144, vCores:7> used=<memory:2048, vCores:1> with event: FINISHED
2018-04-01 20:02:01,177 INFO org.apache.hadoop.yarn.server.resourcemanager.rmcontainer.RMContainerImpl: container_1522627038528_0004_01_000003 Container Transitioned from NEW to ALLOCATED
2018-04-01 20:02:01,177 INFO org.apache.hadoop.yarn.server.resourcemanager.RMAuditLogger: USER=root	OPERATION=AM Allocated Container	TARGET=SchedulerApp	RESULT=SUCCESS	APPID=application_1522627038528_0004	CONTAINERID=container_1522627038528_0004_01_000003
2018-04-01 20:02:01,177 INFO org.apache.hadoop.yarn.server.resourcemanager.scheduler.SchedulerNode: Assigned container container_1522627038528_0004_01_000003 of capacity <memory:1024, vCores:1> on host bd18951cf78e:36999, which has 2 containers, <memory:3072, vCores:2> used and <memory:5120, vCores:6> available after allocation
2018-04-01 20:02:01,178 INFO org.apache.hadoop.yarn.server.resourcemanager.scheduler.capacity.LeafQueue: assignedContainer application attempt=appattempt_1522627038528_0004_000001 container=Container: [ContainerId: container_1522627038528_0004_01_000003, NodeId: bd18951cf78e:36999, NodeHttpAddress: bd18951cf78e:8042, Resource: <memory:1024, vCores:1>, Priority: 10, Token: null, ] queue=default: capacity=1.0, absoluteCapacity=1.0, usedResources=<memory:2048, vCores:1>, usedCapacity=0.25, absoluteUsedCapacity=0.25, numApps=1, numContainers=1 clusterResource=<memory:8192, vCores:8>
2018-04-01 20:02:01,178 INFO org.apache.hadoop.yarn.server.resourcemanager.scheduler.capacity.ParentQueue: Re-sorting assigned queue: root.default stats: default: capacity=1.0, absoluteCapacity=1.0, usedResources=<memory:3072, vCores:2>, usedCapacity=0.375, absoluteUsedCapacity=0.375, numApps=1, numContainers=2
2018-04-01 20:02:01,178 INFO org.apache.hadoop.yarn.server.resourcemanager.scheduler.capacity.ParentQueue: assignedContainer queue=root usedCapacity=0.375 absoluteUsedCapacity=0.375 used=<memory:3072, vCores:2> cluster=<memory:8192, vCores:8>
2018-04-01 20:02:01,271 INFO org.apache.hadoop.yarn.server.resourcemanager.rmcontainer.RMContainerImpl: container_1522627038528_0004_01_000003 Container Transitioned from ALLOCATED to ACQUIRED
2018-04-01 20:02:02,178 INFO org.apache.hadoop.yarn.server.resourcemanager.rmcontainer.RMContainerImpl: container_1522627038528_0004_01_000003 Container Transitioned from ACQUIRED to RUNNING
2018-04-01 20:02:02,274 INFO org.apache.hadoop.yarn.server.resourcemanager.scheduler.AppSchedulingInfo: checking for deactivate of application :application_1522627038528_0004
2018-04-01 20:02:14,721 INFO org.apache.hadoop.yarn.server.resourcemanager.rmapp.attempt.RMAppAttemptImpl: Updating application attempt appattempt_1522627038528_0004_000001 with final state: FINISHING, and exit status: -1000
2018-04-01 20:02:14,721 INFO org.apache.hadoop.yarn.server.resourcemanager.rmapp.attempt.RMAppAttemptImpl: appattempt_1522627038528_0004_000001 State change from RUNNING to FINAL_SAVING
2018-04-01 20:02:14,721 INFO org.apache.hadoop.yarn.server.resourcemanager.rmapp.RMAppImpl: Updating application application_1522627038528_0004 with final state: FINISHING
2018-04-01 20:02:14,721 INFO org.apache.hadoop.yarn.server.resourcemanager.rmapp.RMAppImpl: application_1522627038528_0004 State change from RUNNING to FINAL_SAVING
2018-04-01 20:02:14,721 INFO org.apache.hadoop.yarn.server.resourcemanager.recovery.RMStateStore: Updating info for app: application_1522627038528_0004
2018-04-01 20:02:14,721 INFO org.apache.hadoop.yarn.server.resourcemanager.rmapp.attempt.RMAppAttemptImpl: appattempt_1522627038528_0004_000001 State change from FINAL_SAVING to FINISHING
2018-04-01 20:02:14,721 INFO org.apache.hadoop.yarn.server.resourcemanager.rmapp.RMAppImpl: application_1522627038528_0004 State change from FINAL_SAVING to FINISHING
2018-04-01 20:02:15,510 INFO org.apache.hadoop.yarn.server.resourcemanager.rmcontainer.RMContainerImpl: container_1522627038528_0004_01_000003 Container Transitioned from RUNNING to COMPLETED
2018-04-01 20:02:15,510 INFO org.apache.hadoop.yarn.server.resourcemanager.scheduler.common.fica.FiCaSchedulerApp: Completed container: container_1522627038528_0004_01_000003 in state: COMPLETED event:FINISHED
2018-04-01 20:02:15,510 INFO org.apache.hadoop.yarn.server.resourcemanager.RMAuditLogger: USER=root	OPERATION=AM Released Container	TARGET=SchedulerApp	RESULT=SUCCESS	APPID=application_1522627038528_0004	CONTAINERID=container_1522627038528_0004_01_000003
2018-04-01 20:02:15,510 INFO org.apache.hadoop.yarn.server.resourcemanager.scheduler.SchedulerNode: Released container container_1522627038528_0004_01_000003 of capacity <memory:1024, vCores:1> on host bd18951cf78e:36999, which currently has 1 containers, <memory:2048, vCores:1> used and <memory:6144, vCores:7> available, release resources=true
2018-04-01 20:02:15,510 INFO org.apache.hadoop.yarn.server.resourcemanager.scheduler.capacity.LeafQueue: default used=<memory:2048, vCores:1> numContainers=1 user=root user-resources=<memory:2048, vCores:1>
2018-04-01 20:02:15,511 INFO org.apache.hadoop.yarn.server.resourcemanager.scheduler.capacity.LeafQueue: completedContainer container=Container: [ContainerId: container_1522627038528_0004_01_000003, NodeId: bd18951cf78e:36999, NodeHttpAddress: bd18951cf78e:8042, Resource: <memory:1024, vCores:1>, Priority: 10, Token: Token { kind: ContainerToken, service: 172.20.0.2:36999 }, ] queue=default: capacity=1.0, absoluteCapacity=1.0, usedResources=<memory:2048, vCores:1>, usedCapacity=0.25, absoluteUsedCapacity=0.25, numApps=1, numContainers=1 cluster=<memory:8192, vCores:8>
2018-04-01 20:02:15,511 INFO org.apache.hadoop.yarn.server.resourcemanager.scheduler.capacity.ParentQueue: completedContainer queue=root usedCapacity=0.25 absoluteUsedCapacity=0.25 used=<memory:2048, vCores:1> cluster=<memory:8192, vCores:8>
2018-04-01 20:02:15,511 INFO org.apache.hadoop.yarn.server.resourcemanager.scheduler.capacity.ParentQueue: Re-sorting completed queue: root.default stats: default: capacity=1.0, absoluteCapacity=1.0, usedResources=<memory:2048, vCores:1>, usedCapacity=0.25, absoluteUsedCapacity=0.25, numApps=1, numContainers=1
2018-04-01 20:02:15,511 INFO org.apache.hadoop.yarn.server.resourcemanager.scheduler.capacity.CapacityScheduler: Application attempt appattempt_1522627038528_0004_000001 released container container_1522627038528_0004_01_000003 on node: host: bd18951cf78e:36999 #containers=1 available=<memory:6144, vCores:7> used=<memory:2048, vCores:1> with event: FINISHED
2018-04-01 20:02:15,723 INFO org.apache.hadoop.yarn.server.resourcemanager.ApplicationMasterService: application_1522627038528_0004 unregistered successfully. 
2018-04-01 20:02:21,523 INFO org.apache.hadoop.yarn.server.resourcemanager.rmcontainer.RMContainerImpl: container_1522627038528_0004_01_000001 Container Transitioned from RUNNING to COMPLETED
2018-04-01 20:02:21,523 INFO org.apache.hadoop.yarn.server.resourcemanager.ApplicationMasterService: Unregistering app attempt : appattempt_1522627038528_0004_000001
2018-04-01 20:02:21,523 INFO org.apache.hadoop.yarn.server.resourcemanager.scheduler.common.fica.FiCaSchedulerApp: Completed container: container_1522627038528_0004_01_000001 in state: COMPLETED event:FINISHED
2018-04-01 20:02:21,523 INFO org.apache.hadoop.yarn.server.resourcemanager.security.AMRMTokenSecretManager: Application finished, removing password for appattempt_1522627038528_0004_000001
2018-04-01 20:02:21,523 INFO org.apache.hadoop.yarn.server.resourcemanager.RMAuditLogger: USER=root	OPERATION=AM Released Container	TARGET=SchedulerApp	RESULT=SUCCESS	APPID=application_1522627038528_0004	CONTAINERID=container_1522627038528_0004_01_000001
2018-04-01 20:02:21,523 INFO org.apache.hadoop.yarn.server.resourcemanager.rmapp.attempt.RMAppAttemptImpl: appattempt_1522627038528_0004_000001 State change from FINISHING to FINISHED
2018-04-01 20:02:21,524 INFO org.apache.hadoop.yarn.server.resourcemanager.scheduler.SchedulerNode: Released container container_1522627038528_0004_01_000001 of capacity <memory:2048, vCores:1> on host bd18951cf78e:36999, which currently has 0 containers, <memory:0, vCores:0> used and <memory:8192, vCores:8> available, release resources=true
2018-04-01 20:02:21,524 INFO org.apache.hadoop.yarn.server.resourcemanager.rmapp.RMAppImpl: application_1522627038528_0004 State change from FINISHING to FINISHED
2018-04-01 20:02:21,524 INFO org.apache.hadoop.yarn.server.resourcemanager.scheduler.capacity.LeafQueue: default used=<memory:0, vCores:0> numContainers=0 user=root user-resources=<memory:0, vCores:0>
2018-04-01 20:02:21,524 INFO org.apache.hadoop.yarn.server.resourcemanager.RMAuditLogger: USER=root	OPERATION=Application Finished - Succeeded	TARGET=RMAppManager	RESULT=SUCCESS	APPID=application_1522627038528_0004
2018-04-01 20:02:21,524 INFO org.apache.hadoop.yarn.server.resourcemanager.scheduler.capacity.LeafQueue: completedContainer container=Container: [ContainerId: container_1522627038528_0004_01_000001, NodeId: bd18951cf78e:36999, NodeHttpAddress: bd18951cf78e:8042, Resource: <memory:2048, vCores:1>, Priority: 0, Token: Token { kind: ContainerToken, service: 172.20.0.2:36999 }, ] queue=default: capacity=1.0, absoluteCapacity=1.0, usedResources=<memory:0, vCores:0>, usedCapacity=0.0, absoluteUsedCapacity=0.0, numApps=1, numContainers=0 cluster=<memory:8192, vCores:8>
2018-04-01 20:02:21,524 INFO org.apache.hadoop.yarn.server.resourcemanager.scheduler.capacity.ParentQueue: completedContainer queue=root usedCapacity=0.0 absoluteUsedCapacity=0.0 used=<memory:0, vCores:0> cluster=<memory:8192, vCores:8>
2018-04-01 20:02:21,524 INFO org.apache.hadoop.yarn.server.resourcemanager.amlauncher.AMLauncher: Cleaning master appattempt_1522627038528_0004_000001
2018-04-01 20:02:21,524 INFO org.apache.hadoop.yarn.server.resourcemanager.scheduler.capacity.ParentQueue: Re-sorting completed queue: root.default stats: default: capacity=1.0, absoluteCapacity=1.0, usedResources=<memory:0, vCores:0>, usedCapacity=0.0, absoluteUsedCapacity=0.0, numApps=1, numContainers=0
2018-04-01 20:02:21,525 INFO org.apache.hadoop.yarn.server.resourcemanager.scheduler.capacity.CapacityScheduler: Application attempt appattempt_1522627038528_0004_000001 released container container_1522627038528_0004_01_000001 on node: host: bd18951cf78e:36999 #containers=0 available=<memory:8192, vCores:8> used=<memory:0, vCores:0> with event: FINISHED
2018-04-01 20:02:21,525 INFO org.apache.hadoop.yarn.server.resourcemanager.RMAppManager$ApplicationSummary: appId=application_1522627038528_0004,name=streamjob5340609832938899041.jar,user=root,queue=default,state=FINISHED,trackingUrl=http://bd18951cf78e:8088/proxy/application_1522627038528_0004/,appMasterHost=bd18951cf78e,startTime=1522627295894,finishTime=1522627334721,finalStatus=SUCCEEDED,memorySeconds=127190,vcoreSeconds=78,preemptedAMContainers=0,preemptedNonAMContainers=0,preemptedResources=<memory:0\, vCores:0>,applicationType=MAPREDUCE
2018-04-01 20:02:21,525 INFO org.apache.hadoop.yarn.server.resourcemanager.scheduler.capacity.CapacityScheduler: Application Attempt appattempt_1522627038528_0004_000001 is done. finalState=FINISHED
2018-04-01 20:02:21,525 INFO org.apache.hadoop.yarn.server.resourcemanager.scheduler.AppSchedulingInfo: Application application_1522627038528_0004 requests cleared
2018-04-01 20:02:21,525 INFO org.apache.hadoop.yarn.server.resourcemanager.scheduler.capacity.LeafQueue: Application removed - appId: application_1522627038528_0004 user: root queue: default #user-pending-applications: 0 #user-active-applications: 0 #queue-pending-applications: 0 #queue-active-applications: 0
2018-04-01 20:02:21,525 INFO org.apache.hadoop.yarn.server.resourcemanager.scheduler.capacity.ParentQueue: Application removed - appId: application_1522627038528_0004 user: root leaf-queue of parent: root #applications: 0
2018-04-01 20:02:22,535 INFO org.apache.hadoop.yarn.server.resourcemanager.scheduler.capacity.CapacityScheduler: Null container completed...
